Workbook

Sheet Question 1
A1: 1) | B1: Using the Black-Scholes equations, and assuming that the current Apple share price is $255,
A2: life of option is 8 months, annualized volatility is 30%, annualized continuously compounded risk-free rate is 5%.
A3: and annualized continously compounded dividend rate is 2%
A4: ai) At the money forward call option
A5: aii) At the money spot put option
A7: ai) | B7: S0 | D7: 255 | F7: aii) | G7: S0 | I7: =D7 -> 255
B8: sigma | D8: 0.3 | G8: sigma | I8: =D8 -> 0.3
B9: risk-free rate | D9: =-LN(EXP(-0.04))/(8/12) -> 0.06 | G9: risk-free rate | I9: =D9 -> 0.06
B10: dividend rate | D10: 0.04 | G10: dividend rate | I10: =D10 -> 0.04
B11: option life | D11: =8/12 -> 0.66666667 | G11: option life | I11: =D11 -> 0.66666667
B12: strike | D12: =D7*EXP((D9-D10)*D11) -> 258.42277 | G12: strike | I12: =I7 -> 255
B14: d1 | D14: =(LN(D7/D12)+((D9-D10+(0.5*D8*D8))*D11))/(D8*SQRT(D11)) -> 0.12247449 | G14: d1 | I14: =(LN(I7/I12)+((I9-I10+(0.5*I8*I8))*I11))/(I8*SQRT(I11)) -> 0.17690759
B15: d2 | D15: =D14-(D8*SQRT(D11)) -> -0.12247449 | G15: d2 | I15: =I14-(I8*SQRT(I11)) -> -0.068041382
B16: ATM Forward Put Premium | D16: =(-D7*EXP(-D10*D11)*NORMSDIST(-D14))+(D12*EXP(-D9*D11)*NORMSDIST(-D15)) -> 24.202489 | G16: ATM Spot call Premium | I16: =(I7*EXP(-I10*I11)*NORMSDIST(I14))-(I12*EXP(-I9*I11)*NORMSDIST(I15)) -> 25.721921
A18: bi) | B18: Call (K) - Put(K) = S0*exp(-qT) - K*exp(-rT) | F18: bii) | G18: Call (K) - Put(K) = S0*exp(-qT) - K*exp(-rT)
B19: ATM Fwd Put | C19: =D16 -> 24.202489 | G19: ATM Spot Call | H19: =I16 -> 25.721921
B20: S0 | C20: =D7 -> 255 | G20: S0 | H20: =I7 -> 255
B21: K | C21: =D12 -> 258.42277 | G21: K | H21: =I12 -> 255
B22: Exp(-rT) | C22: =EXP(-D9*D11) -> 0.96078944 | G22: Exp(-rT) | H22: =C22 -> 0.96078944
B23: Exp(-qT) | C23: =EXP(-D10*D11) -> 0.97368575 | G23: Exp(-qT) | H23: =C23 -> 0.97368575
B25: ATM Fwd Call | C25: =C19-(C21*C22)+(C20*C23) -> 24.202489 | G25: ATM spot Put | H25: =H19+(H21*H22)-(H20*H23) -> 22.433362

Sheet Question 2a_1
A1: Option type | B1: =K3 -> C | C1: =L3 -> C | D1: =M3 -> C | E1: =N3 -> C | F1: Net Effect | G1: Payoff To Replicate | H1: Slippage | I1: Replication Position | K1: Option 1 | L1: Option 2 | M1: Option 3 | N1: Option 4
I2: Inputs | J2: Current Stock Price ($) | K2: 110
A3: Stock price At Maturity | B3: Profit | J3: Option Type | K3: C | L3: C | M3: C | N3: C
A4: 70 | B4: =(MAX(IF($B$1="C",1,-1)*(A4-$K$5),0)-IF($K$10="Y",$K$13*EXP($K$6*$K$9),0))*$K$4 -> 0 | C4: =(MAX(IF($C$1="C",1,-1)*(A4-$L$5),0)-IF($K$10="Y",$L$13*EXP($K$6*$K$9),0))*$L$4 -> 0 | D4: =(MAX(IF($D$1="C",1,-1)*(A4-$M$5),0)-IF($K$10="Y",$M$13*EXP($K$6*$K$9),0))*$M$4 -> 0 | E4: =(MAX(IF($E$1="C",1,-1)*(A4-$N$5),0)-IF($K$10="Y",$N$13*EXP($K$6*$K$9),0))*$N$4 -> 0 | F4: =SUM(B4:E4) -> 0 | G4: =IF(A4<=$K$18,0,IF(A4>$K$19,0,$K$19-A4)) -> 0 | H4: =F4-G4 -> 0 | J4: Postion | K4: 2000000 | L4: =-K4 -> -2000000 | M4: -1 | N4: 1 | AL4: ST | AM4: payoff
A5: =A4+1 -> 71 | B5: =(MAX(IF($B$1="C",1,-1)*(A5-$K$5),0)-IF($K$10="Y",$K$13*EXP($K$6*$K$9),0))*$K$4 -> 0 | C5: =(MAX(IF($C$1="C",1,-1)*(A5-$L$5),0)-IF($K$10="Y",$L$13*EXP($K$6*$K$9),0))*$L$4 -> 0 | D5: =(MAX(IF($D$1="C",1,-1)*(A5-$M$5),0)-IF($K$10="Y",$M$13*EXP($K$6*$K$9),0))*$M$4 -> 0 | E5: =(MAX(IF($E$1="C",1,-1)*(A5-$N$5),0)-IF($K$10="Y",$N$13*EXP($K$6*$K$9),0))*$N$4 -> 0 | F5: =SUM(B5:E5) -> 0 | G5: =IF(A5<=$K$18,0,IF(A5>$K$19,0,$K$19-A5)) -> 0 | H5: =F5-G5 -> 0 | J5: Strike Price ($) | K5: 80 | L5: 80.00001 | M5: 80 | N5: 100 | AL5: 0 | AM5: =MAX(0,(AL5^2)-120) -> 0
A6: =A5+1 -> 72 | B6: =(MAX(IF($B$1="C",1,-1)*(A6-$K$5),0)-IF($K$10="Y",$K$13*EXP($K$6*$K$9),0))*$K$4 -> 0 | C6: =(MAX(IF($C$1="C",1,-1)*(A6-$L$5),0)-IF($K$10="Y",$L$13*EXP($K$6*$K$9),0))*$L$4 -> 0 | D6: =(MAX(IF($D$1="C",1,-1)*(A6-$M$5),0)-IF($K$10="Y",$M$13*EXP($K$6*$K$9),0))*$M$4 -> 0 | E6: =(MAX(IF($E$1="C",1,-1)*(A6-$N$5),0)-IF($K$10="Y",$N$13*EXP($K$6*$K$9),0))*$N$4 -> 0 | F6: =SUM(B6:E6) -> 0 | G6: =IF(A6<=$K$18,0,IF(A6>$K$19,0,$K$19-A6)) -> 0 | H6: =F6-G6 -> 0 | J6: Risk Free Rate (%) | K6: 0.04 | AL6: =AL5+2 -> 2 | AM6: =MAX(0,(AL6^2)-120) -> 0
A7: =A6+1 -> 73 | B7: =(MAX(IF($B$1="C",1,-1)*(A7-$K$5),0)-IF($K$10="Y",$K$13*EXP($K$6*$K$9),0))*$K$4 -> 0 | C7: =(MAX(IF($C$1="C",1,-1)*(A7-$L$5),0)-IF($K$10="Y",$L$13*EXP($K$6*$K$9),0))*$L$4 -> 0 | D7: =(MAX(IF($D$1="C",1,-1)*(A7-$M$5),0)-IF($K$10="Y",$M$13*EXP($K$6*$K$9),0))*$M$4 -> 0 | E7: =(MAX(IF($E$1="C",1,-1)*(A7-$N$5),0)-IF($K$10="Y",$N$13*EXP($K$6*$K$9),0))*$N$4 -> 0 | F7: =SUM(B7:E7) -> 0 | G7: =IF(A7<=$K$18,0,IF(A7>$K$19,0,$K$19-A7)) -> 0 | H7: =F7-G7 -> 0 | J7: Dividend Rate (%) | K7: 0.01 | AL7: =AL6+2 -> 4 | AM7: =MAX(0,(AL7^2)-120) -> 0
A8: =A7+1 -> 74 | B8: =(MAX(IF($B$1="C",1,-1)*(A8-$K$5),0)-IF($K$10="Y",$K$13*EXP($K$6*$K$9),0))*$K$4 -> 0 | C8: =(MAX(IF($C$1="C",1,-1)*(A8-$L$5),0)-IF($K$10="Y",$L$13*EXP($K$6*$K$9),0))*$L$4 -> 0 | D8: =(MAX(IF($D$1="C",1,-1)*(A8-$M$5),0)-IF($K$10="Y",$M$13*EXP($K$6*$K$9),0))*$M$4 -> 0 | E8: =(MAX(IF($E$1="C",1,-1)*(A8-$N$5),0)-IF($K$10="Y",$N$13*EXP($K$6*$K$9),0))*$N$4 -> 0 | F8: =SUM(B8:E8) -> 0 | G8: =IF(A8<=$K$18,0,IF(A8>$K$19,0,$K$19-A8)) -> 0 | H8: =F8-G8 -> 0 | J8: Volatility Rate (%) | K8: 0.3 | AL8: =AL7+2 -> 6 | AM8: =MAX(0,(AL8^2)-120) -> 0
A9: =A8+1 -> 75 | B9: =(MAX(IF($B$1="C",1,-1)*(A9-$K$5),0)-IF($K$10="Y",$K$13*EXP($K$6*$K$9),0))*$K$4 -> 0 | C9: =(MAX(IF($C$1="C",1,-1)*(A9-$L$5),0)-IF($K$10="Y",$L$13*EXP($K$6*$K$9),0))*$L$4 -> 0 | D9: =(MAX(IF($D$1="C",1,-1)*(A9-$M$5),0)-IF($K$10="Y",$M$13*EXP($K$6*$K$9),0))*$M$4 -> 0 | E9: =(MAX(IF($E$1="C",1,-1)*(A9-$N$5),0)-IF($K$10="Y",$N$13*EXP($K$6*$K$9),0))*$N$4 -> 0 | F9: =SUM(B9:E9) -> 0 | G9: =IF(A9<=$K$18,0,IF(A9>$K$19,0,$K$19-A9)) -> 0 | H9: =F9-G9 -> 0 | J9: Option Life (years) | K9: 1 | AL9: =AL8+2 -> 8 | AM9: =MAX(0,(AL9^2)-120) -> 0
A10: =A9+1 -> 76 | B10: =(MAX(IF($B$1="C",1,-1)*(A10-$K$5),0)-IF($K$10="Y",$K$13*EXP($K$6*$K$9),0))*$K$4 -> 0 | C10: =(MAX(IF($C$1="C",1,-1)*(A10-$L$5),0)-IF($K$10="Y",$L$13*EXP($K$6*$K$9),0))*$L$4 -> 0 | D10: =(MAX(IF($D$1="C",1,-1)*(A10-$M$5),0)-IF($K$10="Y",$M$13*EXP($K$6*$K$9),0))*$M$4 -> 0 | E10: =(MAX(IF($E$1="C",1,-1)*(A10-$N$5),0)-IF($K$10="Y",$N$13*EXP($K$6*$K$9),0))*$N$4 -> 0 | F10: =SUM(B10:E10) -> 0 | G10: =IF(A10<=$K$18,0,IF(A10>$K$19,0,$K$19-A10)) -> 0 | H10: =F10-G10 -> 0 | J10: Include Premium | K10: N | AL10: =AL9+2 -> 10 | AM10: =MAX(0,(AL10^2)-120) -> 0
A11: =A10+1 -> 77 | B11: =(MAX(IF($B$1="C",1,-1)*(A11-$K$5),0)-IF($K$10="Y",$K$13*EXP($K$6*$K$9),0))*$K$4 -> 0 | C11: =(MAX(IF($C$1="C",1,-1)*(A11-$L$5),0)-IF($K$10="Y",$L$13*EXP($K$6*$K$9),0))*$L$4 -> 0 | D11: =(MAX(IF($D$1="C",1,-1)*(A11-$M$5),0)-IF($K$10="Y",$M$13*EXP($K$6*$K$9),0))*$M$4 -> 0 | E11: =(MAX(IF($E$1="C",1,-1)*(A11-$N$5),0)-IF($K$10="Y",$N$13*EXP($K$6*$K$9),0))*$N$4 -> 0 | F11: =SUM(B11:E11) -> 0 | G11: =IF(A11<=$K$18,0,IF(A11>$K$19,0,$K$19-A11)) -> 0 | H11: =F11-G11 -> 0 | I11: Computations | J11: d1 | K11: =(LN($K$2/K5)+(($K$6-$K$7+(0.5*$K$8*$K$8))*$K$9))/($K$8*SQRT($K$9)) -> 1.3115124 | L11: =(LN($K$2/L5)+(($K$6-$K$7+(0.5*$K$8*$K$8))*$K$9))/($K$8*SQRT($K$9)) -> 1.311512 | M11: =(LN($K$2/M5)+(($K$6-$K$7+(0.5*$K$8*$K$8))*$K$9))/($K$8*SQRT($K$9)) -> 1.3115124 | N11: =(LN($K$2/N5)+(($K$6-$K$7+(0.5*$K$8*$K$8))*$K$9))/($K$8*SQRT($K$9)) -> 0.5677006 | AL11: =AL10+2 -> 12 | AM11: =MAX(0,(AL11^2)-120) -> 24
A12: =A11+1 -> 78 | B12: =(MAX(IF($B$1="C",1,-1)*(A12-$K$5),0)-IF($K$10="Y",$K$13*EXP($K$6*$K$9),0))*$K$4 -> 0 | C12: =(MAX(IF($C$1="C",1,-1)*(A12-$L$5),0)-IF($K$10="Y",$L$13*EXP($K$6*$K$9),0))*$L$4 -> 0 | D12: =(MAX(IF($D$1="C",1,-1)*(A12-$M$5),0)-IF($K$10="Y",$M$13*EXP($K$6*$K$9),0))*$M$4 -> 0 | E12: =(MAX(IF($E$1="C",1,-1)*(A12-$N$5),0)-IF($K$10="Y",$N$13*EXP($K$6*$K$9),0))*$N$4 -> 0 | F12: =SUM(B12:E12) -> 0 | G12: =IF(A12<=$K$18,0,IF(A12>$K$19,0,$K$19-A12)) -> 0 | H12: =F12-G12 -> 0 | J12: d2 | K12: =K11-($K$8*SQRT($K$9)) -> 1.0115124 | L12: =L11-($K$8*SQRT($K$9)) -> 1.011512 | M12: =M11-($K$8*SQRT($K$9)) -> 1.0115124 | N12: =N11-($K$8*SQRT($K$9)) -> 0.2677006 | AL12: =AL11+2 -> 14 | AM12: =MAX(0,(AL12^2)-120) -> 76
A13: =A12+1 -> 79 | B13: =(MAX(IF($B$1="C",1,-1)*(A13-$K$5),0)-IF($K$10="Y",$K$13*EXP($K$6*$K$9),0))*$K$4 -> 0 | C13: =(MAX(IF($C$1="C",1,-1)*(A13-$L$5),0)-IF($K$10="Y",$L$13*EXP($K$6*$K$9),0))*$L$4 -> 0 | D13: =(MAX(IF($D$1="C",1,-1)*(A13-$M$5),0)-IF($K$10="Y",$M$13*EXP($K$6*$K$9),0))*$M$4 -> 0 | E13: =(MAX(IF($E$1="C",1,-1)*(A13-$N$5),0)-IF($K$10="Y",$N$13*EXP($K$6*$K$9),0))*$N$4 -> 0 | F13: =SUM(B13:E13) -> 0 | G13: =IF(A13<=$K$18,0,IF(A13>$K$19,0,$K$19-A13)) -> 0 | H13: =F13-G13 -> 0 | J13: Premium | K13: =IF(K3="C",($K$2*EXP(-$K$7*$K$9)*NORMSDIST(K11))-(K5*EXP(-$K$6*$K$9)*NORMSDIST(K12)),(-$K$2*EXP(-$K$7*$K$9)*NORMSDIST(-K11))-(-K5*EXP(-$K$6*$K$9)*NORMSDIST(-K12))) -> 33.695335 | L13: =IF(L3="C",($K$2*EXP(-$K$7*$K$9)*NORMSDIST(L11))-(L5*EXP(-$K$6*$K$9)*NORMSDIST(L12)),(-$K$2*EXP(-$K$7*$K$9)*NORMSDIST(-L11))-(-L5*EXP(-$K$6*$K$9)*NORMSDIST(-L12))) -> 33.695327 | M13: =IF(M3="C",($K$2*EXP(-$K$7*$K$9)*NORMSDIST(M11))-(M5*EXP(-$K$6*$K$9)*NORMSDIST(M12)),(-$K$2*EXP(-$K$7*$K$9)*NORMSDIST(-M11))-(-M5*EXP(-$K$6*$K$9)*NORMSDIST(-M12))) -> 33.695335 | N13: =IF(N3="C",($K$2*EXP(-$K$7*$K$9)*NORMSDIST(N11))-(N5*EXP(-$K$6*$K$9)*NORMSDIST(N12)),(-$K$2*EXP(-$K$7*$K$9)*NORMSDIST(-N11))-(-N5*EXP(-$K$6*$K$9)*NORMSDIST(-N12))) -> 19.675271 | AL13: =AL12+2 -> 16 | AM13: =MAX(0,(AL13^2)-120) -> 136
A14: =A13+1 -> 80 | B14: =(MAX(IF($B$1="C",1,-1)*(A14-$K$5),0)-IF($K$10="Y",$K$13*EXP($K$6*$K$9),0))*$K$4 -> 0 | C14: =(MAX(IF($C$1="C",1,-1)*(A14-$L$5),0)-IF($K$10="Y",$L$13*EXP($K$6*$K$9),0))*$L$4 -> 0 | D14: =(MAX(IF($D$1="C",1,-1)*(A14-$M$5),0)-IF($K$10="Y",$M$13*EXP($K$6*$K$9),0))*$M$4 -> 0 | E14: =(MAX(IF($E$1="C",1,-1)*(A14-$N$5),0)-IF($K$10="Y",$N$13*EXP($K$6*$K$9),0))*$N$4 -> 0 | F14: =SUM(B14:E14) -> 0 | G14: =IF(A14<=$K$18,0,IF(A14>$K$19,0,$K$19-A14)) -> 0 | H14: =F14-G14 -> 0 | J14: Total Premium | K14: =SUMPRODUCT(K4:N4,K13:N13) -> 2.2002581 | AL14: =AL13+2 -> 18 | AM14: =MAX(0,(AL14^2)-120) -> 204
A15: =A14+1 -> 81 | B15: =(MAX(IF($B$1="C",1,-1)*(A15-$K$5),0)-IF($K$10="Y",$K$13*EXP($K$6*$K$9),0))*$K$4 -> 2000000 | C15: =(MAX(IF($C$1="C",1,-1)*(A15-$L$5),0)-IF($K$10="Y",$L$13*EXP($K$6*$K$9),0))*$L$4 -> -1999980 | D15: =(MAX(IF($D$1="C",1,-1)*(A15-$M$5),0)-IF($K$10="Y",$M$13*EXP($K$6*$K$9),0))*$M$4 -> -1 | E15: =(MAX(IF($E$1="C",1,-1)*(A15-$N$5),0)-IF($K$10="Y",$N$13*EXP($K$6*$K$9),0))*$N$4 -> 0 | F15: =SUM(B15:E15) -> 19 | G15: =IF(A15<=$K$18,0,IF(A15>$K$19,0,$K$19-A15)) -> 19 | H15: =F15-G15 -> 6.2864274e-09 | AL15: =AL14+2 -> 20 | AM15: =MAX(0,(AL15^2)-120) -> 280
A16: =A15+1 -> 82 | B16: =(MAX(IF($B$1="C",1,-1)*(A16-$K$5),0)-IF($K$10="Y",$K$13*EXP($K$6*$K$9),0))*$K$4 -> 4000000 | C16: =(MAX(IF($C$1="C",1,-1)*(A16-$L$5),0)-IF($K$10="Y",$L$13*EXP($K$6*$K$9),0))*$L$4 -> -3999980 | D16: =(MAX(IF($D$1="C",1,-1)*(A16-$M$5),0)-IF($K$10="Y",$M$13*EXP($K$6*$K$9),0))*$M$4 -> -2 | E16: =(MAX(IF($E$1="C",1,-1)*(A16-$N$5),0)-IF($K$10="Y",$N$13*EXP($K$6*$K$9),0))*$N$4 -> 0 | F16: =SUM(B16:E16) -> 18 | G16: =IF(A16<=$K$18,0,IF(A16>$K$19,0,$K$19-A16)) -> 18 | H16: =F16-G16 -> 6.519258e-09 | AL16: =AL15+2 -> 22 | AM16: =MAX(0,(AL16^2)-120) -> 364
A17: =A16+1 -> 83 | B17: =(MAX(IF($B$1="C",1,-1)*(A17-$K$5),0)-IF($K$10="Y",$K$13*EXP($K$6*$K$9),0))*$K$4 -> 6000000 | C17: =(MAX(IF($C$1="C",1,-1)*(A17-$L$5),0)-IF($K$10="Y",$L$13*EXP($K$6*$K$9),0))*$L$4 -> -5999980 | D17: =(MAX(IF($D$1="C",1,-1)*(A17-$M$5),0)-IF($K$10="Y",$M$13*EXP($K$6*$K$9),0))*$M$4 -> -3 | E17: =(MAX(IF($E$1="C",1,-1)*(A17-$N$5),0)-IF($K$10="Y",$N$13*EXP($K$6*$K$9),0))*$N$4 -> 0 | F17: =SUM(B17:E17) -> 17 | G17: =IF(A17<=$K$18,0,IF(A17>$K$19,0,$K$19-A17)) -> 17 | H17: =F17-G17 -> 6.519258e-09 | J17: Structure To Price | AL17: =AL16+2 -> 24 | AM17: =MAX(0,(AL17^2)-120) -> 456
A18: =A17+1 -> 84 | B18: =(MAX(IF($B$1="C",1,-1)*(A18-$K$5),0)-IF($K$10="Y",$K$13*EXP($K$6*$K$9),0))*$K$4 -> 8000000 | C18: =(MAX(IF($C$1="C",1,-1)*(A18-$L$5),0)-IF($K$10="Y",$L$13*EXP($K$6*$K$9),0))*$L$4 -> -7999980 | D18: =(MAX(IF($D$1="C",1,-1)*(A18-$M$5),0)-IF($K$10="Y",$M$13*EXP($K$6*$K$9),0))*$M$4 -> -4 | E18: =(MAX(IF($E$1="C",1,-1)*(A18-$N$5),0)-IF($K$10="Y",$N$13*EXP($K$6*$K$9),0))*$N$4 -> 0 | F18: =SUM(B18:E18) -> 16 | G18: =IF(A18<=$K$18,0,IF(A18>$K$19,0,$K$19-A18)) -> 16 | H18: =F18-G18 -> 6.519258e-09 | J18: Lower Strike | K18: 80 | AL18: =AL17+2 -> 26 | AM18: =MAX(0,(AL18^2)-120) -> 556
A19: =A18+1 -> 85 | B19: =(MAX(IF($B$1="C",1,-1)*(A19-$K$5),0)-IF($K$10="Y",$K$13*EXP($K$6*$K$9),0))*$K$4 -> 10000000 | C19: =(MAX(IF($C$1="C",1,-1)*(A19-$L$5),0)-IF($K$10="Y",$L$13*EXP($K$6*$K$9),0))*$L$4 -> -9999980 | D19: =(MAX(IF($D$1="C",1,-1)*(A19-$M$5),0)-IF($K$10="Y",$M$13*EXP($K$6*$K$9),0))*$M$4 -> -5 | E19: =(MAX(IF($E$1="C",1,-1)*(A19-$N$5),0)-IF($K$10="Y",$N$13*EXP($K$6*$K$9),0))*$N$4 -> 0 | F19: =SUM(B19:E19) -> 15 | G19: =IF(A19<=$K$18,0,IF(A19>$K$19,0,$K$19-A19)) -> 15 | H19: =F19-G19 -> 5.5879354e-09 | J19: Higher Strike | K19: 100 | AL19: =AL18+2 -> 28 | AM19: =MAX(0,(AL19^2)-120) -> 664
A20: =A19+1 -> 86 | B20: =(MAX(IF($B$1="C",1,-1)*(A20-$K$5),0)-IF($K$10="Y",$K$13*EXP($K$6*$K$9),0))*$K$4 -> 12000000 | C20: =(MAX(IF($C$1="C",1,-1)*(A20-$L$5),0)-IF($K$10="Y",$L$13*EXP($K$6*$K$9),0))*$L$4 -> -11999980 | D20: =(MAX(IF($D$1="C",1,-1)*(A20-$M$5),0)-IF($K$10="Y",$M$13*EXP($K$6*$K$9),0))*$M$4 -> -6 | E20: =(MAX(IF($E$1="C",1,-1)*(A20-$N$5),0)-IF($K$10="Y",$N$13*EXP($K$6*$K$9),0))*$N$4 -> 0 | F20: =SUM(B20:E20) -> 14 | G20: =IF(A20<=$K$18,0,IF(A20>$K$19,0,$K$19-A20)) -> 14 | H20: =F20-G20 -> 5.5879354e-09 | J20: Exact Value | K20: =K13-L13-((K19-K18)*NORMSDIST(L12)*EXP(-K6*K9)) -> -16.220314 | AL20: =AL19+2 -> 30 | AM20: =MAX(0,(AL20^2)-120) -> 780
A21: =A20+1 -> 87 | B21: =(MAX(IF($B$1="C",1,-1)*(A21-$K$5),0)-IF($K$10="Y",$K$13*EXP($K$6*$K$9),0))*$K$4 -> 14000000 | C21: =(MAX(IF($C$1="C",1,-1)*(A21-$L$5),0)-IF($K$10="Y",$L$13*EXP($K$6*$K$9),0))*$L$4 -> -13999980 | D21: =(MAX(IF($D$1="C",1,-1)*(A21-$M$5),0)-IF($K$10="Y",$M$13*EXP($K$6*$K$9),0))*$M$4 -> -7 | E21: =(MAX(IF($E$1="C",1,-1)*(A21-$N$5),0)-IF($K$10="Y",$N$13*EXP($K$6*$K$9),0))*$N$4 -> 0 | F21: =SUM(B21:E21) -> 13 | G21: =IF(A21<=$K$18,0,IF(A21>$K$19,0,$K$19-A21)) -> 13 | H21: =F21-G21 -> 5.5879354e-09 | AL21: =AL20+2 -> 32 | AM21: =MAX(0,(AL21^2)-120) -> 904
A22: =A21+1 -> 88 | B22: =(MAX(IF($B$1="C",1,-1)*(A22-$K$5),0)-IF($K$10="Y",$K$13*EXP($K$6*$K$9),0))*$K$4 -> 16000000 | C22: =(MAX(IF($C$1="C",1,-1)*(A22-$L$5),0)-IF($K$10="Y",$L$13*EXP($K$6*$K$9),0))*$L$4 -> -15999980 | D22: =(MAX(IF($D$1="C",1,-1)*(A22-$M$5),0)-IF($K$10="Y",$M$13*EXP($K$6*$K$9),0))*$M$4 -> -8 | E22: =(MAX(IF($E$1="C",1,-1)*(A22-$N$5),0)-IF($K$10="Y",$N$13*EXP($K$6*$K$9),0))*$N$4 -> 0 | F22: =SUM(B22:E22) -> 12 | G22: =IF(A22<=$K$18,0,IF(A22>$K$19,0,$K$19-A22)) -> 12 | H22: =F22-G22 -> 5.5879354e-09 | AL22: =AL21+2 -> 34 | AM22: =MAX(0,(AL22^2)-120) -> 1036
A23: =A22+1 -> 89 | B23: =(MAX(IF($B$1="C",1,-1)*(A23-$K$5),0)-IF($K$10="Y",$K$13*EXP($K$6*$K$9),0))*$K$4 -> 18000000 | C23: =(MAX(IF($C$1="C",1,-1)*(A23-$L$5),0)-IF($K$10="Y",$L$13*EXP($K$6*$K$9),0))*$L$4 -> -17999980 | D23: =(MAX(IF($D$1="C",1,-1)*(A23-$M$5),0)-IF($K$10="Y",$M$13*EXP($K$6*$K$9),0))*$M$4 -> -9 | E23: =(MAX(IF($E$1="C",1,-1)*(A23-$N$5),0)-IF($K$10="Y",$N$13*EXP($K$6*$K$9),0))*$N$4 -> 0 | F23: =SUM(B23:E23) -> 11 | G23: =IF(A23<=$K$18,0,IF(A23>$K$19,0,$K$19-A23)) -> 11 | H23: =F23-G23 -> 7.4505806e-09 | AL23: =AL22+2 -> 36 | AM23: =MAX(0,(AL23^2)-120) -> 1176
A24: =A23+1 -> 90 | B24: =(MAX(IF($B$1="C",1,-1)*(A24-$K$5),0)-IF($K$10="Y",$K$13*EXP($K$6*$K$9),0))*$K$4 -> 20000000 | C24: =(MAX(IF($C$1="C",1,-1)*(A24-$L$5),0)-IF($K$10="Y",$L$13*EXP($K$6*$K$9),0))*$L$4 -> -19999980 | D24: =(MAX(IF($D$1="C",1,-1)*(A24-$M$5),0)-IF($K$10="Y",$M$13*EXP($K$6*$K$9),0))*$M$4 -> -10 | E24: =(MAX(IF($E$1="C",1,-1)*(A24-$N$5),0)-IF($K$10="Y",$N$13*EXP($K$6*$K$9),0))*$N$4 -> 0 | F24: =SUM(B24:E24) -> 10 | G24: =IF(A24<=$K$18,0,IF(A24>$K$19,0,$K$19-A24)) -> 10 | H24: =F24-G24 -> 7.4505806e-09 | AL24: =AL23+2 -> 38 | AM24: =MAX(0,(AL24^2)-120) -> 1324
A25: =A24+1 -> 91 | B25: =(MAX(IF($B$1="C",1,-1)*(A25-$K$5),0)-IF($K$10="Y",$K$13*EXP($K$6*$K$9),0))*$K$4 -> 22000000 | C25: =(MAX(IF($C$1="C",1,-1)*(A25-$L$5),0)-IF($K$10="Y",$L$13*EXP($K$6*$K$9),0))*$L$4 -> -21999980 | D25: =(MAX(IF($D$1="C",1,-1)*(A25-$M$5),0)-IF($K$10="Y",$M$13*EXP($K$6*$K$9),0))*$M$4 -> -11 | E25: =(MAX(IF($E$1="C",1,-1)*(A25-$N$5),0)-IF($K$10="Y",$N$13*EXP($K$6*$K$9),0))*$N$4 -> 0 | F25: =SUM(B25:E25) -> 9 | G25: =IF(A25<=$K$18,0,IF(A25>$K$19,0,$K$19-A25)) -> 9 | H25: =F25-G25 -> 7.4505806e-09 | AL25: =AL24+2 -> 40 | AM25: =MAX(0,(AL25^2)-120) -> 1480
A26: =A25+1 -> 92 | B26: =(MAX(IF($B$1="C",1,-1)*(A26-$K$5),0)-IF($K$10="Y",$K$13*EXP($K$6*$K$9),0))*$K$4 -> 24000000 | C26: =(MAX(IF($C$1="C",1,-1)*(A26-$L$5),0)-IF($K$10="Y",$L$13*EXP($K$6*$K$9),0))*$L$4 -> -23999980 | D26: =(MAX(IF($D$1="C",1,-1)*(A26-$M$5),0)-IF($K$10="Y",$M$13*EXP($K$6*$K$9),0))*$M$4 -> -12 | E26: =(MAX(IF($E$1="C",1,-1)*(A26-$N$5),0)-IF($K$10="Y",$N$13*EXP($K$6*$K$9),0))*$N$4 -> 0 | F26: =SUM(B26:E26) -> 8 | G26: =IF(A26<=$K$18,0,IF(A26>$K$19,0,$K$19-A26)) -> 8 | H26: =F26-G26 -> 7.4505806e-09 | AL26: =AL25+2 -> 42 | AM26: =MAX(0,(AL26^2)-120) -> 1644
A27: =A26+1 -> 93 | B27: =(MAX(IF($B$1="C",1,-1)*(A27-$K$5),0)-IF($K$10="Y",$K$13*EXP($K$6*$K$9),0))*$K$4 -> 26000000 | C27: =(MAX(IF($C$1="C",1,-1)*(A27-$L$5),0)-IF($K$10="Y",$L$13*EXP($K$6*$K$9),0))*$L$4 -> -25999980 | D27: =(MAX(IF($D$1="C",1,-1)*(A27-$M$5),0)-IF($K$10="Y",$M$13*EXP($K$6*$K$9),0))*$M$4 -> -13 | E27: =(MAX(IF($E$1="C",1,-1)*(A27-$N$5),0)-IF($K$10="Y",$N$13*EXP($K$6*$K$9),0))*$N$4 -> 0 | F27: =SUM(B27:E27) -> 7 | G27: =IF(A27<=$K$18,0,IF(A27>$K$19,0,$K$19-A27)) -> 7 | H27: =F27-G27 -> 7.4505806e-09 | AL27: =AL26+2 -> 44 | AM27: =MAX(0,(AL27^2)-120) -> 1816
A28: =A27+1 -> 94 | B28: =(MAX(IF($B$1="C",1,-1)*(A28-$K$5),0)-IF($K$10="Y",$K$13*EXP($K$6*$K$9),0))*$K$4 -> 28000000 | C28: =(MAX(IF($C$1="C",1,-1)*(A28-$L$5),0)-IF($K$10="Y",$L$13*EXP($K$6*$K$9),0))*$L$4 -> -27999980 | D28: =(MAX(IF($D$1="C",1,-1)*(A28-$M$5),0)-IF($K$10="Y",$M$13*EXP($K$6*$K$9),0))*$M$4 -> -14 | E28: =(MAX(IF($E$1="C",1,-1)*(A28-$N$5),0)-IF($K$10="Y",$N$13*EXP($K$6*$K$9),0))*$N$4 -> 0 | F28: =SUM(B28:E28) -> 6 | G28: =IF(A28<=$K$18,0,IF(A28>$K$19,0,$K$19-A28)) -> 6 | H28: =F28-G28 -> 7.4505806e-09 | AL28: =AL27+2 -> 46 | AM28: =MAX(0,(AL28^2)-120) -> 1996
A29: =A28+1 -> 95 | B29: =(MAX(IF($B$1="C",1,-1)*(A29-$K$5),0)-IF($K$10="Y",$K$13*EXP($K$6*$K$9),0))*$K$4 -> 30000000 | C29: =(MAX(IF($C$1="C",1,-1)*(A29-$L$5),0)-IF($K$10="Y",$L$13*EXP($K$6*$K$9),0))*$L$4 -> -29999980 | D29: =(MAX(IF($D$1="C",1,-1)*(A29-$M$5),0)-IF($K$10="Y",$M$13*EXP($K$6*$K$9),0))*$M$4 -> -15 | E29: =(MAX(IF($E$1="C",1,-1)*(A29-$N$5),0)-IF($K$10="Y",$N$13*EXP($K$6*$K$9),0))*$N$4 -> 0 | F29: =SUM(B29:E29) -> 5 | G29: =IF(A29<=$K$18,0,IF(A29>$K$19,0,$K$19-A29)) -> 5 | H29: =F29-G29 -> 7.4505806e-09 | AL29: =AL28+2 -> 48 | AM29: =MAX(0,(AL29^2)-120) -> 2184
A30: =A29+1 -> 96 | B30: =(MAX(IF($B$1="C",1,-1)*(A30-$K$5),0)-IF($K$10="Y",$K$13*EXP($K$6*$K$9),0))*$K$4 -> 32000000 | C30: =(MAX(IF($C$1="C",1,-1)*(A30-$L$5),0)-IF($K$10="Y",$L$13*EXP($K$6*$K$9),0))*$L$4 -> -31999980 | D30: =(MAX(IF($D$1="C",1,-1)*(A30-$M$5),0)-IF($K$10="Y",$M$13*EXP($K$6*$K$9),0))*$M$4 -> -16 | E30: =(MAX(IF($E$1="C",1,-1)*(A30-$N$5),0)-IF($K$10="Y",$N$13*EXP($K$6*$K$9),0))*$N$4 -> 0 | F30: =SUM(B30:E30) -> 4 | G30: =IF(A30<=$K$18,0,IF(A30>$K$19,0,$K$19-A30)) -> 4 | H30: =F30-G30 -> 7.4505806e-09 | AL30: =AL29+2 -> 50 | AM30: =MAX(0,(AL30^2)-120) -> 2380
A31: =A30+1 -> 97 | B31: =(MAX(IF($B$1="C",1,-1)*(A31-$K$5),0)-IF($K$10="Y",$K$13*EXP($K$6*$K$9),0))*$K$4 -> 34000000 | C31: =(MAX(IF($C$1="C",1,-1)*(A31-$L$5),0)-IF($K$10="Y",$L$13*EXP($K$6*$K$9),0))*$L$4 -> -33999980 | D31: =(MAX(IF($D$1="C",1,-1)*(A31-$M$5),0)-IF($K$10="Y",$M$13*EXP($K$6*$K$9),0))*$M$4 -> -17 | E31: =(MAX(IF($E$1="C",1,-1)*(A31-$N$5),0)-IF($K$10="Y",$N$13*EXP($K$6*$K$9),0))*$N$4 -> 0 | F31: =SUM(B31:E31) -> 3 | G31: =IF(A31<=$K$18,0,IF(A31>$K$19,0,$K$19-A31)) -> 3 | H31: =F31-G31 -> 7.4505806e-09 | AL31: =AL30+2 -> 52 | AM31: =MAX(0,(AL31^2)-120) -> 2584
A32: =A31+1 -> 98 | B32: =(MAX(IF($B$1="C",1,-1)*(A32-$K$5),0)-IF($K$10="Y",$K$13*EXP($K$6*$K$9),0))*$K$4 -> 36000000 | C32: =(MAX(IF($C$1="C",1,-1)*(A32-$L$5),0)-IF($K$10="Y",$L$13*EXP($K$6*$K$9),0))*$L$4 -> -35999980 | D32: =(MAX(IF($D$1="C",1,-1)*(A32-$M$5),0)-IF($K$10="Y",$M$13*EXP($K$6*$K$9),0))*$M$4 -> -18 | E32: =(MAX(IF($E$1="C",1,-1)*(A32-$N$5),0)-IF($K$10="Y",$N$13*EXP($K$6*$K$9),0))*$N$4 -> 0 | F32: =SUM(B32:E32) -> 2 | G32: =IF(A32<=$K$18,0,IF(A32>$K$19,0,$K$19-A32)) -> 2 | H32: =F32-G32 -> 7.4505806e-09 | AL32: =AL31+2 -> 54 | AM32: =MAX(0,(AL32^2)-120) -> 2796
... A104: =A103+1 -> 170 | B104: =(MAX(IF($B$1="C",1,-1)*(A104-$K$5),0)-IF($K$10="Y",$K$13*EXP($K$6*$K$9),0))*$K$4 -> 180000000 | C104: =(MAX(IF($C$1="C",1,-1)*(A104-$L$5),0)-IF($K$10="Y",$L$13*EXP($K$6*$K$9),0))*$L$4 -> -179999980 | D104: =(MAX(IF($D$1="C",1,-1)*(A104-$M$5),0)-IF($K$10="Y",$M$13*EXP($K$6*$K$9),0))*$M$4 -> -90 | E104: =(MAX(IF($E$1="C",1,-1)*(A104-$N$5),0)-IF($K$10="Y",$N$13*EXP($K$6*$K$9),0))*$N$4 -> 70 | F104: =SUM(B104:E104) -> 0 | G104: =IF(A104<=$K$18,0,IF(A104>$K$19,0,$K$19-A104)) -> 0 | H104: =F104-G104 -> 0 | AL104: =AL103+2 -> 198 | AM104: =MAX(0,(AL104^2)-120) -> 39084
AL105: =AL104+2 -> 200 | AM105: =MAX(0,(AL105^2)-120) -> 39880
AL106: =AL105+2 -> 202 | AM106: =MAX(0,(AL106^2)-120) -> 40684
AL107: =AL106+2 -> 204 | AM107: =MAX(0,(AL107^2)-120) -> 41496
AL108: =AL107+2 -> 206 | AM108: =MAX(0,(AL108^2)-120) -> 42316
AL109: =AL108+2 -> 208 | AM109: =MAX(0,(AL109^2)-120) -> 43144
AL110: =AL109+2 -> 210 | AM110: =MAX(0,(AL110^2)-120) -> 43980
AL111: =AL110+2 -> 212 | AM111: =MAX(0,(AL111^2)-120) -> 44824
...

Sheet Question 2a_2
A1: Option type | B1: =K3 -> C | C1: =L3 -> C | D1: =M3 -> C | E1: =N3 -> C | F1: Net Effect | G1: Payoff To Replicate | H1: Slippage | I1: Replication Position | K1: Option 1 | L1: Option 2 | M1: Option 3 | N1: Option 4
I2: Inputs | J2: Current Stock Price ($) | K2: 110
A3: Stock price At Maturity | B3: Profit | J3: Option Type | K3: C | L3: =K3 -> C | M3: =L3 -> C | N3: =M3 -> C
A4: 70 | B4: =(MAX(IF($B$1="C",1,-1)*(A4-$K$5),0)-IF($K$10="Y",$K$13*EXP($K$6*$K$9),0))*$K$4 -> 0 | C4: =(MAX(IF($C$1="C",1,-1)*(A4-$L$5),0)-IF($K$10="Y",$L$13*EXP($K$6*$K$9),0))*$L$4 -> 0 | D4: =(MAX(IF($D$1="C",1,-1)*(A4-$M$5),0)-IF($K$10="Y",$M$13*EXP($K$6*$K$9),0))*$M$4 -> 0 | E4: =(MAX(IF($E$1="C",1,-1)*(A4-$N$5),0)-IF($K$10="Y",$N$13*EXP($K$6*$K$9),0))*$N$4 -> 0 | F4: =SUM(B4:E4) -> 0 | G4: =IF(A4<=$K$18,0,IF(A4>$K$19,0,A4-$K$18)) -> 0 | H4: =F4-G4 -> 0 | J4: Postion | K4: 1 | L4: -1 | M4: -200000 | N4: =-M4 -> 200000 | AL4: ST | AM4: payoff
A5: =A4+1 -> 71 | B5: =(MAX(IF($B$1="C",1,-1)*(A5-$K$5),0)-IF($K$10="Y",$K$13*EXP($K$6*$K$9),0))*$K$4 -> 0 | C5: =(MAX(IF($C$1="C",1,-1)*(A5-$L$5),0)-IF($K$10="Y",$L$13*EXP($K$6*$K$9),0))*$L$4 -> 0 | D5: =(MAX(IF($D$1="C",1,-1)*(A5-$M$5),0)-IF($K$10="Y",$M$13*EXP($K$6*$K$9),0))*$M$4 -> 0 | E5: =(MAX(IF($E$1="C",1,-1)*(A5-$N$5),0)-IF($K$10="Y",$N$13*EXP($K$6*$K$9),0))*$N$4 -> 0 | F5: =SUM(B5:E5) -> 0 | G5: =IF(A5<=$K$18,0,IF(A5>$K$19,0,A5-$K$18)) -> 0 | H5: =F5-G5 -> 0 | J5: Strike Price ($) | K5: 100 | L5: 120 | M5: 120 | N5: 120.0001 | AL5: 0 | AM5: =MAX(0,(AL5^2)-120) -> 0
A6: =A5+1 -> 72 | B6: =(MAX(IF($B$1="C",1,-1)*(A6-$K$5),0)-IF($K$10="Y",$K$13*EXP($K$6*$K$9),0))*$K$4 -> 0 | C6: =(MAX(IF($C$1="C",1,-1)*(A6-$L$5),0)-IF($K$10="Y",$L$13*EXP($K$6*$K$9),0))*$L$4 -> 0 | D6: =(MAX(IF($D$1="C",1,-1)*(A6-$M$5),0)-IF($K$10="Y",$M$13*EXP($K$6*$K$9),0))*$M$4 -> 0 | E6: =(MAX(IF($E$1="C",1,-1)*(A6-$N$5),0)-IF($K$10="Y",$N$13*EXP($K$6*$K$9),0))*$N$4 -> 0 | F6: =SUM(B6:E6) -> 0 | G6: =IF(A6<=$K$18,0,IF(A6>$K$19,0,A6-$K$18)) -> 0 | H6: =F6-G6 -> 0 | J6: Risk Free Rate (%) | K6: 0.04 | AL6: =AL5+2 -> 2 | AM6: =MAX(0,(AL6^2)-120) -> 0
A7: =A6+1 -> 73 | B7: =(MAX(IF($B$1="C",1,-1)*(A7-$K$5),0)-IF($K$10="Y",$K$13*EXP($K$6*$K$9),0))*$K$4 -> 0 | C7: =(MAX(IF($C$1="C",1,-1)*(A7-$L$5),0)-IF($K$10="Y",$L$13*EXP($K$6*$K$9),0))*$L$4 -> 0 | D7: =(MAX(IF($D$1="C",1,-1)*(A7-$M$5),0)-IF($K$10="Y",$M$13*EXP($K$6*$K$9),0))*$M$4 -> 0 | E7: =(MAX(IF($E$1="C",1,-1)*(A7-$N$5),0)-IF($K$10="Y",$N$13*EXP($K$6*$K$9),0))*$N$4 -> 0 | F7: =SUM(B7:E7) -> 0 | G7: =IF(A7<=$K$18,0,IF(A7>$K$19,0,A7-$K$18)) -> 0 | H7: =F7-G7 -> 0 | J7: Dividend Rate (%) | K7: 0.01 | AL7: =AL6+2 -> 4 | AM7: =MAX(0,(AL7^2)-120) -> 0
A8: =A7+1 -> 74 | B8: =(MAX(IF($B$1="C",1,-1)*(A8-$K$5),0)-IF($K$10="Y",$K$13*EXP($K$6*$K$9),0))*$K$4 -> 0 | C8: =(MAX(IF($C$1="C",1,-1)*(A8-$L$5),0)-IF($K$10="Y",$L$13*EXP($K$6*$K$9),0))*$L$4 -> 0 | D8: =(MAX(IF($D$1="C",1,-1)*(A8-$M$5),0)-IF($K$10="Y",$M$13*EXP($K$6*$K$9),0))*$M$4 -> 0 | E8: =(MAX(IF($E$1="C",1,-1)*(A8-$N$5),0)-IF($K$10="Y",$N$13*EXP($K$6*$K$9),0))*$N$4 -> 0 | F8: =SUM(B8:E8) -> 0 | G8: =IF(A8<=$K$18,0,IF(A8>$K$19,0,A8-$K$18)) -> 0 | H8: =F8-G8 -> 0 | J8: Volatility Rate (%) | K8: 0.3 | AL8: =AL7+2 -> 6 | AM8: =MAX(0,(AL8^2)-120) -> 0
A9: =A8+1 -> 75 | B9: =(MAX(IF($B$1="C",1,-1)*(A9-$K$5),0)-IF($K$10="Y",$K$13*EXP($K$6*$K$9),0))*$K$4 -> 0 | C9: =(MAX(IF($C$1="C",1,-1)*(A9-$L$5),0)-IF($K$10="Y",$L$13*EXP($K$6*$K$9),0))*$L$4 -> 0 | D9: =(MAX(IF($D$1="C",1,-1)*(A9-$M$5),0)-IF($K$10="Y",$M$13*EXP($K$6*$K$9),0))*$M$4 -> 0 | E9: =(MAX(IF($E$1="C",1,-1)*(A9-$N$5),0)-IF($K$10="Y",$N$13*EXP($K$6*$K$9),0))*$N$4 -> 0 | F9: =SUM(B9:E9) -> 0 | G9: =IF(A9<=$K$18,0,IF(A9>$K$19,0,A9-$K$18)) -> 0 | H9: =F9-G9 -> 0 | J9: Option Life (years) | K9: 1 | AL9: =AL8+2 -> 8 | AM9: =MAX(0,(AL9^2)-120) -> 0
A10: =A9+1 -> 76 | B10: =(MAX(IF($B$1="C",1,-1)*(A10-$K$5),0)-IF($K$10="Y",$K$13*EXP($K$6*$K$9),0))*$K$4 -> 0 | C10: =(MAX(IF($C$1="C",1,-1)*(A10-$L$5),0)-IF($K$10="Y",$L$13*EXP($K$6*$K$9),0))*$L$4 -> 0 | D10: =(MAX(IF($D$1="C",1,-1)*(A10-$M$5),0)-IF($K$10="Y",$M$13*EXP($K$6*$K$9),0))*$M$4 -> 0 | E10: =(MAX(IF($E$1="C",1,-1)*(A10-$N$5),0)-IF($K$10="Y",$N$13*EXP($K$6*$K$9),0))*$N$4 -> 0 | F10: =SUM(B10:E10) -> 0 | G10: =IF(A10<=$K$18,0,IF(A10>$K$19,0,A10-$K$18)) -> 0 | H10: =F10-G10 -> 0 | J10: Include Premium | K10: N | AL10: =AL9+2 -> 10 | AM10: =MAX(0,(AL10^2)-120) -> 0
A11: =A10+1 -> 77 | B11: =(MAX(IF($B$1="C",1,-1)*(A11-$K$5),0)-IF($K$10="Y",$K$13*EXP($K$6*$K$9),0))*$K$4 -> 0 | C11: =(MAX(IF($C$1="C",1,-1)*(A11-$L$5),0)-IF($K$10="Y",$L$13*EXP($K$6*$K$9),0))*$L$4 -> 0 | D11: =(MAX(IF($D$1="C",1,-1)*(A11-$M$5),0)-IF($K$10="Y",$M$13*EXP($K$6*$K$9),0))*$M$4 -> 0 | E11: =(MAX(IF($E$1="C",1,-1)*(A11-$N$5),0)-IF($K$10="Y",$N$13*EXP($K$6*$K$9),0))*$N$4 -> 0 | F11: =SUM(B11:E11) -> 0 | G11: =IF(A11<=$K$18,0,IF(A11>$K$19,0,A11-$K$18)) -> 0 | H11: =F11-G11 -> 0 | I11: Computations | J11: d1 | K11: =(LN($K$2/K5)+(($K$6-$K$7+(0.5*$K$8*$K$8))*$K$9))/($K$8*SQRT($K$9)) -> 0.5677006 | L11: =(LN($K$2/L5)+(($K$6-$K$7+(0.5*$K$8*$K$8))*$K$9))/($K$8*SQRT($K$9)) -> -0.040037923 | M11: =(LN($K$2/M5)+(($K$6-$K$7+(0.5*$K$8*$K$8))*$K$9))/($K$8*SQRT($K$9)) -> -0.040037923 | N11: =(LN($K$2/N5)+(($K$6-$K$7+(0.5*$K$8*$K$8))*$K$9))/($K$8*SQRT($K$9)) -> -0.040040701 | AL11: =AL10+2 -> 12 | AM11: =MAX(0,(AL11^2)-120) -> 24
A12: =A11+1 -> 78 | B12: =(MAX(IF($B$1="C",1,-1)*(A12-$K$5),0)-IF($K$10="Y",$K$13*EXP($K$6*$K$9),0))*$K$4 -> 0 | C12: =(MAX(IF($C$1="C",1,-1)*(A12-$L$5),0)-IF($K$10="Y",$L$13*EXP($K$6*$K$9),0))*$L$4 -> 0 | D12: =(MAX(IF($D$1="C",1,-1)*(A12-$M$5),0)-IF($K$10="Y",$M$13*EXP($K$6*$K$9),0))*$M$4 -> 0 | E12: =(MAX(IF($E$1="C",1,-1)*(A12-$N$5),0)-IF($K$10="Y",$N$13*EXP($K$6*$K$9),0))*$N$4 -> 0 | F12: =SUM(B12:E12) -> 0 | G12: =IF(A12<=$K$18,0,IF(A12>$K$19,0,A12-$K$18)) -> 0 | H12: =F12-G12 -> 0 | J12: d2 | K12: =K11-($K$8*SQRT($K$9)) -> 0.2677006 | L12: =L11-($K$8*SQRT($K$9)) -> -0.34003792 | M12: =M11-($K$8*SQRT($K$9)) -> -0.34003792 | N12: =N11-($K$8*SQRT($K$9)) -> -0.3400407 | AL12: =AL11+2 -> 14 | AM12: =MAX(0,(AL12^2)-120) -> 76
A13: =A12+1 -> 79 | B13: =(MAX(IF($B$1="C",1,-1)*(A13-$K$5),0)-IF($K$10="Y",$K$13*EXP($K$6*$K$9),0))*$K$4 -> 0 | C13: =(MAX(IF($C$1="C",1,-1)*(A13-$L$5),0)-IF($K$10="Y",$L$13*EXP($K$6*$K$9),0))*$L$4 -> 0 | D13: =(MAX(IF($D$1="C",1,-1)*(A13-$M$5),0)-IF($K$10="Y",$M$13*EXP($K$6*$K$9),0))*$M$4 -> 0 | E13: =(MAX(IF($E$1="C",1,-1)*(A13-$N$5),0)-IF($K$10="Y",$N$13*EXP($K$6*$K$9),0))*$N$4 -> 0 | F13: =SUM(B13:E13) -> 0 | G13: =IF(A13<=$K$18,0,IF(A13>$K$19,0,A13-$K$18)) -> 0 | H13: =F13-G13 -> 0 | J13: Premium | K13: =IF(K3="C",($K$2*EXP(-$K$7*$K$9)*NORMSDIST(K11))-(K5*EXP(-$K$6*$K$9)*NORMSDIST(K12)),(-$K$2*EXP(-$K$7*$K$9)*NORMSDIST(-K11))-(-K5*EXP(-$K$6*$K$9)*NORMSDIST(-K12))) -> 19.675271 | L13: =IF(L3="C",($K$2*EXP(-$K$7*$K$9)*NORMSDIST(L11))-(L5*EXP(-$K$6*$K$9)*NORMSDIST(L12)),(-$K$2*EXP(-$K$7*$K$9)*NORMSDIST(-L11))-(-L5*EXP(-$K$6*$K$9)*NORMSDIST(-L12))) -> 10.410428 | M13: =IF(M3="C",($K$2*EXP(-$K$7*$K$9)*NORMSDIST(M11))-(M5*EXP(-$K$6*$K$9)*NORMSDIST(M12)),(-$K$2*EXP(-$K$7*$K$9)*NORMSDIST(-M11))-(-M5*EXP(-$K$6*$K$9)*NORMSDIST(-M12))) -> 10.410428 | N13: =IF(N3="C",($K$2*EXP(-$K$7*$K$9)*NORMSDIST(N11))-(N5*EXP(-$K$6*$K$9)*NORMSDIST(N12)),(-$K$2*EXP(-$K$7*$K$9)*NORMSDIST(-N11))-(-N5*EXP(-$K$6*$K$9)*NORMSDIST(-N12))) -> 10.410393 | AL13: =AL12+2 -> 16 | AM13: =MAX(0,(AL13^2)-120) -> 136
A14: =A13+1 -> 80 | B14: =(MAX(IF($B$1="C",1,-1)*(A14-$K$5),0)-IF($K$10="Y",$K$13*EXP($K$6*$K$9),0))*$K$4 -> 0 | C14: =(MAX(IF($C$1="C",1,-1)*(A14-$L$5),0)-IF($K$10="Y",$L$13*EXP($K$6*$K$9),0))*$L$4 -> 0 | D14: =(MAX(IF($D$1="C",1,-1)*(A14-$M$5),0)-IF($K$10="Y",$M$13*EXP($K$6*$K$9),0))*$M$4 -> 0 | E14: =(MAX(IF($E$1="C",1,-1)*(A14-$N$5),0)-IF($K$10="Y",$N$13*EXP($K$6*$K$9),0))*$N$4 -> 0 | F14: =SUM(B14:E14) -> 0 | G14: =IF(A14<=$K$18,0,IF(A14>$K$19,0,A14-$K$18)) -> 0 | H14: =F14-G14 -> 0 | J14: Total Premium | K14: =SUMPRODUCT(K4:N4,K13:N13) -> 2.2143111 | AL14: =AL13+2 -> 18 | AM14: =MAX(0,(AL14^2)-120) -> 204
A15: =A14+1 -> 81 | B15: =(MAX(IF($B$1="C",1,-1)*(A15-$K$5),0)-IF($K$10="Y",$K$13*EXP($K$6*$K$9),0))*$K$4 -> 0 | C15: =(MAX(IF($C$1="C",1,-1)*(A15-$L$5),0)-IF($K$10="Y",$L$13*EXP($K$6*$K$9),0))*$L$4 -> 0 | D15: =(MAX(IF($D$1="C",1,-1)*(A15-$M$5),0)-IF($K$10="Y",$M$13*EXP($K$6*$K$9),0))*$M$4 -> 0 | E15: =(MAX(IF($E$1="C",1,-1)*(A15-$N$5),0)-IF($K$10="Y",$N$13*EXP($K$6*$K$9),0))*$N$4 -> 0 | F15: =SUM(B15:E15) -> 0 | G15: =IF(A15<=$K$18,0,IF(A15>$K$19,0,A15-$K$18)) -> 0 | H15: =F15-G15 -> 0 | AL15: =AL14+2 -> 20 | AM15: =MAX(0,(AL15^2)-120) -> 280
A16: =A15+1 -> 82 | B16: =(MAX(IF($B$1="C",1,-1)*(A16-$K$5),0)-IF($K$10="Y",$K$13*EXP($K$6*$K$9),0))*$K$4 -> 0 | C16: =(MAX(IF($C$1="C",1,-1)*(A16-$L$5),0)-IF($K$10="Y",$L$13*EXP($K$6*$K$9),0))*$L$4 -> 0 | D16: =(MAX(IF($D$1="C",1,-1)*(A16-$M$5),0)-IF($K$10="Y",$M$13*EXP($K$6*$K$9),0))*$M$4 -> 0 | E16: =(MAX(IF($E$1="C",1,-1)*(A16-$N$5),0)-IF($K$10="Y",$N$13*EXP($K$6*$K$9),0))*$N$4 -> 0 | F16: =SUM(B16:E16) -> 0 | G16: =IF(A16<=$K$18,0,IF(A16>$K$19,0,A16-$K$18)) -> 0 | H16: =F16-G16 -> 0 | AL16: =AL15+2 -> 22 | AM16: =MAX(0,(AL16^2)-120) -> 364
A17: =A16+1 -> 83 | B17: =(MAX(IF($B$1="C",1,-1)*(A17-$K$5),0)-IF($K$10="Y",$K$13*EXP($K$6*$K$9),0))*$K$4 -> 0 | C17: =(MAX(IF($C$1="C",1,-1)*(A17-$L$5),0)-IF($K$10="Y",$L$13*EXP($K$6*$K$9),0))*$L$4 -> 0 | D17: =(MAX(IF($D$1="C",1,-1)*(A17-$M$5),0)-IF($K$10="Y",$M$13*EXP($K$6*$K$9),0))*$M$4 -> 0 | E17: =(MAX(IF($E$1="C",1,-1)*(A17-$N$5),0)-IF($K$10="Y",$N$13*EXP($K$6*$K$9),0))*$N$4 -> 0 | F17: =SUM(B17:E17) -> 0 | G17: =IF(A17<=$K$18,0,IF(A17>$K$19,0,A17-$K$18)) -> 0 | H17: =F17-G17 -> 0 | J17: Structure To Price | AL17: =AL16+2 -> 24 | AM17: =MAX(0,(AL17^2)-120) -> 456
A18: =A17+1 -> 84 | B18: =(MAX(IF($B$1="C",1,-1)*(A18-$K$5),0)-IF($K$10="Y",$K$13*EXP($K$6*$K$9),0))*$K$4 -> 0 | C18: =(MAX(IF($C$1="C",1,-1)*(A18-$L$5),0)-IF($K$10="Y",$L$13*EXP($K$6*$K$9),0))*$L$4 -> 0 | D18: =(MAX(IF($D$1="C",1,-1)*(A18-$M$5),0)-IF($K$10="Y",$M$13*EXP($K$6*$K$9),0))*$M$4 -> 0 | E18: =(MAX(IF($E$1="C",1,-1)*(A18-$N$5),0)-IF($K$10="Y",$N$13*EXP($K$6*$K$9),0))*$N$4 -> 0 | F18: =SUM(B18:E18) -> 0 | G18: =IF(A18<=$K$18,0,IF(A18>$K$19,0,A18-$K$18)) -> 0 | H18: =F18-G18 -> 0 | J18: Lower Strike | K18: 100 | AL18: =AL17+2 -> 26 | AM18: =MAX(0,(AL18^2)-120) -> 556
A19: =A18+1 -> 85 | B19: =(MAX(IF($B$1="C",1,-1)*(A19-$K$5),0)-IF($K$10="Y",$K$13*EXP($K$6*$K$9),0))*$K$4 -> 0 | C19: =(MAX(IF($C$1="C",1,-1)*(A19-$L$5),0)-IF($K$10="Y",$L$13*EXP($K$6*$K$9),0))*$L$4 -> 0 | D19: =(MAX(IF($D$1="C",1,-1)*(A19-$M$5),0)-IF($K$10="Y",$M$13*EXP($K$6*$K$9),0))*$M$4 -> 0 | E19: =(MAX(IF($E$1="C",1,-1)*(A19-$N$5),0)-IF($K$10="Y",$N$13*EXP($K$6*$K$9),0))*$N$4 -> 0 | F19: =SUM(B19:E19) -> 0 | G19: =IF(A19<=$K$18,0,IF(A19>$K$19,0,A19-$K$18)) -> 0 | H19: =F19-G19 -> 0 | J19: Higher Strike | K19: 120 | AL19: =AL18+2 -> 28 | AM19: =MAX(0,(AL19^2)-120) -> 664
A20: =A19+1 -> 86 | B20: =(MAX(IF($B$1="C",1,-1)*(A20-$K$5),0)-IF($K$10="Y",$K$13*EXP($K$6*$K$9),0))*$K$4 -> 0 | C20: =(MAX(IF($C$1="C",1,-1)*(A20-$L$5),0)-IF($K$10="Y",$L$13*EXP($K$6*$K$9),0))*$L$4 -> 0 | D20: =(MAX(IF($D$1="C",1,-1)*(A20-$M$5),0)-IF($K$10="Y",$M$13*EXP($K$6*$K$9),0))*$M$4 -> 0 | E20: =(MAX(IF($E$1="C",1,-1)*(A20-$N$5),0)-IF($K$10="Y",$N$13*EXP($K$6*$K$9),0))*$N$4 -> 0 | F20: =SUM(B20:E20) -> 0 | G20: =IF(A20<=$K$18,0,IF(A20>$K$19,0,A20-$K$18)) -> 0 | H20: =F20-G20 -> 0 | J20: Exact Value | K20: =-K13+L13-((K19-K18)*NORMSDIST(-K12)*EXP(-K6*K9)) -> -16.844797 | AL20: =AL19+2 -> 30 | AM20: =MAX(0,(AL20^2)-120) -> 780
A21: =A20+1 -> 87 | B21: =(MAX(IF($B$1="C",1,-1)*(A21-$K$5),0)-IF($K$10="Y",$K$13*EXP($K$6*$K$9),0))*$K$4 -> 0 | C21: =(MAX(IF($C$1="C",1,-1)*(A21-$L$5),0)-IF($K$10="Y",$L$13*EXP($K$6*$K$9),0))*$L$4 -> 0 | D21: =(MAX(IF($D$1="C",1,-1)*(A21-$M$5),0)-IF($K$10="Y",$M$13*EXP($K$6*$K$9),0))*$M$4 -> 0 | E21: =(MAX(IF($E$1="C",1,-1)*(A21-$N$5),0)-IF($K$10="Y",$N$13*EXP($K$6*$K$9),0))*$N$4 -> 0 | F21: =SUM(B21:E21) -> 0 | G21: =IF(A21<=$K$18,0,IF(A21>$K$19,0,A21-$K$18)) -> 0 | H21: =F21-G21 -> 0 | AL21: =AL20+2 -> 32 | AM21: =MAX(0,(AL21^2)-120) -> 904
A22: =A21+1 -> 88 | B22: =(MAX(IF($B$1="C",1,-1)*(A22-$K$5),0)-IF($K$10="Y",$K$13*EXP($K$6*$K$9),0))*$K$4 -> 0 | C22: =(MAX(IF($C$1="C",1,-1)*(A22-$L$5),0)-IF($K$10="Y",$L$13*EXP($K$6*$K$9),0))*$L$4 -> 0 | D22: =(MAX(IF($D$1="C",1,-1)*(A22-$M$5),0)-IF($K$10="Y",$M$13*EXP($K$6*$K$9),0))*$M$4 -> 0 | E22: =(MAX(IF($E$1="C",1,-1)*(A22-$N$5),0)-IF($K$10="Y",$N$13*EXP($K$6*$K$9),0))*$N$4 -> 0 | F22: =SUM(B22:E22) -> 0 | G22: =IF(A22<=$K$18,0,IF(A22>$K$19,0,A22-$K$18)) -> 0 | H22: =F22-G22 -> 0 | AL22: =AL21+2 -> 34 | AM22: =MAX(0,(AL22^2)-120) -> 1036
A23: =A22+1 -> 89 | B23: =(MAX(IF($B$1="C",1,-1)*(A23-$K$5),0)-IF($K$10="Y",$K$13*EXP($K$6*$K$9),0))*$K$4 -> 0 | C23: =(MAX(IF($C$1="C",1,-1)*(A23-$L$5),0)-IF($K$10="Y",$L$13*EXP($K$6*$K$9),0))*$L$4 -> 0 | D23: =(MAX(IF($D$1="C",1,-1)*(A23-$M$5),0)-IF($K$10="Y",$M$13*EXP($K$6*$K$9),0))*$M$4 -> 0 | E23: =(MAX(IF($E$1="C",1,-1)*(A23-$N$5),0)-IF($K$10="Y",$N$13*EXP($K$6*$K$9),0))*$N$4 -> 0 | F23: =SUM(B23:E23) -> 0 | G23: =IF(A23<=$K$18,0,IF(A23>$K$19,0,A23-$K$18)) -> 0 | H23: =F23-G23 -> 0 | AL23: =AL22+2 -> 36 | AM23: =MAX(0,(AL23^2)-120) -> 1176
A24: =A23+1 -> 90 | B24: =(MAX(IF($B$1="C",1,-1)*(A24-$K$5),0)-IF($K$10="Y",$K$13*EXP($K$6*$K$9),0))*$K$4 -> 0 | C24: =(MAX(IF($C$1="C",1,-1)*(A24-$L$5),0)-IF($K$10="Y",$L$13*EXP($K$6*$K$9),0))*$L$4 -> 0 | D24: =(MAX(IF($D$1="C",1,-1)*(A24-$M$5),0)-IF($K$10="Y",$M$13*EXP($K$6*$K$9),0))*$M$4 -> 0 | E24: =(MAX(IF($E$1="C",1,-1)*(A24-$N$5),0)-IF($K$10="Y",$N$13*EXP($K$6*$K$9),0))*$N$4 -> 0 | F24: =SUM(B24:E24) -> 0 | G24: =IF(A24<=$K$18,0,IF(A24>$K$19,0,A24-$K$18)) -> 0 | H24: =F24-G24 -> 0 | AL24: =AL23+2 -> 38 | AM24: =MAX(0,(AL24^2)-120) -> 1324
A25: =A24+1 -> 91 | B25: =(MAX(IF($B$1="C",1,-1)*(A25-$K$5),0)-IF($K$10="Y",$K$13*EXP($K$6*$K$9),0))*$K$4 -> 0 | C25: =(MAX(IF($C$1="C",1,-1)*(A25-$L$5),0)-IF($K$10="Y",$L$13*EXP($K$6*$K$9),0))*$L$4 -> 0 | D25: =(MAX(IF($D$1="C",1,-1)*(A25-$M$5),0)-IF($K$10="Y",$M$13*EXP($K$6*$K$9),0))*$M$4 -> 0 | E25: =(MAX(IF($E$1="C",1,-1)*(A25-$N$5),0)-IF($K$10="Y",$N$13*EXP($K$6*$K$9),0))*$N$4 -> 0 | F25: =SUM(B25:E25) -> 0 | G25: =IF(A25<=$K$18,0,IF(A25>$K$19,0,A25-$K$18)) -> 0 | H25: =F25-G25 -> 0 | AL25: =AL24+2 -> 40 | AM25: =MAX(0,(AL25^2)-120) -> 1480
A26: =A25+1 -> 92 | B26: =(MAX(IF($B$1="C",1,-1)*(A26-$K$5),0)-IF($K$10="Y",$K$13*EXP($K$6*$K$9),0))*$K$4 -> 0 | C26: =(MAX(IF($C$1="C",1,-1)*(A26-$L$5),0)-IF($K$10="Y",$L$13*EXP($K$6*$K$9),0))*$L$4 -> 0 | D26: =(MAX(IF($D$1="C",1,-1)*(A26-$M$5),0)-IF($K$10="Y",$M$13*EXP($K$6*$K$9),0))*$M$4 -> 0 | E26: =(MAX(IF($E$1="C",1,-1)*(A26-$N$5),0)-IF($K$10="Y",$N$13*EXP($K$6*$K$9),0))*$N$4 -> 0 | F26: =SUM(B26:E26) -> 0 | G26: =IF(A26<=$K$18,0,IF(A26>$K$19,0,A26-$K$18)) -> 0 | H26: =F26-G26 -> 0 | AL26: =AL25+2 -> 42 | AM26: =MAX(0,(AL26^2)-120) -> 1644
A27: =A26+1 -> 93 | B27: =(MAX(IF($B$1="C",1,-1)*(A27-$K$5),0)-IF($K$10="Y",$K$13*EXP($K$6*$K$9),0))*$K$4 -> 0 | C27: =(MAX(IF($C$1="C",1,-1)*(A27-$L$5),0)-IF($K$10="Y",$L$13*EXP($K$6*$K$9),0))*$L$4 -> 0 | D27: =(MAX(IF($D$1="C",1,-1)*(A27-$M$5),0)-IF($K$10="Y",$M$13*EXP($K$6*$K$9),0))*$M$4 -> 0 | E27: =(MAX(IF($E$1="C",1,-1)*(A27-$N$5),0)-IF($K$10="Y",$N$13*EXP($K$6*$K$9),0))*$N$4 -> 0 | F27: =SUM(B27:E27) -> 0 | G27: =IF(A27<=$K$18,0,IF(A27>$K$19,0,A27-$K$18)) -> 0 | H27: =F27-G27 -> 0 | AL27: =AL26+2 -> 44 | AM27: =MAX(0,(AL27^2)-120) -> 1816
A28: =A27+1 -> 94 | B28: =(MAX(IF($B$1="C",1,-1)*(A28-$K$5),0)-IF($K$10="Y",$K$13*EXP($K$6*$K$9),0))*$K$4 -> 0 | C28: =(MAX(IF($C$1="C",1,-1)*(A28-$L$5),0)-IF($K$10="Y",$L$13*EXP($K$6*$K$9),0))*$L$4 -> 0 | D28: =(MAX(IF($D$1="C",1,-1)*(A28-$M$5),0)-IF($K$10="Y",$M$13*EXP($K$6*$K$9),0))*$M$4 -> 0 | E28: =(MAX(IF($E$1="C",1,-1)*(A28-$N$5),0)-IF($K$10="Y",$N$13*EXP($K$6*$K$9),0))*$N$4 -> 0 | F28: =SUM(B28:E28) -> 0 | G28: =IF(A28<=$K$18,0,IF(A28>$K$19,0,A28-$K$18)) -> 0 | H28: =F28-G28 -> 0 | AL28: =AL27+2 -> 46 | AM28: =MAX(0,(AL28^2)-120) -> 1996
A29: =A28+1 -> 95 | B29: =(MAX(IF($B$1="C",1,-1)*(A29-$K$5),0)-IF($K$10="Y",$K$13*EXP($K$6*$K$9),0))*$K$4 -> 0 | C29: =(MAX(IF($C$1="C",1,-1)*(A29-$L$5),0)-IF($K$10="Y",$L$13*EXP($K$6*$K$9),0))*$L$4 -> 0 | D29: =(MAX(IF($D$1="C",1,-1)*(A29-$M$5),0)-IF($K$10="Y",$M$13*EXP($K$6*$K$9),0))*$M$4 -> 0 | E29: =(MAX(IF($E$1="C",1,-1)*(A29-$N$5),0)-IF($K$10="Y",$N$13*EXP($K$6*$K$9),0))*$N$4 -> 0 | F29: =SUM(B29:E29) -> 0 | G29: =IF(A29<=$K$18,0,IF(A29>$K$19,0,A29-$K$18)) -> 0 | H29: =F29-G29 -> 0 | AL29: =AL28+2 -> 48 | AM29: =MAX(0,(AL29^2)-120) -> 2184
A30: =A29+1 -> 96 | B30: =(MAX(IF($B$1="C",1,-1)*(A30-$K$5),0)-IF($K$10="Y",$K$13*EXP($K$6*$K$9),0))*$K$4 -> 0 | C30: =(MAX(IF($C$1="C",1,-1)*(A30-$L$5),0)-IF($K$10="Y",$L$13*EXP($K$6*$K$9),0))*$L$4 -> 0 | D30: =(MAX(IF($D$1="C",1,-1)*(A30-$M$5),0)-IF($K$10="Y",$M$13*EXP($K$6*$K$9),0))*$M$4 -> 0 | E30: =(MAX(IF($E$1="C",1,-1)*(A30-$N$5),0)-IF($K$10="Y",$N$13*EXP($K$6*$K$9),0))*$N$4 -> 0 | F30: =SUM(B30:E30) -> 0 | G30: =IF(A30<=$K$18,0,IF(A30>$K$19,0,A30-$K$18)) -> 0 | H30: =F30-G30 -> 0 | AL30: =AL29+2 -> 50 | AM30: =MAX(0,(AL30^2)-120) -> 2380
A31: =A30+1 -> 97 | B31: =(MAX(IF($B$1="C",1,-1)*(A31-$K$5),0)-IF($K$10="Y",$K$13*EXP($K$6*$K$9),0))*$K$4 -> 0 | C31: =(MAX(IF($C$1="C",1,-1)*(A31-$L$5),0)-IF($K$10="Y",$L$13*EXP($K$6*$K$9),0))*$L$4 -> 0 | D31: =(MAX(IF($D$1="C",1,-1)*(A31-$M$5),0)-IF($K$10="Y",$M$13*EXP($K$6*$K$9),0))*$M$4 -> 0 | E31: =(MAX(IF($E$1="C",1,-1)*(A31-$N$5),0)-IF($K$10="Y",$N$13*EXP($K$6*$K$9),0))*$N$4 -> 0 | F31: =SUM(B31:E31) -> 0 | G31: =IF(A31<=$K$18,0,IF(A31>$K$19,0,A31-$K$18)) -> 0 | H31: =F31-G31 -> 0 | AL31: =AL30+2 -> 52 | AM31: =MAX(0,(AL31^2)-120) -> 2584
A32: =A31+1 -> 98 | B32: =(MAX(IF($B$1="C",1,-1)*(A32-$K$5),0)-IF($K$10="Y",$K$13*EXP($K$6*$K$9),0))*$K$4 -> 0 | C32: =(MAX(IF($C$1="C",1,-1)*(A32-$L$5),0)-IF($K$10="Y",$L$13*EXP($K$6*$K$9),0))*$L$4 -> 0 | D32: =(MAX(IF($D$1="C",1,-1)*(A32-$M$5),0)-IF($K$10="Y",$M$13*EXP($K$6*$K$9),0))*$M$4 -> 0 | E32: =(MAX(IF($E$1="C",1,-1)*(A32-$N$5),0)-IF($K$10="Y",$N$13*EXP($K$6*$K$9),0))*$N$4 -> 0 | F32: =SUM(B32:E32) -> 0 | G32: =IF(A32<=$K$18,0,IF(A32>$K$19,0,A32-$K$18)) -> 0 | H32: =F32-G32 -> 0 | AL32: =AL31+2 -> 54 | AM32: =MAX(0,(AL32^2)-120) -> 2796
... A104: =A103+1 -> 170 | B104: =(MAX(IF($B$1="C",1,-1)*(A104-$K$5),0)-IF($K$10="Y",$K$13*EXP($K$6*$K$9),0))*$K$4 -> 70 | C104: =(MAX(IF($C$1="C",1,-1)*(A104-$L$5),0)-IF($K$10="Y",$L$13*EXP($K$6*$K$9),0))*$L$4 -> -50 | D104: =(MAX(IF($D$1="C",1,-1)*(A104-$M$5),0)-IF($K$10="Y",$M$13*EXP($K$6*$K$9),0))*$M$4 -> -10000000 | E104: =(MAX(IF($E$1="C",1,-1)*(A104-$N$5),0)-IF($K$10="Y",$N$13*EXP($K$6*$K$9),0))*$N$4 -> 9999980 | F104: =SUM(B104:E104) -> 0 | G104: =IF(A104<=$K$18,0,IF(A104>$K$19,0,A104-$K$18)) -> 0 | H104: =F104-G104 -> 0 | AL104: =AL103+2 -> 198 | AM104: =MAX(0,(AL104^2)-120) -> 39084
AL105: =AL104+2 -> 200 | AM105: =MAX(0,(AL105^2)-120) -> 39880
AL106: =AL105+2 -> 202 | AM106: =MAX(0,(AL106^2)-120) -> 40684
AL107: =AL106+2 -> 204 | AM107: =MAX(0,(AL107^2)-120) -> 41496
AL108: =AL107+2 -> 206 | AM108: =MAX(0,(AL108^2)-120) -> 42316
AL109: =AL108+2 -> 208 | AM109: =MAX(0,(AL109^2)-120) -> 43144
AL110: =AL109+2 -> 210 | AM110: =MAX(0,(AL110^2)-120) -> 43980
AL111: =AL110+2 -> 212 | AM111: =MAX(0,(AL111^2)-120) -> 44824
...

Sheet Question 2a_3
A1: Option type | B1: Structure 1 | C1: Structure 2 | D1: Net Effect | E1: Payoff To Replicate | F1: Slippage | G1: Replication Position | I1: Option 1 | J1: Option 2 | K1: Option 3 | L1: Option 4
G2: Inputs | H2: Current Stock Price ($) | I2: 110
A3: Stock price At Maturity | B3: Profit | H3: Option Type | I3: P | J3: =I3 -> P | K3: C | L3: C
A4: 70 | B4: ='Question 2a_1'!F4 -> 0 | C4: ='Question 2a_2'!F4 -> 0 | D4: =SUM(B4:C4) -> 0 | E4: =IF(A4<=$I$18,0,IF(A4<=$I$19,$I$19-A4,IF(A4<=$I$20,A4-$I$19,0))) -> 0 | F4: =D4-E4 -> 0 | H4: Postion | I4: 0 | J4: 0 | K4: 0 | L4: =-K4 -> 0 | AJ4: ST | AK4: payoff
A5: =A4+1 -> 71 | B5: ='Question 2a_1'!F5 -> 0 | C5: ='Question 2a_2'!F5 -> 0 | D5: =SUM(B5:C5) -> 0 | E5: =IF(A5<=$I$18,0,IF(A5<=$I$19,$I$19-A5,IF(A5<=$I$20,A5-$I$19,0))) -> 0 | F5: =D5-E5 -> 0 | H5: Strike Price ($) | I5: 80 | J5: 100 | K5: 100 | L5: 120 | AJ5: 0 | AK5: =MAX(0,(AJ5^2)-120) -> 0
A6: =A5+1 -> 72 | B6: ='Question 2a_1'!F6 -> 0 | C6: ='Question 2a_2'!F6 -> 0 | D6: =SUM(B6:C6) -> 0 | E6: =IF(A6<=$I$18,0,IF(A6<=$I$19,$I$19-A6,IF(A6<=$I$20,A6-$I$19,0))) -> 0 | F6: =D6-E6 -> 0 | H6: Risk Free Rate (%) | I6: 0.04 | AJ6: =AJ5+2 -> 2 | AK6: =MAX(0,(AJ6^2)-120) -> 0
A7: =A6+1 -> 73 | B7: ='Question 2a_1'!F7 -> 0 | C7: ='Question 2a_2'!F7 -> 0 | D7: =SUM(B7:C7) -> 0 | E7: =IF(A7<=$I$18,0,IF(A7<=$I$19,$I$19-A7,IF(A7<=$I$20,A7-$I$19,0))) -> 0 | F7: =D7-E7 -> 0 | H7: Dividend Rate (%) | I7: 0.01 | AJ7: =AJ6+2 -> 4 | AK7: =MAX(0,(AJ7^2)-120) -> 0
A8: =A7+1 -> 74 | B8: ='Question 2a_1'!F8 -> 0 | C8: ='Question 2a_2'!F8 -> 0 | D8: =SUM(B8:C8) -> 0 | E8: =IF(A8<=$I$18,0,IF(A8<=$I$19,$I$19-A8,IF(A8<=$I$20,A8-$I$19,0))) -> 0 | F8: =D8-E8 -> 0 | H8: Volatility Rate (%) | I8: 0.3 | AJ8: =AJ7+2 -> 6 | AK8: =MAX(0,(AJ8^2)-120) -> 0
A9: =A8+1 -> 75 | B9: ='Question 2a_1'!F9 -> 0 | C9: ='Question 2a_2'!F9 -> 0 | D9: =SUM(B9:C9) -> 0 | E9: =IF(A9<=$I$18,0,IF(A9<=$I$19,$I$19-A9,IF(A9<=$I$20,A9-$I$19,0))) -> 0 | F9: =D9-E9 -> 0 | H9: Option Life (years) | I9: 1 | AJ9: =AJ8+2 -> 8 | AK9: =MAX(0,(AJ9^2)-120) -> 0
A10: =A9+1 -> 76 | B10: ='Question 2a_1'!F10 -> 0 | C10: ='Question 2a_2'!F10 -> 0 | D10: =SUM(B10:C10) -> 0 | E10: =IF(A10<=$I$18,0,IF(A10<=$I$19,$I$19-A10,IF(A10<=$I$20,A10-$I$19,0))) -> 0 | F10: =D10-E10 -> 0 | H10: Include Premium | I10: N | AJ10: =AJ9+2 -> 10 | AK10: =MAX(0,(AJ10^2)-120) -> 0
A11: =A10+1 -> 77 | B11: ='Question 2a_1'!F11 -> 0 | C11: ='Question 2a_2'!F11 -> 0 | D11: =SUM(B11:C11) -> 0 | E11: =IF(A11<=$I$18,0,IF(A11<=$I$19,$I$19-A11,IF(A11<=$I$20,A11-$I$19,0))) -> 0 | F11: =D11-E11 -> 0 | G11: Computations | H11: d1 | I11: =(LN($I$2/I5)+(($I$6-$I$7+(0.5*$I$8*$I$8))*$I$9))/($I$8*SQRT($I$9)) -> 1.3115124 | J11: =(LN($I$2/J5)+(($I$6-$I$7+(0.5*$I$8*$I$8))*$I$9))/($I$8*SQRT($I$9)) -> 0.5677006 | K11: =(LN($I$2/K5)+(($I$6-$I$7+(0.5*$I$8*$I$8))*$I$9))/($I$8*SQRT($I$9)) -> 0.5677006 | L11: =(LN($I$2/L5)+(($I$6-$I$7+(0.5*$I$8*$I$8))*$I$9))/($I$8*SQRT($I$9)) -> -0.040037923 | AJ11: =AJ10+2 -> 12 | AK11: =MAX(0,(AJ11^2)-120) -> 24
A12: =A11+1 -> 78 | B12: ='Question 2a_1'!F12 -> 0 | C12: ='Question 2a_2'!F12 -> 0 | D12: =SUM(B12:C12) -> 0 | E12: =IF(A12<=$I$18,0,IF(A12<=$I$19,$I$19-A12,IF(A12<=$I$20,A12-$I$19,0))) -> 0 | F12: =D12-E12 -> 0 | H12: d2 | I12: =I11-($I$8*SQRT($I$9)) -> 1.0115124 | J12: =J11-($I$8*SQRT($I$9)) -> 0.2677006 | K12: =K11-($I$8*SQRT($I$9)) -> 0.2677006 | L12: =L11-($I$8*SQRT($I$9)) -> -0.34003792 | AJ12: =AJ11+2 -> 14 | AK12: =MAX(0,(AJ12^2)-120) -> 76
A13: =A12+1 -> 79 | B13: ='Question 2a_1'!F13 -> 0 | C13: ='Question 2a_2'!F13 -> 0 | D13: =SUM(B13:C13) -> 0 | E13: =IF(A13<=$I$18,0,IF(A13<=$I$19,$I$19-A13,IF(A13<=$I$20,A13-$I$19,0))) -> 0 | F13: =D13-E13 -> 0 | H13: Premium | I13: =IF(I3="C",($I$2*EXP(-$I$7*$I$9)*NORMSDIST(I11))-(I5*EXP(-$I$6*$I$9)*NORMSDIST(I12)),(-$I$2*EXP(-$I$7*$I$9)*NORMSDIST(-I11))-(-I5*EXP(-$I$6*$I$9)*NORMSDIST(-I12))) -> 1.6530087 | J13: =IF(J3="C",($I$2*EXP(-$I$7*$I$9)*NORMSDIST(J11))-(J5*EXP(-$I$6*$I$9)*NORMSDIST(J12)),(-$I$2*EXP(-$I$7*$I$9)*NORMSDIST(-J11))-(-J5*EXP(-$I$6*$I$9)*NORMSDIST(-J12))) -> 6.8487329 | K13: =IF(K3="C",($I$2*EXP(-$I$7*$I$9)*NORMSDIST(K11))-(K5*EXP(-$I$6*$I$9)*NORMSDIST(K12)),(-$I$2*EXP(-$I$7*$I$9)*NORMSDIST(-K11))-(-K5*EXP(-$I$6*$I$9)*NORMSDIST(-K12))) -> 19.675271 | L13: =IF(L3="C",($I$2*EXP(-$I$7*$I$9)*NORMSDIST(L11))-(L5*EXP(-$I$6*$I$9)*NORMSDIST(L12)),(-$I$2*EXP(-$I$7*$I$9)*NORMSDIST(-L11))-(-L5*EXP(-$I$6*$I$9)*NORMSDIST(-L12))) -> 10.410428 | AJ13: =AJ12+2 -> 16 | AK13: =MAX(0,(AJ13^2)-120) -> 136
A14: =A13+1 -> 80 | B14: ='Question 2a_1'!F14 -> 0 | C14: ='Question 2a_2'!F14 -> 0 | D14: =SUM(B14:C14) -> 0 | E14: =IF(A14<=$I$18,0,IF(A14<=$I$19,$I$19-A14,IF(A14<=$I$20,A14-$I$19,0))) -> 0 | F14: =D14-E14 -> 0 | H14: Total Premium | I14: ='Question 2a_1'!K14+'Question 2a_2'!K14 -> 4.4145692 | AJ14: =AJ13+2 -> 18 | AK14: =MAX(0,(AJ14^2)-120) -> 204
A15: =A14+1 -> 81 | B15: ='Question 2a_1'!F15 -> 19 | C15: ='Question 2a_2'!F15 -> 0 | D15: =SUM(B15:C15) -> 19 | E15: =IF(A15<=$I$18,0,IF(A15<=$I$19,$I$19-A15,IF(A15<=$I$20,A15-$I$19,0))) -> 19 | F15: =D15-E15 -> 6.2864274e-09 | AJ15: =AJ14+2 -> 20 | AK15: =MAX(0,(AJ15^2)-120) -> 280
A16: =A15+1 -> 82 | B16: ='Question 2a_1'!F16 -> 18 | C16: ='Question 2a_2'!F16 -> 0 | D16: =SUM(B16:C16) -> 18 | E16: =IF(A16<=$I$18,0,IF(A16<=$I$19,$I$19-A16,IF(A16<=$I$20,A16-$I$19,0))) -> 18 | F16: =D16-E16 -> 6.519258e-09 | AJ16: =AJ15+2 -> 22 | AK16: =MAX(0,(AJ16^2)-120) -> 364
A17: =A16+1 -> 83 | B17: ='Question 2a_1'!F17 -> 17 | C17: ='Question 2a_2'!F17 -> 0 | D17: =SUM(B17:C17) -> 17 | E17: =IF(A17<=$I$18,0,IF(A17<=$I$19,$I$19-A17,IF(A17<=$I$20,A17-$I$19,0))) -> 17 | F17: =D17-E17 -> 6.519258e-09 | H17: Structure To Price | AJ17: =AJ16+2 -> 24 | AK17: =MAX(0,(AJ17^2)-120) -> 456
A18: =A17+1 -> 84 | B18: ='Question 2a_1'!F18 -> 16 | C18: ='Question 2a_2'!F18 -> 0 | D18: =SUM(B18:C18) -> 16 | E18: =IF(A18<=$I$18,0,IF(A18<=$I$19,$I$19-A18,IF(A18<=$I$20,A18-$I$19,0))) -> 16 | F18: =D18-E18 -> 6.519258e-09 | H18: Lower Strike | I18: 80 | AJ18: =AJ17+2 -> 26 | AK18: =MAX(0,(AJ18^2)-120) -> 556
A19: =A18+1 -> 85 | B19: ='Question 2a_1'!F19 -> 15 | C19: ='Question 2a_2'!F19 -> 0 | D19: =SUM(B19:C19) -> 15 | E19: =IF(A19<=$I$18,0,IF(A19<=$I$19,$I$19-A19,IF(A19<=$I$20,A19-$I$19,0))) -> 15 | F19: =D19-E19 -> 5.5879354e-09 | H19: Mid Strike | I19: 100 | AJ19: =AJ18+2 -> 28 | AK19: =MAX(0,(AJ19^2)-120) -> 664
A20: =A19+1 -> 86 | B20: ='Question 2a_1'!F20 -> 14 | C20: ='Question 2a_2'!F20 -> 0 | D20: =SUM(B20:C20) -> 14 | E20: =IF(A20<=$I$18,0,IF(A20<=$I$19,$I$19-A20,IF(A20<=$I$20,A20-$I$19,0))) -> 14 | F20: =D20-E20 -> 5.5879354e-09 | H20: Upper Strike | I20: 120 | AJ20: =AJ19+2 -> 30 | AK20: =MAX(0,(AJ20^2)-120) -> 780
A21: =A20+1 -> 87 | B21: ='Question 2a_1'!F21 -> 13 | C21: ='Question 2a_2'!F21 -> 0 | D21: =SUM(B21:C21) -> 13 | E21: =IF(A21<=$I$18,0,IF(A21<=$I$19,$I$19-A21,IF(A21<=$I$20,A21-$I$19,0))) -> 13 | F21: =D21-E21 -> 5.5879354e-09 | H21: Exact Value | I21: =(J13-I13)+(K13-L13)-((I19-I18)*NORMSDIST(-I12)*EXP(-I6*I9))-((I20-I19)*NORMSDIST(L12)*EXP(-I6*I9)) -> 4.4145602 | AJ21: =AJ20+2 -> 32 | AK21: =MAX(0,(AJ21^2)-120) -> 904
A22: =A21+1 -> 88 | B22: ='Question 2a_1'!F22 -> 12 | C22: ='Question 2a_2'!F22 -> 0 | D22: =SUM(B22:C22) -> 12 | E22: =IF(A22<=$I$18,0,IF(A22<=$I$19,$I$19-A22,IF(A22<=$I$20,A22-$I$19,0))) -> 12 | F22: =D22-E22 -> 5.5879354e-09 | AJ22: =AJ21+2 -> 34 | AK22: =MAX(0,(AJ22^2)-120) -> 1036
A23: =A22+1 -> 89 | B23: ='Question 2a_1'!F23 -> 11 | C23: ='Question 2a_2'!F23 -> 0 | D23: =SUM(B23:C23) -> 11 | E23: =IF(A23<=$I$18,0,IF(A23<=$I$19,$I$19-A23,IF(A23<=$I$20,A23-$I$19,0))) -> 11 | F23: =D23-E23 -> 7.4505806e-09 | AJ23: =AJ22+2 -> 36 | AK23: =MAX(0,(AJ23^2)-120) -> 1176
A24: =A23+1 -> 90 | B24: ='Question 2a_1'!F24 -> 10 | C24: ='Question 2a_2'!F24 -> 0 | D24: =SUM(B24:C24) -> 10 | E24: =IF(A24<=$I$18,0,IF(A24<=$I$19,$I$19-A24,IF(A24<=$I$20,A24-$I$19,0))) -> 10 | F24: =D24-E24 -> 7.4505806e-09 | AJ24: =AJ23+2 -> 38 | AK24: =MAX(0,(AJ24^2)-120) -> 1324
A25: =A24+1 -> 91 | B25: ='Question 2a_1'!F25 -> 9 | C25: ='Question 2a_2'!F25 -> 0 | D25: =SUM(B25:C25) -> 9 | E25: =IF(A25<=$I$18,0,IF(A25<=$I$19,$I$19-A25,IF(A25<=$I$20,A25-$I$19,0))) -> 9 | F25: =D25-E25 -> 7.4505806e-09 | AJ25: =AJ24+2 -> 40 | AK25: =MAX(0,(AJ25^2)-120) -> 1480
A26: =A25+1 -> 92 | B26: ='Question 2a_1'!F26 -> 8 | C26: ='Question 2a_2'!F26 -> 0 | D26: =SUM(B26:C26) -> 8 | E26: =IF(A26<=$I$18,0,IF(A26<=$I$19,$I$19-A26,IF(A26<=$I$20,A26-$I$19,0))) -> 8 | F26: =D26-E26 -> 7.4505806e-09 | AJ26: =AJ25+2 -> 42 | AK26: =MAX(0,(AJ26^2)-120) -> 1644
A27: =A26+1 -> 93 | B27: ='Question 2a_1'!F27 -> 7 | C27: ='Question 2a_2'!F27 -> 0 | D27: =SUM(B27:C27) -> 7 | E27: =IF(A27<=$I$18,0,IF(A27<=$I$19,$I$19-A27,IF(A27<=$I$20,A27-$I$19,0))) -> 7 | F27: =D27-E27 -> 7.4505806e-09 | AJ27: =AJ26+2 -> 44 | AK27: =MAX(0,(AJ27^2)-120) -> 1816
A28: =A27+1 -> 94 | B28: ='Question 2a_1'!F28 -> 6 | C28: ='Question 2a_2'!F28 -> 0 | D28: =SUM(B28:C28) -> 6 | E28: =IF(A28<=$I$18,0,IF(A28<=$I$19,$I$19-A28,IF(A28<=$I$20,A28-$I$19,0))) -> 6 | F28: =D28-E28 -> 7.4505806e-09 | AJ28: =AJ27+2 -> 46 | AK28: =MAX(0,(AJ28^2)-120) -> 1996
A29: =A28+1 -> 95 | B29: ='Question 2a_1'!F29 -> 5 | C29: ='Question 2a_2'!F29 -> 0 | D29: =SUM(B29:C29) -> 5 | E29: =IF(A29<=$I$18,0,IF(A29<=$I$19,$I$19-A29,IF(A29<=$I$20,A29-$I$19,0))) -> 5 | F29: =D29-E29 -> 7.4505806e-09 | AJ29: =AJ28+2 -> 48 | AK29: =MAX(0,(AJ29^2)-120) -> 2184
A30: =A29+1 -> 96 | B30: ='Question 2a_1'!F30 -> 4 | C30: ='Question 2a_2'!F30 -> 0 | D30: =SUM(B30:C30) -> 4 | E30: =IF(A30<=$I$18,0,IF(A30<=$I$19,$I$19-A30,IF(A30<=$I$20,A30-$I$19,0))) -> 4 | F30: =D30-E30 -> 7.4505806e-09 | AJ30: =AJ29+2 -> 50 | AK30: =MAX(0,(AJ30^2)-120) -> 2380
A31: =A30+1 -> 97 | B31: ='Question 2a_1'!F31 -> 3 | C31: ='Question 2a_2'!F31 -> 0 | D31: =SUM(B31:C31) -> 3 | E31: =IF(A31<=$I$18,0,IF(A31<=$I$19,$I$19-A31,IF(A31<=$I$20,A31-$I$19,0))) -> 3 | F31: =D31-E31 -> 7.4505806e-09 | AJ31: =AJ30+2 -> 52 | AK31: =MAX(0,(AJ31^2)-120) -> 2584
A32: =A31+1 -> 98 | B32: ='Question 2a_1'!F32 -> 2 | C32: ='Question 2a_2'!F32 -> 0 | D32: =SUM(B32:C32) -> 2 | E32: =IF(A32<=$I$18,0,IF(A32<=$I$19,$I$19-A32,IF(A32<=$I$20,A32-$I$19,0))) -> 2 | F32: =D32-E32 -> 7.4505806e-09 | AJ32: =AJ31+2 -> 54 | AK32: =MAX(0,(AJ32^2)-120) -> 2796
A33: =A32+1 -> 99 | B33: ='Question 2a_1'!F33 -> 1 | C33: ='Question 2a_2'!F33 -> 0 | D33: =SUM(B33:C33) -> 1 | E33: =IF(A33<=$I$18,0,IF(A33<=$I$19,$I$19-A33,IF(A33<=$I$20,A33-$I$19,0))) -> 1 | F33: =D33-E33 -> 7.4505806e-09 | AJ33: =AJ32+2 -> 56 | AK33: =MAX(0,(AJ33^2)-120) -> 3016
... A104: =A103+1 -> 170 | B104: ='Question 2a_1'!F104 -> 0 | C104: ='Question 2a_2'!F104 -> 0 | D104: =SUM(B104:C104) -> 0 | E104: =IF(A104<=$I$18,0,IF(A104<=$I$19,$I$19-A104,IF(A104<=$I$20,A104-$I$19,0))) -> 0 | F104: =D104-E104 -> 0 | AJ104: =AJ103+2 -> 198 | AK104: =MAX(0,(AJ104^2)-120) -> 39084
AJ105: =AJ104+2 -> 200 | AK105: =MAX(0,(AJ105^2)-120) -> 39880
AJ106: =AJ105+2 -> 202 | AK106: =MAX(0,(AJ106^2)-120) -> 40684
AJ107: =AJ106+2 -> 204 | AK107: =MAX(0,(AJ107^2)-120) -> 41496
AJ108: =AJ107+2 -> 206 | AK108: =MAX(0,(AJ108^2)-120) -> 42316
AJ109: =AJ108+2 -> 208 | AK109: =MAX(0,(AJ109^2)-120) -> 43144
AJ110: =AJ109+2 -> 210 | AK110: =MAX(0,(AJ110^2)-120) -> 43980
...

Sheet Question 2b
A1: S0 | B1: 110 | E1: Working | F1: Delta t | G1: =B8/B9 -> 0.033333333
A2: X1 | B2: 80 | F2: u | G2: =EXP(B5*SQRT(G1)) -> 1.0563
A3: X2 | B3: 100 | F3: d | G3: =1/G2 -> 0.94670073
A4: X3 | B4: 120 | F4: p | G4: =(EXP((B6-B7)*G1)-G3)/(G2-G3) -> 0.49543907
A5: volatility | B5: 0.3 | F5: Option Value | G5: =A108 -> 2.8657106
A6: Risk free | B6: 0.04
A7: Dividend | B7: 0.01
A8: Term (yrs) | B8: 1
A9: n | B9: 30
A14: 0 | B14: Delta t | C14: 2 Delta t | D14: 3 Delta t | E14: 4 Delta t | F14: 5 Delta t | G14: 6 Delta t | H14: 7 Delta t | I14: 8 Delta t | J14: 9 Delta t | K14: 10 Delta t | L14: 11 Delta t | M14: 12 Delta t | N14: 13 Delta t | O14: 14 Delta t | P14: 15 Delta t | Q14: 16 Delta t | R14: 17 Delta t | S14: 18 Delta t | T14: 19 Delta t | U14: 20 Delta t | V14: 21 Delta t | W14: 22 Delta t | X14: 23 Delta t | Y14: 24 Delta t | Z14: 25 Delta t | AA14: 26 Delta t | AB14: 27 Delta t | AC14: 28 Delta t | AD14: 29 Delta t | AE14: 30 Delta t
AE15: =$G$2*AD16 -> 568.86778
AD16: =$G$2*AC17 -> 538.54754
AC17: =$G$2*AB18 -> 509.84335 | AE17: =$G$2*AD18 -> 509.84335
AB18: =$G$2*AA19 -> 482.66907 | AD18: =$G$2*AC19 -> 482.66907
AA19: =$G$2*Z20 -> 456.94316 | AC19: =$G$2*AB20 -> 456.94316 | AE19: =$G$2*AD20 -> 456.94316
Z20: =$G$2*Y21 -> 432.58843 | AB20: =$G$2*AA21 -> 432.58843 | AD20: =$G$2*AC21 -> 432.58843
Y21: =$G$2*X22 -> 409.53178 | AA21: =$G$2*Z22 -> 409.53178 | AC21: =$G$2*AB22 -> 409.53178 | AE21: =$G$2*AD22 -> 409.53178
X22: =$G$2*W23 -> 387.70403 | Z22: =$G$2*Y23 -> 387.70403 | AB22: =$G$2*AA23 -> 387.70403 | AD22: =$G$2*AC23 -> 387.70403
W23: =$G$2*V24 -> 367.03969 | Y23: =$G$2*X24 -> 367.03969 | AA23: =$G$2*Z24 -> 367.03969 | AC23: =$G$2*AB24 -> 367.03969 | AE23: =$G$2*AD24 -> 367.03969
V24: =$G$2*U25 -> 347.47674 | X24: =$G$2*W25 -> 347.47674 | Z24: =$G$2*Y25 -> 347.47674 | AB24: =$G$2*AA25 -> 347.47674 | AD24: =$G$2*AC25 -> 347.47674
U25: =$G$2*T26 -> 328.95649 | W25: =$G$2*V26 -> 328.95649 | Y25: =$G$2*X26 -> 328.95649 | AA25: =$G$2*Z26 -> 328.95649 | AC25: =$G$2*AB26 -> 328.95649 | AE25: =$G$2*AD26 -> 328.95649
T26: =$G$2*S27 -> 311.42335 | V26: =$G$2*U27 -> 311.42335 | X26: =$G$2*W27 -> 311.42335 | Z26: =$G$2*Y27 -> 311.42335 | AB26: =$G$2*AA27 -> 311.42335 | AD26: =$G$2*AC27 -> 311.42335
S27: =$G$2*R28 -> 294.82471 | U27: =$G$2*T28 -> 294.82471 | W27: =$G$2*V28 -> 294.82471 | Y27: =$G$2*X28 -> 294.82471 | AA27: =$G$2*Z28 -> 294.82471 | AC27: =$G$2*AB28 -> 294.82471 | AE27: =$G$2*AD28 -> 294.82471
R28: =$G$2*Q29 -> 279.11077 | T28: =$G$2*S29 -> 279.11077 | V28: =$G$2*U29 -> 279.11077 | X28: =$G$2*W29 -> 279.11077 | Z28: =$G$2*Y29 -> 279.11077 | AB28: =$G$2*AA29 -> 279.11077 | AD28: =$G$2*AC29 -> 279.11077
Q29: =$G$2*P30 -> 264.23437 | S29: =$G$2*R30 -> 264.23437 | U29: =$G$2*T30 -> 264.23437 | W29: =$G$2*V30 -> 264.23437 | Y29: =$G$2*X30 -> 264.23437 | AA29: =$G$2*Z30 -> 264.23437 | AC29: =$G$2*AB30 -> 264.23437 | AE29: =$G$2*AD30 -> 264.23437
P30: =$G$2*O31 -> 250.15087 | R30: =$G$2*Q31 -> 250.15087 | T30: =$G$2*S31 -> 250.15087 | V30: =$G$2*U31 -> 250.15087 | X30: =$G$2*W31 -> 250.15087 | Z30: =$G$2*Y31 -> 250.15087 | AB30: =$G$2*AA31 -> 250.15087 | AD30: =$G$2*AC31 -> 250.15087
O31: =$G$2*N32 -> 236.81801 | Q31: =$G$2*P32 -> 236.81801 | S31: =$G$2*R32 -> 236.81801 | U31: =$G$2*T32 -> 236.81801 | W31: =$G$2*V32 -> 236.81801 | Y31: =$G$2*X32 -> 236.81801 | AA31: =$G$2*Z32 -> 236.81801 | AC31: =$G$2*AB32 -> 236.81801 | AE31: =$G$2*AD32 -> 236.81801
N32: =$G$2*M33 -> 224.19578 | P32: =$G$2*O33 -> 224.19578 | R32: =$G$2*Q33 -> 224.19578 | T32: =$G$2*S33 -> 224.19578 | V32: =$G$2*U33 -> 224.19578 | X32: =$G$2*W33 -> 224.19578 | Z32: =$G$2*Y33 -> 224.19578 | AB32: =$G$2*AA33 -> 224.19578 | AD32: =$G$2*AC33 -> 224.19578
M33: =$G$2*L34 -> 212.24631 | O33: =$G$2*N34 -> 212.24631 | Q33: =$G$2*P34 -> 212.24631 | S33: =$G$2*R34 -> 212.24631 | U33: =$G$2*T34 -> 212.24631 | W33: =$G$2*V34 -> 212.24631 | Y33: =$G$2*X34 -> 212.24631 | AA33: =$G$2*Z34 -> 212.24631 | AC33: =$G$2*AB34 -> 212.24631 | AE33: =$G$2*AD34 -> 212.24631
L34: =$G$2*K35 -> 200.93374 | N34: =$G$2*M35 -> 200.93374 | P34: =$G$2*O35 -> 200.93374 | R34: =$G$2*Q35 -> 200.93374 | T34: =$G$2*S35 -> 200.93374 | V34: =$G$2*U35 -> 200.93374 | X34: =$G$2*W35 -> 200.93374 | Z34: =$G$2*Y35 -> 200.93374 | AB34: =$G$2*AA35 -> 200.93374 | AD34: =$G$2*AC35 -> 200.93374
K35: =$G$2*J36 -> 190.22411 | M35: =$G$2*L36 -> 190.22411 | O35: =$G$2*N36 -> 190.22411 | Q35: =$G$2*P36 -> 190.22411 | S35: =$G$2*R36 -> 190.22411 | U35: =$G$2*T36 -> 190.22411 | W35: =$G$2*V36 -> 190.22411 | Y35: =$G$2*X36 -> 190.22411 | AA35: =$G$2*Z36 -> 190.22411 | AC35: =$G$2*AB36 -> 190.22411 | AE35: =$G$2*AD36 -> 190.22411
J36: =$G$2*I37 -> 180.08531 | L36: =$G$2*K37 -> 180.08531 | N36: =$G$2*M37 -> 180.08531 | P36: =$G$2*O37 -> 180.08531 | R36: =$G$2*Q37 -> 180.08531 | T36: =$G$2*S37 -> 180.08531 | V36: =$G$2*U37 -> 180.08531 | X36: =$G$2*W37 -> 180.08531 | Z36: =$G$2*Y37 -> 180.08531 | AB36: =$G$2*AA37 -> 180.08531 | AD36: =$G$2*AC37 -> 180.08531
I37: =$G$2*H38 -> 170.48689 | K37: =$G$2*J38 -> 170.48689 | M37: =$G$2*L38 -> 170.48689 | O37: =$G$2*N38 -> 170.48689 | Q37: =$G$2*P38 -> 170.48689 | S37: =$G$2*R38 -> 170.48689 | U37: =$G$2*T38 -> 170.48689 | W37: =$G$2*V38 -> 170.48689 | Y37: =$G$2*X38 -> 170.48689 | AA37: =$G$2*Z38 -> 170.48689 | AC37: =$G$2*AB38 -> 170.48689 | AE37: =$G$2*AD38 -> 170.48689
H38: =$G$2*G39 -> 161.40006 | J38: =$G$2*I39 -> 161.40006 | L38: =$G$2*K39 -> 161.40006 | N38: =$G$2*M39 -> 161.40006 | P38: =$G$2*O39 -> 161.40006 | R38: =$G$2*Q39 -> 161.40006 | T38: =$G$2*S39 -> 161.40006 | V38: =$G$2*U39 -> 161.40006 | X38: =$G$2*W39 -> 161.40006 | Z38: =$G$2*Y39 -> 161.40006 | AB38: =$G$2*AA39 -> 161.40006 | AD38: =$G$2*AC39 -> 161.40006
G39: =$G$2*F40 -> 152.79756 | I39: =$G$2*H40 -> 152.79756 | K39: =$G$2*J40 -> 152.79756 | M39: =$G$2*L40 -> 152.79756 | O39: =$G$2*N40 -> 152.79756 | Q39: =$G$2*P40 -> 152.79756 | S39: =$G$2*R40 -> 152.79756 | U39: =$G$2*T40 -> 152.79756 | W39: =$G$2*V40 -> 152.79756 | Y39: =$G$2*X40 -> 152.79756 | AA39: =$G$2*Z40 -> 152.79756 | AC39: =$G$2*AB40 -> 152.79756 | AE39: =$G$2*AD40 -> 152.79756
F40: =$G$2*E41 -> 144.65356 | H40: =$G$2*G41 -> 144.65356 | J40: =$G$2*I41 -> 144.65356 | L40: =$G$2*K41 -> 144.65356 | N40: =$G$2*M41 -> 144.65356 | P40: =$G$2*O41 -> 144.65356 | R40: =$G$2*Q41 -> 144.65356 | T40: =$G$2*S41 -> 144.65356 | V40: =$G$2*U41 -> 144.65356 | X40: =$G$2*W41 -> 144.65356 | Z40: =$G$2*Y41 -> 144.65356 | AB40: =$G$2*AA41 -> 144.65356 | AD40: =$G$2*AC41 -> 144.65356
E41: =$G$2*D42 -> 136.94363 | G41: =$G$2*F42 -> 136.94363 | I41: =$G$2*H42 -> 136.94363 | K41: =$G$2*J42 -> 136.94363 | M41: =$G$2*L42 -> 136.94363 | O41: =$G$2*N42 -> 136.94363 | Q41: =$G$2*P42 -> 136.94363 | S41: =$G$2*R42 -> 136.94363 | U41: =$G$2*T42 -> 136.94363 | W41: =$G$2*V42 -> 136.94363 | Y41: =$G$2*X42 -> 136.94363 | AA41: =$G$2*Z42 -> 136.94363 | AC41: =$G$2*AB42 -> 136.94363 | AE41: =$G$2*AD42 -> 136.94363
D42: =$G$2*C43 -> 129.64464 | F42: =$G$2*E43 -> 129.64464 | H42: =$G$2*G43 -> 129.64464 | J42: =$G$2*I43 -> 129.64464 | L42: =$G$2*K43 -> 129.64464 | N42: =$G$2*M43 -> 129.64464 | P42: =$G$2*O43 -> 129.64464 | R42: =$G$2*Q43 -> 129.64464 | T42: =$G$2*S43 -> 129.64464 | V42: =$G$2*U43 -> 129.64464 | X42: =$G$2*W43 -> 129.64464 | Z42: =$G$2*Y43 -> 129.64464 | AB42: =$G$2*AA43 -> 129.64464 | AD42: =$G$2*AC43 -> 129.64464
C43: =$G$2*B44 -> 122.73467 | E43: =$G$2*D44 -> 122.73467 | G43: =$G$2*F44 -> 122.73467 | I43: =$G$2*H44 -> 122.73467 | K43: =$G$2*J44 -> 122.73467 | M43: =$G$2*L44 -> 122.73467 | O43: =$G$2*N44 -> 122.73467 | Q43: =$G$2*P44 -> 122.73467 | S43: =$G$2*R44 -> 122.73467 | U43: =$G$2*T44 -> 122.73467 | W43: =$G$2*V44 -> 122.73467 | Y43: =$G$2*X44 -> 122.73467 | AA43: =$G$2*Z44 -> 122.73467 | AC43: =$G$2*AB44 -> 122.73467 | AE43: =$G$2*AD44 -> 122.73467
