Workbook

Sheet Slide 17
A1: uniform random number | B1: =RAND() -> 0.47247571

Sheet Slide 24a
B1: X | C1: 1 | D1: 2 | E1: 3 | F1: 4
B2: P(X=x) | C2: 0.2 | D2: 0.3 | E2: 0.45 | F2: 0.05
A3: Step 1 | B3: P(X ≤ x) | C3: =C2 -> 0.2 | D3: =D2+C3 -> 0.5 | E3: =E2+D3 -> 0.95 | F3: =F2+E3 -> 1 | G3: <<<Find the cumulative probabilities
A4: Step 2 | B4: Uniform number can be between (0, 0.2] | G4: <<<Bucket generated uniform values
B5: Uniform number can be between (0.2,0.5]
B6: Uniform number can be between (0.5, 0.95]
B7: Uniform number can be between (0.95, 1]
A8: Step 3 | B8: If uniform number is in interval (0, 0.2], assign value X = 1 | G8: <<<Assign values to buckets
B9: If uniform number is in interval (0.2, 0.5], assign value X = 2
B10: If uniform number is in interval (0.5, 0.95], assign value X = 3
B11: If uniform number is in interval (0.95, 1], assign value X = 4

Sheet Slide 24b
A1: X | B1: 0 | C1: -2 | D1: 1 | E1: 1.5
A2: P(X=x) | B2: 0.3 | C2: 0.25 | D2: 0.3 | E2: 0.15
A3: P(X ≤ x) | B3: ='Slide 24a'!C3 -> 0.2 | C3: ='Slide 24a'!D3 -> 0.5 | D3: ='Slide 24a'!E3 -> 0.95 | E3: ='Slide 24a'!F3 -> 1
A4: Rand U(0,1) | B4: =RAND() -> 0.58985066
A5: Rand Variate X | B5: =IF(B4<=B3,B1,IF(B4<=C3,C1,IF(B4<=D3,D1,E1))) -> 1

Sheet Slide 25a
A1: Step 0 | B1: X | C1: -2 | D1: 0 | E1: 1 | F1: 1.5 | G1: <<<Order the X values
B2: P(X=x) | C2: 0.25 | D2: 0.3 | E2: 0.3 | F2: 0.15
A3: Step 1 | B3: P(X ≤ x) | C3: =C2 -> 0.25 | D3: =D2+C3 -> 0.55 | E3: =E2+D3 -> 0.85 | F3: =F2+E3 -> 1 | G3: <<<Find the cumulative probabilities
A4: Step 2 | B4: Uniform number can be between (0, 0.25] | G4: <<<Bucket generated uniform values
B5: Uniform number can be between (0.25,0.55]
B6: Uniform number can be between (0.55, 0.85]
B7: Uniform number can be between (0.85, 1]
A8: Step 3 | B8: If uniform number is in interval (0, 0.25], assign value X = - 2 | G8: <<<Assign values to buckets
B9: If uniform number is in interval (0.25, 0.55], assign value X = 0
B10: If uniform number is in interval (0.55, 0.85], assign value X = 1
B11: If uniform number is in interval (0.85, 1], assign value X = 1.5

Sheet Slide 25b
A1: X | B1: ='Slide 25a'!C1 -> -2 | C1: ='Slide 25a'!D1 -> 0 | D1: ='Slide 25a'!E1 -> 1 | E1: ='Slide 25a'!F1 -> 1.5
A2: P(X=x) | B2: ='Slide 25a'!C2 -> 0.25 | C2: ='Slide 25a'!D2 -> 0.3 | D2: ='Slide 25a'!E2 -> 0.3 | E2: ='Slide 25a'!F2 -> 0.15
A3: P(X ≤ x) | B3: ='Slide 25a'!C3 -> 0.25 | C3: ='Slide 25a'!D3 -> 0.55 | D3: ='Slide 25a'!E3 -> 0.85 | E3: ='Slide 25a'!F3 -> 1
A4: Rand U(0,1) | B4: =RAND() -> 0.81222129
A5: Rand Variate X | B5: =IF(B4<=B3,B1,IF(B4<=C3,C1,IF(B4<=D3,D1,E1))) -> 1

Sheet Slide 26
A1: Success Probability | B1: 0.4
A2: X | B2: 0 | C2: 1 | D2: 2 | E2: 3 | F2: 4 | G2: 5
A3: P(X=x) | B3: =COMBIN(5,B2)*($B$1^B2)*((1-$B$1)^(5-B2)) -> 0.07776 | C3: =COMBIN(5,C2)*($B$1^C2)*((1-$B$1)^(5-C2)) -> 0.2592 | D3: =COMBIN(5,D2)*($B$1^D2)*((1-$B$1)^(5-D2)) -> 0.3456 | E3: =COMBIN(5,E2)*($B$1^E2)*((1-$B$1)^(5-E2)) -> 0.2304 | F3: =COMBIN(5,F2)*($B$1^F2)*((1-$B$1)^(5-F2)) -> 0.0768 | G3: =COMBIN(5,G2)*($B$1^G2)*((1-$B$1)^(5-G2)) -> 0.01024
A4: P(X ≤ x) | B4: =B3 -> 0.07776 | C4: =C3+B4 -> 0.33696 | D4: =D3+C4 -> 0.68256 | E4: =E3+D4 -> 0.91296 | F4: =F3+E4 -> 0.98976 | G4: =G3+F4 -> 1
A5: Rand U(0,1) | B5: =RAND() -> 0.9793197
A6: Rand Variate X | B6: =IF(B5<=B4,B2,IF(B5<=C4,C2,IF(B5<=D4,D2,IF(B5<=E4,E2,IF(B5<=F4,F2,G2))))) -> 4

Sheet Slide 27a
A1: Lower Limit | B1: 2
A2: Upper Limit | B2: 6
A3: x | B3: f(x) | I3: Step 0: | J3: See what the picture looks like - uniform on (2,4)
A4: =A5-0.0001 -> 1.9999 | B4: 0 | I4: Step 1: | J4: See how to make this look like U(0,1)
A5: =B1 -> 2 | B5: =1/($B$2-$B$1) -> 0.25 | J5: To do this, we can achieve this using 2 steps
A6: =A5+(0.01*($B$2-$B$1)) -> 2.04 | B6: =1/($B$2-$B$1) -> 0.25 | J6: 1) Subtract all observations by 2
A7: =A6+(0.01*($B$2-$B$1)) -> 2.08 | B7: =1/($B$2-$B$1) -> 0.25 | J7: The result would be a uniform on (0,4)
A8: =A7+(0.01*($B$2-$B$1)) -> 2.12 | B8: =1/($B$2-$B$1) -> 0.25 | J8: See Slide 21b
A9: =A8+(0.01*($B$2-$B$1)) -> 2.16 | B9: =1/($B$2-$B$1) -> 0.25
A10: =A9+(0.01*($B$2-$B$1)) -> 2.2 | B10: =1/($B$2-$B$1) -> 0.25
A11: =A10+(0.01*($B$2-$B$1)) -> 2.24 | B11: =1/($B$2-$B$1) -> 0.25
A12: =A11+(0.01*($B$2-$B$1)) -> 2.28 | B12: =1/($B$2-$B$1) -> 0.25
A13: =A12+(0.01*($B$2-$B$1)) -> 2.32 | B13: =1/($B$2-$B$1) -> 0.25
A14: =A13+(0.01*($B$2-$B$1)) -> 2.36 | B14: =1/($B$2-$B$1) -> 0.25
A15: =A14+(0.01*($B$2-$B$1)) -> 2.4 | B15: =1/($B$2-$B$1) -> 0.25
A16: =A15+(0.01*($B$2-$B$1)) -> 2.44 | B16: =1/($B$2-$B$1) -> 0.25
A17: =A16+(0.01*($B$2-$B$1)) -> 2.48 | B17: =1/($B$2-$B$1) -> 0.25
A18: =A17+(0.01*($B$2-$B$1)) -> 2.52 | B18: =1/($B$2-$B$1) -> 0.25
A19: =A18+(0.01*($B$2-$B$1)) -> 2.56 | B19: =1/($B$2-$B$1) -> 0.25
A20: =A19+(0.01*($B$2-$B$1)) -> 2.6 | B20: =1/($B$2-$B$1) -> 0.25
... A105: =A104+(0.01*($B$2-$B$1)) -> 6 | B105: =1/($B$2-$B$1) -> 0.25
A106: =A105+0.0001 -> 6.0001 | B106: 0

Sheet Slide 27b
A1: Lower Limit | B1: 0
A2: Upper Limit | B2: 4
A3: x | B3: f(x) | I3: Step 0: | J3: See what the picture looks like - uniform on (2,4)
A4: =A5-0.0001 -> -0.0001 | B4: 0 | I4: Step 1: | J4: See how to make this look like U(0,1)
A5: =B1 -> 0 | B5: =1/($B$2-$B$1) -> 0.25 | J5: To do this, we can achieve this using 2 steps
A6: =A5+(0.01*($B$2-$B$1)) -> 0.04 | B6: =1/($B$2-$B$1) -> 0.25 | J6: 1) Subtract all observations by 2
A7: =A6+(0.01*($B$2-$B$1)) -> 0.08 | B7: =1/($B$2-$B$1) -> 0.25 | J7: The result would be a uniform on (0,4)
A8: =A7+(0.01*($B$2-$B$1)) -> 0.12 | B8: =1/($B$2-$B$1) -> 0.25 | J8: 2) Divide all observations by 4
A9: =A8+(0.01*($B$2-$B$1)) -> 0.16 | B9: =1/($B$2-$B$1) -> 0.25 | J9: The result would be a uniform on (0,1)
A10: =A9+(0.01*($B$2-$B$1)) -> 0.2 | B10: =1/($B$2-$B$1) -> 0.25
A11: =A10+(0.01*($B$2-$B$1)) -> 0.24 | B11: =1/($B$2-$B$1) -> 0.25
A12: =A11+(0.01*($B$2-$B$1)) -> 0.28 | B12: =1/($B$2-$B$1) -> 0.25
A13: =A12+(0.01*($B$2-$B$1)) -> 0.32 | B13: =1/($B$2-$B$1) -> 0.25
A14: =A13+(0.01*($B$2-$B$1)) -> 0.36 | B14: =1/($B$2-$B$1) -> 0.25
A15: =A14+(0.01*($B$2-$B$1)) -> 0.4 | B15: =1/($B$2-$B$1) -> 0.25
A16: =A15+(0.01*($B$2-$B$1)) -> 0.44 | B16: =1/($B$2-$B$1) -> 0.25
A17: =A16+(0.01*($B$2-$B$1)) -> 0.48 | B17: =1/($B$2-$B$1) -> 0.25
A18: =A17+(0.01*($B$2-$B$1)) -> 0.52 | B18: =1/($B$2-$B$1) -> 0.25
A19: =A18+(0.01*($B$2-$B$1)) -> 0.56 | B19: =1/($B$2-$B$1) -> 0.25
A20: =A19+(0.01*($B$2-$B$1)) -> 0.6 | B20: =1/($B$2-$B$1) -> 0.25
A21: =A20+(0.01*($B$2-$B$1)) -> 0.64 | B21: =1/($B$2-$B$1) -> 0.25
... A105: =A104+(0.01*($B$2-$B$1)) -> 4 | B105: =1/($B$2-$B$1) -> 0.25
A106: =A105+0.0001 -> 4.0001 | B106: 0

Sheet Slide 27c
A1: Lower Limit | B1: 0
A2: Upper Limit | B2: 1
A3: x | B3: f(x) | I3: Step 0: | J3: See what the picture looks like - uniform on (2,4)
A4: =A5-0.0001 -> -0.0001 | B4: 0 | I4: Step 1: | J4: See how to make this look like U(0,1)
A5: =B1 -> 0 | B5: =1/($B$2-$B$1) -> 1 | J5: To do this, we can achieve this using 2 steps
A6: =A5+(0.01*($B$2-$B$1)) -> 0.01 | B6: =1/($B$2-$B$1) -> 1 | J6: 1) Subtract all observations by 2
A7: =A6+(0.01*($B$2-$B$1)) -> 0.02 | B7: =1/($B$2-$B$1) -> 1 | J7: The result would be a uniform on (0,4)
A8: =A7+(0.01*($B$2-$B$1)) -> 0.03 | B8: =1/($B$2-$B$1) -> 1 | J8: 2) Divide all observations by 4
A9: =A8+(0.01*($B$2-$B$1)) -> 0.04 | B9: =1/($B$2-$B$1) -> 1 | J9: The result would be a uniform on (0,1)
A10: =A9+(0.01*($B$2-$B$1)) -> 0.05 | B10: =1/($B$2-$B$1) -> 1
A11: =A10+(0.01*($B$2-$B$1)) -> 0.06 | B11: =1/($B$2-$B$1) -> 1 | I11: Bottom line: If Y represents any observation from U(0,1)
A12: =A11+(0.01*($B$2-$B$1)) -> 0.07 | B12: =1/($B$2-$B$1) -> 1 | J12: and X represents any observation from U(2,6)
A13: =A12+(0.01*($B$2-$B$1)) -> 0.08 | B13: =1/($B$2-$B$1) -> 1 | J13: The we have
A14: =A13+(0.01*($B$2-$B$1)) -> 0.09 | B14: =1/($B$2-$B$1) -> 1
A15: =A14+(0.01*($B$2-$B$1)) -> 0.1 | B15: =1/($B$2-$B$1) -> 1
A16: =A15+(0.01*($B$2-$B$1)) -> 0.11 | B16: =1/($B$2-$B$1) -> 1
A17: =A16+(0.01*($B$2-$B$1)) -> 0.12 | B17: =1/($B$2-$B$1) -> 1
A18: =A17+(0.01*($B$2-$B$1)) -> 0.13 | B18: =1/($B$2-$B$1) -> 1 | J18: Put another way, if we can generate a value of
A19: =A18+(0.01*($B$2-$B$1)) -> 0.14 | B19: =1/($B$2-$B$1) -> 1 | J19: Then
A20: =A19+(0.01*($B$2-$B$1)) -> 0.15 | B20: =1/($B$2-$B$1) -> 1
A21: =A20+(0.01*($B$2-$B$1)) -> 0.16 | B21: =1/($B$2-$B$1) -> 1
A22: =A21+(0.01*($B$2-$B$1)) -> 0.17 | B22: =1/($B$2-$B$1) -> 1 | J22: In general we can say that if X is uniform on (a,b)
A23: =A22+(0.01*($B$2-$B$1)) -> 0.18 | B23: =1/($B$2-$B$1) -> 1 | J23: and Y is uniform on (0,1), then
A24: =A23+(0.01*($B$2-$B$1)) -> 0.19 | B24: =1/($B$2-$B$1) -> 1
A25: =A24+(0.01*($B$2-$B$1)) -> 0.2 | B25: =1/($B$2-$B$1) -> 1
A26: =A25+(0.01*($B$2-$B$1)) -> 0.21 | B26: =1/($B$2-$B$1) -> 1
A27: =A26+(0.01*($B$2-$B$1)) -> 0.22 | B27: =1/($B$2-$B$1) -> 1
A28: =A27+(0.01*($B$2-$B$1)) -> 0.23 | B28: =1/($B$2-$B$1) -> 1
A29: =A28+(0.01*($B$2-$B$1)) -> 0.24 | B29: =1/($B$2-$B$1) -> 1
A30: =A29+(0.01*($B$2-$B$1)) -> 0.25 | B30: =1/($B$2-$B$1) -> 1
A31: =A30+(0.01*($B$2-$B$1)) -> 0.26 | B31: =1/($B$2-$B$1) -> 1
A32: =A31+(0.01*($B$2-$B$1)) -> 0.27 | B32: =1/($B$2-$B$1) -> 1
A33: =A32+(0.01*($B$2-$B$1)) -> 0.28 | B33: =1/($B$2-$B$1) -> 1
A34: =A33+(0.01*($B$2-$B$1)) -> 0.29 | B34: =1/($B$2-$B$1) -> 1
A35: =A34+(0.01*($B$2-$B$1)) -> 0.3 | B35: =1/($B$2-$B$1) -> 1
... A105: =A104+(0.01*($B$2-$B$1)) -> 1 | B105: =1/($B$2-$B$1) -> 1
A106: =A105+0.0001 -> 1.0001 | B106: 0

Sheet Slide 27d
A1: Lower Limit of Uniform (a) | B1: 2
A2: Upper Limit of Uniform (b) | B2: 6
A3: Y - Rand U(0,1) | B3: =RAND() -> 0.4732873
A4: X - Rand U(a,b) | B4: =(B3*(B2-B1))+B1 -> 3.8931492

Sheet Slide 28
A1: Lower Limit | B1: 2
A2: Upper Limit | B2: 6
A3: x | B3: f(x) | I3: Step 0: | J3: See what the picture looks like - triangle on (2,4)
A4: =A5-0.0001 -> 1.9999 | B4: 0 | I4: Step 1: | J4: See how to make this look like U(0,1)
A5: =B1 -> 2 | B5: =(A5-$B$1)*2/(($B$2-$B$1)^2) -> 0 | J5: Any ideas?
A6: =A5+(0.01*($B$2-$B$1)) -> 2.04 | B6: =(A6-$B$1)*2/(($B$2-$B$1)^2) -> 0.005
A7: =A6+(0.01*($B$2-$B$1)) -> 2.08 | B7: =(A7-$B$1)*2/(($B$2-$B$1)^2) -> 0.01
A8: =A7+(0.01*($B$2-$B$1)) -> 2.12 | B8: =(A8-$B$1)*2/(($B$2-$B$1)^2) -> 0.015
A9: =A8+(0.01*($B$2-$B$1)) -> 2.16 | B9: =(A9-$B$1)*2/(($B$2-$B$1)^2) -> 0.02
A10: =A9+(0.01*($B$2-$B$1)) -> 2.2 | B10: =(A10-$B$1)*2/(($B$2-$B$1)^2) -> 0.025
A11: =A10+(0.01*($B$2-$B$1)) -> 2.24 | B11: =(A11-$B$1)*2/(($B$2-$B$1)^2) -> 0.03
A12: =A11+(0.01*($B$2-$B$1)) -> 2.28 | B12: =(A12-$B$1)*2/(($B$2-$B$1)^2) -> 0.035
A13: =A12+(0.01*($B$2-$B$1)) -> 2.32 | B13: =(A13-$B$1)*2/(($B$2-$B$1)^2) -> 0.04
A14: =A13+(0.01*($B$2-$B$1)) -> 2.36 | B14: =(A14-$B$1)*2/(($B$2-$B$1)^2) -> 0.045
A15: =A14+(0.01*($B$2-$B$1)) -> 2.4 | B15: =(A15-$B$1)*2/(($B$2-$B$1)^2) -> 0.05
A16: =A15+(0.01*($B$2-$B$1)) -> 2.44 | B16: =(A16-$B$1)*2/(($B$2-$B$1)^2) -> 0.055
A17: =A16+(0.01*($B$2-$B$1)) -> 2.48 | B17: =(A17-$B$1)*2/(($B$2-$B$1)^2) -> 0.06
... A105: =A104+(0.01*($B$2-$B$1)) -> 6 | B105: =(A105-$B$1)*2/(($B$2-$B$1)^2) -> 0.5
A106: =A105+0.0001 -> 6.0001 | B106: 0

Sheet Slide 30 
A1: Lower Limit | B1: 2
A2: Upper Limit | B2: 6
A3: x | B3: f(x) | C3: F(x) | I3: Step 0: | J3: See what the picture looks like - triangle on (2,4)
A4: =A5-0.0001 -> 1.9999 | B4: 0 | C4: 0 | I4: Step 1: | J4: See how to make this look like U(0,1)
A5: =B1 -> 2 | B5: =(A5-$B$1)*2/(($B$2-$B$1)^2) -> 0 | C5: =IF(A5<$B$1,0,IF(A5>$B$2,1,((A5-$B$1)^2)/(($B$2-$B$1)^2))) -> 0 | J5: Any ideas?
A6: =A5+(0.01*($B$2-$B$1)) -> 2.04 | B6: =(A6-$B$1)*2/(($B$2-$B$1)^2) -> 0.005 | C6: =IF(A6<$B$1,0,IF(A6>$B$2,1,((A6-$B$1)^2)/(($B$2-$B$1)^2))) -> 0.0001
A7: =A6+(0.01*($B$2-$B$1)) -> 2.08 | B7: =(A7-$B$1)*2/(($B$2-$B$1)^2) -> 0.01 | C7: =IF(A7<$B$1,0,IF(A7>$B$2,1,((A7-$B$1)^2)/(($B$2-$B$1)^2))) -> 0.0004
A8: =A7+(0.01*($B$2-$B$1)) -> 2.12 | B8: =(A8-$B$1)*2/(($B$2-$B$1)^2) -> 0.015 | C8: =IF(A8<$B$1,0,IF(A8>$B$2,1,((A8-$B$1)^2)/(($B$2-$B$1)^2))) -> 0.0009
A9: =A8+(0.01*($B$2-$B$1)) -> 2.16 | B9: =(A9-$B$1)*2/(($B$2-$B$1)^2) -> 0.02 | C9: =IF(A9<$B$1,0,IF(A9>$B$2,1,((A9-$B$1)^2)/(($B$2-$B$1)^2))) -> 0.0016
A10: =A9+(0.01*($B$2-$B$1)) -> 2.2 | B10: =(A10-$B$1)*2/(($B$2-$B$1)^2) -> 0.025 | C10: =IF(A10<$B$1,0,IF(A10>$B$2,1,((A10-$B$1)^2)/(($B$2-$B$1)^2))) -> 0.0025
A11: =A10+(0.01*($B$2-$B$1)) -> 2.24 | B11: =(A11-$B$1)*2/(($B$2-$B$1)^2) -> 0.03 | C11: =IF(A11<$B$1,0,IF(A11>$B$2,1,((A11-$B$1)^2)/(($B$2-$B$1)^2))) -> 0.0036
A12: =A11+(0.01*($B$2-$B$1)) -> 2.28 | B12: =(A12-$B$1)*2/(($B$2-$B$1)^2) -> 0.035 | C12: =IF(A12<$B$1,0,IF(A12>$B$2,1,((A12-$B$1)^2)/(($B$2-$B$1)^2))) -> 0.0049
A13: =A12+(0.01*($B$2-$B$1)) -> 2.32 | B13: =(A13-$B$1)*2/(($B$2-$B$1)^2) -> 0.04 | C13: =IF(A13<$B$1,0,IF(A13>$B$2,1,((A13-$B$1)^2)/(($B$2-$B$1)^2))) -> 0.0064
A14: =A13+(0.01*($B$2-$B$1)) -> 2.36 | B14: =(A14-$B$1)*2/(($B$2-$B$1)^2) -> 0.045 | C14: =IF(A14<$B$1,0,IF(A14>$B$2,1,((A14-$B$1)^2)/(($B$2-$B$1)^2))) -> 0.0081
A15: =A14+(0.01*($B$2-$B$1)) -> 2.4 | B15: =(A15-$B$1)*2/(($B$2-$B$1)^2) -> 0.05 | C15: =IF(A15<$B$1,0,IF(A15>$B$2,1,((A15-$B$1)^2)/(($B$2-$B$1)^2))) -> 0.01
A16: =A15+(0.01*($B$2-$B$1)) -> 2.44 | B16: =(A16-$B$1)*2/(($B$2-$B$1)^2) -> 0.055 | C16: =IF(A16<$B$1,0,IF(A16>$B$2,1,((A16-$B$1)^2)/(($B$2-$B$1)^2))) -> 0.0121
A17: =A16+(0.01*($B$2-$B$1)) -> 2.48 | B17: =(A17-$B$1)*2/(($B$2-$B$1)^2) -> 0.06 | C17: =IF(A17<$B$1,0,IF(A17>$B$2,1,((A17-$B$1)^2)/(($B$2-$B$1)^2))) -> 0.0144
... A105: =A104+(0.01*($B$2-$B$1)) -> 6 | B105: =(A105-$B$1)*2/(($B$2-$B$1)^2) -> 0.5 | C105: =IF(A105<$B$1,0,IF(A105>$B$2,1,((A105-$B$1)^2)/(($B$2-$B$1)^2))) -> 1
A106: =A105+0.0001 -> 6.0001 | B106: 0 | C106: =IF(A106<$B$1,0,IF(A106>$B$2,1,0.25*(A106-$B$1)*(A106-$B$1)/($B$2-$B$1))) -> 1
A107: =A106+0.1 -> 6.1001 | B107: =B106 -> 0 | C107: =IF(A107<$B$1,0,IF(A107>$B$2,1,0.25*(A107-$B$1)*(A107-$B$1)/($B$2-$B$1))) -> 1
A108: =A107+0.1 -> 6.2001 | B108: =B107 -> 0 | C108: =IF(A108<$B$1,0,IF(A108>$B$2,1,0.25*(A108-$B$1)*(A108-$B$1)/($B$2-$B$1))) -> 1
A109: =A108+0.1 -> 6.3001 | B109: =B108 -> 0 | C109: =IF(A109<$B$1,0,IF(A109>$B$2,1,0.25*(A109-$B$1)*(A109-$B$1)/($B$2-$B$1))) -> 1

Sheet Simulation of pi
A1: x | B1: =RAND() -> 0.39484877 | E1: =B4 -> 1
A2: y | B2: =RAND() -> 0.75117608 | D2: 1 | E2: 1
A3: Dist from origin | B3: =SQRT((B1^2)+(B2^2)) -> 0.84862892 | D3: =D2+1 -> 2 | E3: 0
A4: Indicator | B4: =IF(B3<1,1,0) -> 1 | D4: =D3+1 -> 3 | E4: 1
A5: Pi value | B5: =AVERAGE(E2:E1001)*4 -> 3.156 | D5: =D4+1 -> 4 | E5: 1
D6: =D5+1 -> 5 | E6: 1
D7: =D6+1 -> 6 | E7: 1
D8: =D7+1 -> 7 | E8: 1
D9: =D8+1 -> 8 | E9: 1
D10: =D9+1 -> 9 | E10: 0
D11: =D10+1 -> 10 | E11: 1
D12: =D11+1 -> 11 | E12: 1
D13: =D12+1 -> 12 | E13: 1
D14: =D13+1 -> 13 | E14: 1
D15: =D14+1 -> 14 | E15: 1
D16: =D15+1 -> 15 | E16: 1
D17: =D16+1 -> 16 | E17: 1
... D1001: =D1000+1 -> 1000 | E1001: 1

Sheet Int problem 1
A1: x | B1: =RAND() -> 0.14922727 | E1: =B3 -> 0.77014633
A2: scaled x | B2: =(B1*(3-1))+1 -> 1.2984545 | D2: 1 | E2: 0.57087174
A3: 1/x | B3: =1/B2 -> 0.77014633 | D3: =D2+1 -> 2 | E3: 0.33488792
A4: area | B4: =SUM(E2:E1001)*(3-1)/1000 -> 1.0957315 | D4: =D3+1 -> 3 | E4: 0.50679911
D5: =D4+1 -> 4 | E5: 0.6442491
D6: =D5+1 -> 5 | E6: 0.50607691
D7: =D6+1 -> 6 | E7: 0.44480903
D8: =D7+1 -> 7 | E8: 0.97862526
D9: =D8+1 -> 8 | E9: 0.67571403
D10: =D9+1 -> 9 | E10: 0.48320332
D11: =D10+1 -> 10 | E11: 0.72206936
D12: =D11+1 -> 11 | E12: 0.54989433
D13: =D12+1 -> 12 | E13: 0.36228011
D14: =D13+1 -> 13 | E14: 0.41354772
D15: =D14+1 -> 14 | E15: 0.43400305
D16: =D15+1 -> 15 | E16: 0.65151405
... D1001: =D1000+1 -> 1000 | E1001: 0.33542199

Sheet Int problem 2
A1: x | B1: =RAND() -> 0.081594291 | E1: =B3 -> 0.39885929
A2: scaled x | B2: =(B1*(0.25-0)) -> 0.020398573 | D2: 1 | E2: 0.39875514
A3: transform | B3: =EXP(-0.5*B2*B2)/SQRT(2*PI()) -> 0.39885929 | D3: =D2+1 -> 2 | E3: 0.38795135
A4: area | B4: =0.5+SUM(E2:E1001)*(0.25-0)/1000 -> 0.59876317 | D4: =D3+1 -> 3 | E4: 0.39874784
D5: =D4+1 -> 4 | E5: 0.3876562
D6: =D5+1 -> 5 | E6: 0.39137166
D7: =D6+1 -> 6 | E7: 0.39340031
D8: =D7+1 -> 7 | E8: 0.39058273
D9: =D8+1 -> 8 | E9: 0.39754516
D10: =D9+1 -> 9 | E10: 0.39755552
D11: =D10+1 -> 10 | E11: 0.39801718
D12: =D11+1 -> 11 | E12: 0.39433389
D13: =D12+1 -> 12 | E13: 0.39503733
D14: =D13+1 -> 13 | E14: 0.39650691
D15: =D14+1 -> 14 | E15: 0.38933449
D16: =D15+1 -> 15 | E16: 0.39225438
... D1001: =D1000+1 -> 1000 | E1001: 0.39612096

Sheet Slide 33_s (1 path)
A1: S0 | B1: 100
A2: r | B2: 0.1
A3: q | B3: 0.03 | J3: Time | K3: uni rand numbers | L3: normal random numbers | M3: stock price path
A4: vol | B4: 0.3 | J4: 0 | M4: =B1 -> 100
A5: Time | B5: 0.5 | J5: =J4+$B$6 -> 0.041666667 | K5: =RAND() -> 0.87787586 | L5: =NORMSINV(K5) -> 1.1644337 | M5: =M4*EXP(($B$2-$B$3-(0.5*$B$4*$B$4))*$B$6)*EXP($B$4*SQRT($B$6)*L5) -> 107.50298
A6: delta t | B6: =B5/12 -> 0.041666667 | C6: years | J6: =J5+$B$6 -> 0.083333333 | K6: =RAND() -> 0.87120772 | L6: =NORMSINV(K6) -> 1.1321187 | M6: =M5*EXP(($B$2-$B$3-(0.5*$B$4*$B$4))*$B$6)*EXP($B$4*SQRT($B$6)*L6) -> 115.34043
J7: =J6+$B$6 -> 0.125 | K7: =RAND() -> 0.66517573 | L7: =NORMSINV(K7) -> 0.42663042 | M7: =M6*EXP(($B$2-$B$3-(0.5*$B$4*$B$4))*$B$6)*EXP($B$4*SQRT($B$6)*L7) -> 118.51688
J8: =J7+$B$6 -> 0.16666667 | K8: =RAND() -> 0.64285281 | L8: =NORMSINV(K8) -> 0.36609473 | M8: =M7*EXP(($B$2-$B$3-(0.5*$B$4*$B$4))*$B$6)*EXP($B$4*SQRT($B$6)*L8) -> 121.33019
J9: =J8+$B$6 -> 0.20833333 | K9: =RAND() -> 0.12265796 | L9: =NORMSINV(K9) -> -1.161802 | M9: =M8*EXP(($B$2-$B$3-(0.5*$B$4*$B$4))*$B$6)*EXP($B$4*SQRT($B$6)*L9) -> 113.11577
J10: =J9+$B$6 -> 0.25 | K10: =RAND() -> 0.90281095 | L10: =NORMSINV(K10) -> 1.2977359 | M10: =M9*EXP(($B$2-$B$3-(0.5*$B$4*$B$4))*$B$6)*EXP($B$4*SQRT($B$6)*L10) -> 122.59954
J11: =J10+$B$6 -> 0.29166667 | K11: =RAND() -> 0.99275354 | L11: =NORMSINV(K11) -> 2.4448084 | M11: =M10*EXP(($B$2-$B$3-(0.5*$B$4*$B$4))*$B$6)*EXP($B$4*SQRT($B$6)*L11) -> 142.54792
J12: =J11+$B$6 -> 0.33333333 | K12: =RAND() -> 0.80533131 | L12: =NORMSINV(K12) -> 0.86081965 | M12: =M11*EXP(($B$2-$B$3-(0.5*$B$4*$B$4))*$B$6)*EXP($B$4*SQRT($B$6)*L12) -> 150.42041
J13: =J12+$B$6 -> 0.375 | K13: =RAND() -> 0.86107727 | L13: =NORMSINV(K13) -> 1.085172 | M13: =M12*EXP(($B$2-$B$3-(0.5*$B$4*$B$4))*$B$6)*EXP($B$4*SQRT($B$6)*L13) -> 160.92344
J14: =J13+$B$6 -> 0.41666667 | K14: =RAND() -> 0.68111962 | L14: =NORMSINV(K14) -> 0.47083194 | M14: =M13*EXP(($B$2-$B$3-(0.5*$B$4*$B$4))*$B$6)*EXP($B$4*SQRT($B$6)*L14) -> 165.80342
J15: =J14+$B$6 -> 0.45833333 | K15: =RAND() -> 0.54374464 | L15: =NORMSINV(K15) -> 0.10987221 | M15: =M14*EXP(($B$2-$B$3-(0.5*$B$4*$B$4))*$B$6)*EXP($B$4*SQRT($B$6)*L15) -> 167.09672
J16: =J15+$B$6 -> 0.5 | K16: =RAND() -> 0.20426898 | L16: =NORMSINV(K16) -> -0.82646923 | M16: =M15*EXP(($B$2-$B$3-(0.5*$B$4*$B$4))*$B$6)*EXP($B$4*SQRT($B$6)*L16) -> 159.01583

Sheet Slide 33_o (1 path)
A1: S0 | B1: 100
A2: X | B2: 120
A3: r | B3: 0.1 | J3: Time | K3: uni rand numbers | L3: normal random numbers | M3: stock price path
A4: q | B4: 0.03 | J4: 0 | M4: =B1 -> 100
A5: vol | B5: 0.3 | J5: =J4+$B$7 -> 0.041666667 | K5: =RAND() -> 0.96394347 | L5: =NORMSINV(K5) -> 1.7984037 | M5: =M4*EXP(($B$3-$B$4-(0.5*$B$5*$B$5))*$B$7)*EXP($B$5*SQRT($B$7)*L5) -> 111.75859
A6: Time | B6: 0.5 | J6: =J5+$B$7 -> 0.083333333 | K6: =RAND() -> 0.2520922 | L6: =NORMSINV(K6) -> -0.66792041 | M6: =M5*EXP(($B$3-$B$4-(0.5*$B$5*$B$5))*$B$7)*EXP($B$5*SQRT($B$7)*L6) -> 107.39152
A7: delta t | B7: =B6/12 -> 0.041666667 | C7: years | J7: =J6+$B$7 -> 0.125 | K7: =RAND() -> 0.37178465 | L7: =NORMSINV(K7) -> -0.32713034 | M7: =M6*EXP(($B$3-$B$4-(0.5*$B$5*$B$5))*$B$7)*EXP($B$5*SQRT($B$7)*L7) -> 105.3713
J8: =J7+$B$7 -> 0.16666667 | K8: =RAND() -> 0.16168933 | L8: =NORMSINV(K8) -> -0.9875386 | M8: =M7*EXP(($B$3-$B$4-(0.5*$B$5*$B$5))*$B$7)*EXP($B$5*SQRT($B$7)*L8) -> 99.291288
J9: =J8+$B$7 -> 0.20833333 | K9: =RAND() -> 0.46457891 | L9: =NORMSINV(K9) -> -0.088904489 | M9: =M8*EXP(($B$3-$B$4-(0.5*$B$5*$B$5))*$B$7)*EXP($B$5*SQRT($B$7)*L9) -> 98.855109
J10: =J9+$B$7 -> 0.25 | K10: =RAND() -> 0.040759296 | L10: =NORMSINV(K10) -> -1.741942 | M10: =M9*EXP(($B$3-$B$4-(0.5*$B$5*$B$5))*$B$7)*EXP($B$5*SQRT($B$7)*L10) -> 88.94562
J11: =J10+$B$7 -> 0.29166667 | K11: =RAND() -> 0.45332765 | L11: =NORMSINV(K11) -> -0.1172584 | M11: =M10*EXP(($B$3-$B$4-(0.5*$B$5*$B$5))*$B$7)*EXP($B$5*SQRT($B$7)*L11) -> 88.401263
J12: =J11+$B$7 -> 0.33333333 | K12: =RAND() -> 0.034319441 | L12: =NORMSINV(K12) -> -1.8207894 | M12: =M11*EXP(($B$3-$B$4-(0.5*$B$5*$B$5))*$B$7)*EXP($B$5*SQRT($B$7)*L12) -> 79.156571
J13: =J12+$B$7 -> 0.375 | K13: =RAND() -> 0.4642842 | L13: =NORMSINV(K13) -> -0.089646171 | M13: =M12*EXP(($B$3-$B$4-(0.5*$B$5*$B$5))*$B$7)*EXP($B$5*SQRT($B$7)*L13) -> 78.805263
J14: =J13+$B$7 -> 0.41666667 | K14: =RAND() -> 0.88914442 | L14: =NORMSINV(K14) -> 1.2219907 | M14: =M13*EXP(($B$3-$B$4-(0.5*$B$5*$B$5))*$B$7)*EXP($B$5*SQRT($B$7)*L14) -> 85.017132
J15: =J14+$B$7 -> 0.45833333 | K15: =RAND() -> 0.52684879 | L15: =NORMSINV(K15) -> 0.067350821 | M15: =M14*EXP(($B$3-$B$4-(0.5*$B$5*$B$5))*$B$7)*EXP($B$5*SQRT($B$7)*L15) -> 85.457471
J16: =J15+$B$7 -> 0.5 | K16: =RAND() -> 0.633051 | L16: =NORMSINV(K16) -> 0.33994493 | M16: =M15*EXP(($B$3-$B$4-(0.5*$B$5*$B$5))*$B$7)*EXP($B$5*SQRT($B$7)*L16) -> 87.346048
L17: Option Payoff (1 path) | M17: =MAX(M16-B2,0) -> 0
L18: PV (Option payoff (1 path)) | M18: =M17*EXP(-B3*B6) -> 0

Sheet Slide 34_ R
A1: S0 | B1: 100
A2: X | B2: 100
A3: r | B3: 0.1 | J3: Time | K3: uni rand numbers | L3: normal random numbers | M3: stock price path
A4: q | B4: 0.03 | J4: 0 | M4: =B1 -> 100 | P4: Path | Q4: =M12 -> 0
A5: vol | B5: 0.3 | J5: =J4+$B$7 -> 0.083333333 | K5: =RAND() -> 0.80405172 | L5: =NORMSINV(K5) -> 0.85618301 | M5: =M4*EXP(($B$3-$B$4-(0.5*$B$5*$B$5))*$B$7)*EXP($B$5*SQRT($B$7)*L5) -> 107.92118 | P5: 1 | Q5: 3.8937523
A6: Time | B6: 0.5 | J6: =J5+$B$7 -> 0.16666667 | K6: =RAND() -> 0.3008047 | L6: =NORMSINV(K6) -> -0.52208753 | M6: =M5*EXP(($B$3-$B$4-(0.5*$B$5*$B$5))*$B$7)*EXP($B$5*SQRT($B$7)*L6) -> 103.36541 | P6: =P5+1 -> 2 | Q6: 0
A7: delta t | B7: =B6/6 -> 0.083333333 | C7: years | J7: =J6+$B$7 -> 0.25 | K7: =RAND() -> 0.54342702 | L7: =NORMSINV(K7) -> 0.10907128 | M7: =M6*EXP(($B$3-$B$4-(0.5*$B$5*$B$5))*$B$7)*EXP($B$5*SQRT($B$7)*L7) -> 104.56402 | P7: =P6+1 -> 3 | Q7: 0
J8: =J7+$B$7 -> 0.33333333 | K8: =RAND() -> 0.10685088 | L8: =NORMSINV(K8) -> -1.2434508 | M8: =M7*EXP(($B$3-$B$4-(0.5*$B$5*$B$5))*$B$7)*EXP($B$5*SQRT($B$7)*L8) -> 94.084836 | P8: =P7+1 -> 4 | Q8: 0
J9: =J8+$B$7 -> 0.41666667 | K9: =RAND() -> 0.10968214 | L9: =NORMSINV(K9) -> -1.2282203 | M9: =M8*EXP(($B$3-$B$4-(0.5*$B$5*$B$5))*$B$7)*EXP($B$5*SQRT($B$7)*L9) -> 84.767586 | P9: =P8+1 -> 5 | Q9: 2.6513056
J10: =J9+$B$7 -> 0.5 | K10: =RAND() -> 0.023739043 | L10: =NORMSINV(K10) -> -1.9820103 | M10: =M9*EXP(($B$3-$B$4-(0.5*$B$5*$B$5))*$B$7)*EXP($B$5*SQRT($B$7)*L10) -> 71.546632 | P10: =P9+1 -> 6 | Q10: 0
L11: Option Payoff (T) | M11: =MAX(AVERAGE(M5:M10)-B2,0) -> 0 | P11: =P10+1 -> 7 | Q11: 33.031955
L12: Option Payoff (0) | M12: =M11*EXP(-B3*B6) -> 0 | P12: =P11+1 -> 8 | Q12: 15.632542
L13: Option Premium | M13: =AVERAGE(Q5:Q5004) -> 6.3606192 | P13: =P12+1 -> 9 | Q13: 2.4977401
P14: =P13+1 -> 10 | Q14: 0.0023923055
P15: =P14+1 -> 11 | Q15: 0
P16: =P15+1 -> 12 | Q16: 0
P17: =P16+1 -> 13 | Q17: 0
P18: =P17+1 -> 14 | Q18: 22.916211
P19: =P18+1 -> 15 | Q19: 16.475979
P20: =P19+1 -> 16 | Q20: 0
P21: =P20+1 -> 17 | Q21: 0
P22: =P21+1 -> 18 | Q22: 21.007639
P23: =P22+1 -> 19 | Q23: 0
P24: =P23+1 -> 20 | Q24: 0
P25: =P24+1 -> 21 | Q25: 3.4350872
... P5004: =P5003+1 -> 5000 | Q5004: 0

Sheet Slide 35_ R
A1: S0 | B1: 100
A2: r | B2: 0.1
A3: q | B3: 0.03 | J3: Time | K3: uni rand numbers | L3: normal random numbers | M3: stock price path
A4: vol | B4: 0.3 | J4: 0 | M4: =B1 -> 100 | P4: Path | Q4: =M12 -> 0
A5: Time | B5: 0.5 | J5: =J4+$B$6 -> 0.083333333 | K5: =RAND() -> 0.16798765 | L5: =NORMSINV(K5) -> -0.96214794 | M5: =M4*EXP(($B$2-$B$3-(0.5*$B$4*$B$4))*$B$6)*EXP($B$4*SQRT($B$6)*L5) -> 92.197136 | P5: 1 | Q5: 4.3320952
A6: delta t | B6: =B5/6 -> 0.083333333 | C6: years | J6: =J5+$B$6 -> 0.16666667 | K6: =RAND() -> 0.0092226783 | L6: =NORMSINV(K6) -> -2.3565546 | M6: =M5*EXP(($B$2-$B$3-(0.5*$B$4*$B$4))*$B$6)*EXP($B$4*SQRT($B$6)*L6) -> 75.333791 | P6: =P5+1 -> 2 | Q6: 6.4776234
J7: =J6+$B$6 -> 0.25 | K7: =RAND() -> 0.067994546 | L7: =NORMSINV(K7) -> -1.4908949 | M7: =M6*EXP(($B$2-$B$3-(0.5*$B$4*$B$4))*$B$6)*EXP($B$4*SQRT($B$6)*L7) -> 66.346886 | P7: =P6+1 -> 3 | Q7: 0
J8: =J7+$B$6 -> 0.33333333 | K8: =RAND() -> 0.20011623 | L8: =NORMSINV(K8) -> -0.84120613 | M8: =M7*EXP(($B$2-$B$3-(0.5*$B$4*$B$4))*$B$6)*EXP($B$4*SQRT($B$6)*L8) -> 61.813982 | P8: =P7+1 -> 4 | Q8: 0
J9: =J8+$B$6 -> 0.41666667 | K9: =RAND() -> 0.50631115 | L9: =NORMSINV(K9) -> 0.015820355 | M9: =M8*EXP(($B$2-$B$3-(0.5*$B$4*$B$4))*$B$6)*EXP($B$4*SQRT($B$6)*L9) -> 62.02782 | P9: =P8+1 -> 5 | Q9: 5.489016
J10: =J9+$B$6 -> 0.5 | K10: =RAND() -> 0.63461648 | L10: =NORMSINV(K10) -> 0.34410537 | M10: =M9*EXP(($B$2-$B$3-(0.5*$B$4*$B$4))*$B$6)*EXP($B$4*SQRT($B$6)*L10) -> 64.037364 | P10: =P9+1 -> 6 | Q10: 0
L11: Option Payoff (T) | M11: =MAX(M10-M7,0) -> 0 | P11: =P10+1 -> 7 | Q11: 11.380498
L12: Option Payoff (0) | M12: =M11*EXP(-B2*B5) -> 0 | P12: =P11+1 -> 8 | Q12: 0
L13: Option Premium | M13: =AVERAGE(Q5:Q5004) -> 6.85673 | P13: =P12+1 -> 9 | Q13: 1.0158595
P14: =P13+1 -> 10 | Q14: 6.0086383
P15: =P14+1 -> 11 | Q15: 0.72627437
P16: =P15+1 -> 12 | Q16: 30.066755
P17: =P16+1 -> 13 | Q17: 6.7451268
P18: =P17+1 -> 14 | Q18: 4.7850605
P19: =P18+1 -> 15 | Q19: 24.221874
P20: =P19+1 -> 16 | Q20: 0
P21: =P20+1 -> 17 | Q21: 19.605008
P22: =P21+1 -> 18 | Q22: 9.8923095
P23: =P22+1 -> 19 | Q23: 0
P24: =P23+1 -> 20 | Q24: 0
P25: =P24+1 -> 21 | Q25: 0
... P5004: =P5003+1 -> 5000 | Q5004: 0

Sheet Slide 36_R
A1: S0 | B1: 100
A2: X | B2: 120
A3: H | B3: 90 | J3: Time | K3: uni rand numbers | L3: normal random numbers | M3: stock price path
A4: r | B4: 0.1 | J4: 0 | M4: =B1 -> 100 | P4: Path | Q4: =M12 -> 10.742714
A5: q | B5: 0.03 | J5: =J4+$B$8 -> 0.083333333 | K5: =RAND() -> 0.46544885 | L5: =NORMSINV(K5) -> -0.086715454 | M5: =M4*EXP(($B$4-$B$5-(0.5*$B$6*$B$6))*$B$8)*EXP($B$6*SQRT($B$8)*L5) -> 99.458825 | P5: 1 | Q5: 28.527695
A6: vol | B6: 0.3 | J6: =J5+$B$8 -> 0.16666667 | K6: =RAND() -> 0.56040771 | L6: =NORMSINV(K6) -> 0.15200299 | M6: =M5*EXP(($B$4-$B$5-(0.5*$B$6*$B$6))*$B$8)*EXP($B$6*SQRT($B$8)*L6) -> 100.98691 | P6: =P5+1 -> 2 | Q6: 0
A7: Time | B7: 0.5 | J7: =J6+$B$8 -> 0.25 | K7: =RAND() -> 0.68492587 | L7: =NORMSINV(K7) -> 0.48151819 | M7: =M6*EXP(($B$4-$B$5-(0.5*$B$6*$B$6))*$B$8)*EXP($B$6*SQRT($B$8)*L7) -> 105.50675 | P7: =P6+1 -> 3 | Q7: 0
A8: delta t | B8: =B7/6 -> 0.083333333 | C8: years | J8: =J7+$B$8 -> 0.33333333 | K8: =RAND() -> 0.32721345 | L8: =NORMSINV(K8) -> -0.44762078 | M8: =M7*EXP(($B$4-$B$5-(0.5*$B$6*$B$6))*$B$8)*EXP($B$6*SQRT($B$8)*L8) -> 101.7067 | P8: =P7+1 -> 4 | Q8: 12.610208
J9: =J8+$B$8 -> 0.41666667 | K9: =RAND() -> 0.87767121 | L9: =NORMSINV(K9) -> 1.1634238 | M9: =M8*EXP(($B$4-$B$5-(0.5*$B$6*$B$6))*$B$8)*EXP($B$6*SQRT($B$8)*L9) -> 112.72283 | P9: =P8+1 -> 5 | Q9: 0
J10: =J9+$B$8 -> 0.5 | K10: =RAND() -> 0.95879763 | L10: =NORMSINV(K10) -> 1.7369005 | M10: =M9*EXP(($B$4-$B$5-(0.5*$B$6*$B$6))*$B$8)*EXP($B$6*SQRT($B$8)*L10) -> 131.2935 | P10: =P9+1 -> 6 | Q10: 0
L11: Option Payoff (T) | M11: =IF(MIN(M5:M9)>90,MAX(M10-B2,0),0) -> 11.293505 | P11: =P10+1 -> 7 | Q11: 0
L12: Option Payoff (0) | M12: =M11*EXP(-B4*B7) -> 10.742714 | P12: =P11+1 -> 8 | Q12: 0
L13: Option Premium | M13: =AVERAGE(Q5:Q5004) -> 3.3388432 | P13: =P12+1 -> 9 | Q13: 26.77257
P14: =P13+1 -> 10 | Q14: 0
P15: =P14+1 -> 11 | Q15: 0
P16: =P15+1 -> 12 | Q16: 0
P17: =P16+1 -> 13 | Q17: 3.4711967
P18: =P17+1 -> 14 | Q18: 0
P19: =P18+1 -> 15 | Q19: 15.25587
P20: =P19+1 -> 16 | Q20: 0
P21: =P20+1 -> 17 | Q21: 0
P22: =P21+1 -> 18 | Q22: 0
P23: =P22+1 -> 19 | Q23: 0
P24: =P23+1 -> 20 | Q24: 0
P25: =P24+1 -> 21 | Q25: 0
... P5004: =P5003+1 -> 5000 | Q5004: 49.43091

Sheet Slide 37_data
A1: Term (mths) | B1: Zero Rates | C1: Dividend Rates | D1: Spot Volatility
A2: 0.5 | B2: 0.03 | C2: 0.0005 | D2: 0.3
A3: =A2+0.5 -> 1 | B3: =B2+0.0025 -> 0.0325 | C3: =C2+0.0025 -> 0.003 | D3: =D2+0.05 -> 0.35
A4: =A3+0.5 -> 1.5 | B4: =B3+0.0025 -> 0.035 | C4: =C3+0.0025 -> 0.0055 | D4: =D3+0.05 -> 0.4
A5: =A4+0.5 -> 2 | B5: =B4+0.0025 -> 0.0375 | C5: =C4+0.0025 -> 0.008 | D5: =D4+0.05 -> 0.45
A6: =A5+0.5 -> 2.5 | B6: =B5+0.0025 -> 0.04 | C6: =C5+0.0025 -> 0.0105 | D6: =D5+0.05 -> 0.5
A7: =A6+0.5 -> 3 | B7: =B6+0.0025 -> 0.0425 | C7: =C6+0.0025 -> 0.013 | D7: =D6+0.05 -> 0.55
A8: =A7+0.5 -> 3.5 | B8: =B7+0.0025 -> 0.045 | C8: =C7+0.0025 -> 0.0155 | D8: =D7+0.05 -> 0.6
A9: =A8+0.5 -> 4 | B9: =B8+0.0025 -> 0.0475 | C9: =C8+0.0025 -> 0.018 | D9: =D8+0.05 -> 0.65
A10: =A9+0.5 -> 4.5 | B10: =B9+0.0025 -> 0.05 | C10: =C9+0.0025 -> 0.0205 | D10: =D9+0.05 -> 0.7
A11: =A10+0.5 -> 5 | B11: =B10+0.0025 -> 0.0525 | C11: =C10+0.0025 -> 0.023 | D11: =D10+0.05 -> 0.75
A12: =A11+0.5 -> 5.5 | B12: =B11+0.0025 -> 0.055 | C12: =C11+0.0025 -> 0.0255 | D12: =D11+0.05 -> 0.8
A13: =A12+0.5 -> 6 | B13: =B12+0.0025 -> 0.0575 | C13: =C12+0.0025 -> 0.028 | D13: =D12+0.05 -> 0.85

Sheet Slide 37_R (simple)
B3: S0 | C3: 100 | F3: Time (mths) | G3: zero risk free | H3: zero dividend | I3: spot volatility | J3: uni rand numbers | K3: normal random numbers | L3: stock price path
A4: Call | B4: Strike | C4: 120 | F4: 0 | L4: =C3 -> 100 | O4: Path | P4: =L16 -> 1.6540637
B5: Option Life (yrs) | C5: =3/12 -> 0.25 | F5: 2 | G5: =B9 -> 0.05 | H5: =B10 -> 0.02 | I5: =B11 -> 0.3 | J5: =RAND() -> 0.64546739 | K5: =NORMSINV(J5) -> 0.37311181 | L5: =L4*EXP((G5-H5-(0.5*I5*I5))*F5/12)*EXP(I5*SQRT((F5-F4)/12)*K5) -> 104.41432 | O5: 1 | P5: 2.8199114
A6: Put | B6: Strike | C6: 90 | K6: Option Type | L6: Call | M6: Put | O6: =O5+1 -> 2 | P6: 3.3973954
B7: Option Life (yrs) | C7: =4/12 -> 0.33333333 | K7: Spot | L7: =L5 -> 104.41432 | M7: =L5 -> 104.41432 | O7: =O6+1 -> 3 | P7: 4.9252461
K8: Strike | L8: =C4 -> 120 | M8: =C6 -> 90 | O8: =O7+1 -> 4 | P8: 7.1088157
A9: r | B9: 0.05 | K9: Option Life | L9: =C5 -> 0.25 | M9: =C7 -> 0.33333333 | O9: =O8+1 -> 5 | P9: 1.9085479
A10: q | B10: 0.02 | K10: Risk-free | L10: =B9 -> 0.05 | M10: =L10 -> 0.05 | O10: =O9+1 -> 6 | P10: 5.2011794
A11: sigma | B11: 0.3 | K11: Dividend | L11: =B10 -> 0.02 | M11: =L11 -> 0.02 | O11: =O10+1 -> 7 | P11: 4.4291977
K12: Volatility | L12: =B11 -> 0.3 | M12: =L12 -> 0.3 | O12: =O11+1 -> 8 | P12: 2.6524741
K13: d1 | L13: =(LN(L7/L8)+((L10-L11+(0.5*L9*L9))*L9))/(L9*SQRT(L9)) -> -0.99049903 | M13: =(LN(M7/M8)+((M10-M11+(0.5*M9*M9))*M9))/(M9*SQRT(M9)) -> 0.92011239 | O13: =O12+1 -> 9 | P13: 1.9818911
K14: d2 | L14: =L13-(L12*SQRT(L9)) -> -1.140499 | M14: =M13-(M12*SQRT(M9)) -> 0.74690731 | O14: =O13+1 -> 10 | P14: 6.2388982
K15: Option Premium | L15: =(L7*EXP(-L11*L9)*NORMSDIST(L13))-(L8*EXP(-L10*L9)*NORMSDIST(L14)) -> 1.6679051 | M15: =(-M7*EXP(-M11*M9)*NORMSDIST(-M13))+(M8*EXP(-M10*M9)*NORMSDIST(-M14)) -> 1.6010925 | O15: =O14+1 -> 11 | P15: 6.0397032
K16: Best Choice Value | L16: =MAX(L15,M15)*EXP(-G5*F5/12) -> 1.6540637 | O16: =O15+1 -> 12 | P16: 2.2720055
K17: Option Premium | L17: =AVERAGE(P5:P5004) -> 5.0005953 | O17: =O16+1 -> 13 | P17: 3.6879458
O18: =O17+1 -> 14 | P18: 6.0981231
O19: =O18+1 -> 15 | P19: 5.1513515
O20: =O19+1 -> 16 | P20: 9.5748099
O21: =O20+1 -> 17 | P21: 6.147869
O22: =O21+1 -> 18 | P22: 5.6298787
O23: =O22+1 -> 19 | P23: 2.6018768
O24: =O23+1 -> 20 | P24: 8.2324982
O25: =O24+1 -> 21 | P25: 10.029498
O26: =O25+1 -> 22 | P26: 4.3197357
O27: =O26+1 -> 23 | P27: 3.3690963
O28: =O27+1 -> 24 | P28: 3.0715356
O29: =O28+1 -> 25 | P29: 2.4300039
... O5004: =O5003+1 -> 5000 | P5004: 4.9016959

Sheet Slide 37_R
A1: Term (mths) | B1: Zero Rates | C1: Dividend Rates | D1: Spot Volatility
A2: 0.5 | B2: 0.03 | C2: 0.0005 | D2: 0.3
A3: =A2+0.5 -> 1 | B3: =B2+0.0025 -> 0.0325 | C3: =C2+0.0025 -> 0.003 | D3: =D2+0.05 -> 0.35 | G3: S0 | H3: 100 | J3: Time (mths) | K3: zero risk free | L3: zero dividend | M3: spot volatility | N3: uni rand numbers | O3: normal random numbers | P3: stock price path
A4: =A3+0.5 -> 1.5 | B4: =B3+0.0025 -> 0.035 | C4: =C3+0.0025 -> 0.0055 | D4: =D3+0.05 -> 0.4 | F4: Call | G4: Strike | H4: 120 | J4: 0 | P4: =H3 -> 100 | S4: Path | T4: =P16 -> 20.38643
A5: =A4+0.5 -> 2 | B5: =B4+0.0025 -> 0.0375 | C5: =C4+0.0025 -> 0.008 | D5: =D4+0.05 -> 0.45 | G5: Option Life (yrs) | H5: =3/12 -> 0.25 | J5: 2 | K5: =VLOOKUP(J5,$A$2:$B$13,2,FALSE) -> 0.0375 | L5: =VLOOKUP(J5,$A$2:$C$13,3,FALSE) -> 0.008 | M5: =VLOOKUP(J5,$A$2:$D$13,4,FALSE) -> 0.45 | N5: =RAND() -> 0.18922262 | O5: =NORMSINV(N5) -> -0.8807646 | P5: =P4*EXP((K5-L5-(0.5*M5*M5))*J5/12)*EXP(M5*SQRT((J5-J4)/12)*O5) -> 84.049429 | S5: 1 | T5: 22.9147
A6: =A5+0.5 -> 2.5 | B6: =B5+0.0025 -> 0.04 | C6: =C5+0.0025 -> 0.0105 | D6: =D5+0.05 -> 0.5 | F6: Put | G6: Strike | H6: 90 | O6: Option Type | P6: Call | Q6: Put | S6: =S5+1 -> 2 | T6: 19.937182
A7: =A6+0.5 -> 3 | B7: =B6+0.0025 -> 0.0425 | C7: =C6+0.0025 -> 0.013 | D7: =D6+0.05 -> 0.55 | G7: Option Life (yrs) | H7: =4/12 -> 0.33333333 | O7: Spot | P7: =P5 -> 84.049429 | Q7: =P5 -> 84.049429 | S7: =S6+1 -> 3 | T7: 19.097224
A8: =A7+0.5 -> 3.5 | B8: =B7+0.0025 -> 0.045 | C8: =C7+0.0025 -> 0.0155 | D8: =D7+0.05 -> 0.6 | O8: Strike | P8: =H4 -> 120 | Q8: =H6 -> 90 | S8: =S7+1 -> 4 | T8: 20.854288
A9: =A8+0.5 -> 4 | B9: =B8+0.0025 -> 0.0475 | C9: =C8+0.0025 -> 0.018 | D9: =D8+0.05 -> 0.65 | O9: Option Life | P9: =H5 -> 0.25 | Q9: =H7 -> 0.33333333 | S9: =S8+1 -> 5 | T9: 30.555597
A10: =A9+0.5 -> 4.5 | B10: =B9+0.0025 -> 0.05 | C10: =C9+0.0025 -> 0.0205 | D10: =D9+0.05 -> 0.7 | O10: Risk-free | P10: =((B11*A11/12)-(B5*A5/12))/((A11-A5)/12) -> 0.0625 | Q10: =((B13*A13/12)-(B5*A5/12))/((A13-A5)/12) -> 0.0675 | S10: =S9+1 -> 6 | T10: 27.116719
A11: =A10+0.5 -> 5 | B11: =B10+0.0025 -> 0.0525 | C11: =C10+0.0025 -> 0.023 | D11: =D10+0.05 -> 0.75 | O11: Dividend | P11: =((C11*A11/12)-(C5*A5/12))/((A11-A5)/12) -> 0.033 | Q11: =((C13*A13/12)-(C5*A5/12))/((A13-A5)/12) -> 0.038 | S11: =S10+1 -> 7 | T11: 26.386914
A12: =A11+0.5 -> 5.5 | B12: =B11+0.0025 -> 0.055 | C12: =C11+0.0025 -> 0.0255 | D12: =D11+0.05 -> 0.8 | O12: Volatility | P12: =SQRT(((D11*D11*A11/12)-(D5*D5*A5/12))/((A11-A5)/12)) -> 0.89582364 | Q12: =SQRT(((D13*D13*A13/12)-(D5*D5*A5/12))/((A13-A5)/12)) -> 0.99121138 | S12: =S11+1 -> 8 | T12: 18.724
A13: =A12+0.5 -> 6 | B13: =B12+0.0025 -> 0.0575 | C13: =C12+0.0025 -> 0.028 | D13: =D12+0.05 -> 0.85 | O13: d1 | P13: =(LN(P7/P8)+((P10-P11+(0.5*P9*P9))*P9))/(P9*SQRT(P9)) -> -2.7271934 | Q13: =(LN(Q7/Q8)+((Q10-Q11+(0.5*Q9*Q9))*Q9))/(Q9*SQRT(Q9)) -> -0.20812022 | S13: =S12+1 -> 9 | T13: 24.891785
O14: d2 | P14: =P13-(P12*SQRT(P9)) -> -3.1751053 | Q14: =Q13-(Q12*SQRT(Q9)) -> -0.78039637 | S14: =S13+1 -> 10 | T14: 18.170194
O15: Option Premium | P15: =(P7*EXP(-P11*P9)*NORMSDIST(P13))-(P8*EXP(-P10*P9)*NORMSDIST(P14)) -> 0.17775383 | Q15: =(-Q7*EXP(-Q11*Q9)*NORMSDIST(-Q13))+(Q8*EXP(-Q10*Q9)*NORMSDIST(-Q14)) -> 20.514244 | S15: =S14+1 -> 11 | T15: 18.966213
O16: Best Choice Value | P16: =MAX(P15,Q15)*EXP(-K5*J5/12) -> 20.38643 | S16: =S15+1 -> 12 | T16: 30.23905
O17: Option Premium | P17: =AVERAGE(T5:T5004) -> 19.078388 | S17: =S16+1 -> 13 | T17: 21.084672
S18: =S17+1 -> 14 | T18: 15.95239
S19: =S18+1 -> 15 | T19: 22.523208
S20: =S19+1 -> 16 | T20: 20.394171
S21: =S20+1 -> 17 | T21: 18.602976
S22: =S21+1 -> 18 | T22: 19.713586
S23: =S22+1 -> 19 | T23: 21.605782
S24: =S23+1 -> 20 | T24: 18.556084
S25: =S24+1 -> 21 | T25: 17.503326
S26: =S25+1 -> 22 | T26: 14.962198
S27: =S26+1 -> 23 | T27: 20.474633
S28: =S27+1 -> 24 | T28: 20.376757
S29: =S28+1 -> 25 | T29: 12.57744
... S5004: =S5003+1 -> 5000 | T5004: 26.552689

Sheet Slide 41
A1: S0 | B1: 1.6 | C1: USD per GBP
A2: K | B2: 1.7 | C2: USD per GBP | G2: Now that we have all the inputs mapped out,
A3: Volatility | B3: 0.141 | G3: What does call on £ mean? Call opiton or put option
A4: Risk free | B4: 0.08 | C4: <<dom risk free (US)
A5: Dividend | B5: 0.11 | C5: <<for risk free (GBP)
A6: Term | B6: =1/3 -> 0.33333333 | C6: years
A11: USD - domestic rate
A12: GBP - foreign rate

Sheet Slide 42
A1: S0 | B1: 1.6 | C1: USD per GBP | F1: d1 | G1: =(LN(B1/B2)+(((B4-B5)+(0.5*B3*B3))*B6))/(B3*SQRT(B6)) -> -0.82685307
A2: K | B2: 1.7 | C2: USD per GBP | F2: d2 | G2: =G1-(B3*SQRT(B6)) -> -0.90825946
A3: Volatility | B3: 0.141
A4: Risk free | B4: 0.08 | C4: <<dom risk free (US) | F4: Call (on £) | G4: =(B1*EXP(-B5*B6)*NORMSDIST(G1))-(B2*EXP(-B4*B6)*NORMSDIST(G2)) -> 0.013851662 | H4: USD per GBP | I4: <<<rate
A5: Dividend | B5: 0.11 | C5: <<for risk free (GBP)
A6: Term | B6: =1/3 -> 0.33333333 | C6: years
A11: USD - domestic rate
A12: GBP - foreign rate

Sheet Slide 43a
B2: Options On Stocks | C2: Options of Currencies
A3: underlying | B3: stock (prices) | C3: currency (rates)
A4: strike | B4: price | C4: rate
A5: r | B5: zero rate (domestic) | C5: zero rate (domestic)
A6: q | B6: dividend rate | C6: zero rate (foreign)
A7: sigma | B7: stock volatility | C7: rate volatility
A8: time | B8: option life | C8: option life
A9: notional | B9: Number of stocks | C9: Currency ($ or £ or USD)
A10: type | B10: call or put | C10: call on currency or put on currency

Sheet Slide 43b
A1: S0 | B1: 1.6 | C1: USD per GBP | F1: d1 | G1: =(LN(B1/B2)+(((B4-B5)+(0.5*B3*B3))*B6))/(B3*SQRT(B6)) -> -0.82685307
A2: K | B2: 1.7 | C2: USD per GBP | F2: d2 | G2: =G1-(B3*SQRT(B6)) -> -0.90825946
A3: Volatility | B3: 0.141
A4: Risk free | B4: 0.08 | C4: <<dom risk free (US) | F4: Call (on £) | G4: =(B1*EXP(-B5*B6)*NORMSDIST(G1))-(B2*EXP(-B4*B6)*NORMSDIST(G2)) -> 0.013851662 | H4: USD per GBP | I4: <<<rate
A5: Dividend | B5: 0.11 | C5: <<for risk free (GBP) | F5: Call premium | G5: =G4*B7 -> 1385.1662 | H5: USD | I5: <<<dollars
A6: Term | B6: =1/3 -> 0.33333333 | C6: years
A7: Notional | B7: 100000 | C7: £
A11: USD - domestic rate
A12: GBP - foreign rate

Sheet Slide 44
A1: S0 | B1: =1/1.6 -> 0.625 | C1: GBP per USD | F1: d1 | G1: =(LN(B1/B2)+(((B4-B5)+(0.5*B3*B3))*B6))/(B3*SQRT(B6)) -> 0.90825946
A2: K | B2: =1/1.7 -> 0.58823529 | C2: GBP per USD | F2: d2 | G2: =G1-(B3*SQRT(B6)) -> 0.82685307
A3: Volatility | B3: 0.141
A4: Risk free | B4: 0.11 | C4: <<dom risk free (GBP) | F4: Put (on £) | G4: =(-B1*EXP(-B5*B6)*NORMSDIST(-G1))+(B2*EXP(-B4*B6)*NORMSDIST(-G2)) -> 0.0050925229 | H4: GBP per USD | I4: <<<rate
A5: Dividend | B5: 0.08 | C5: <<for risk free (USD) | F5: Put premium | G5: =G4*B7 -> 865.72889 | H5: GBP | I5: <<<dollars
A6: Term | B6: =1/3 -> 0.33333333 | C6: years | F6: Put premium | G6: =G5/B1 -> 1385.1662 | H6: USD
A7: Notional | B7: 170000 | C7: USD
A11: USD - domestic rate
A12: GBP - foreign rate

Sheet Slide 45
A1: S0 | B1: 1.6 | C1: USD per GBP | F1: d1 | G1: =(LN(B1/B2)+(((B4-B5)+(0.5*B3*B3))*B6))/(B3*SQRT(B6)) -> -0.82685307 | L1: S0 | M1: =1/B1 -> 0.625 | N1: GBP per USD | Q1: d1 | R1: =(LN(M1/M2)+(((M4-M5)+(0.5*M3*M3))*M6))/(M3*SQRT(M6)) -> 0.90825946
A2: K | B2: 1.7 | C2: USD per GBP | F2: d2 | G2: =G1-(B3*SQRT(B6)) -> -0.90825946 | L2: K | M2: =1/B2 -> 0.58823529 | N2: GBP per USD | Q2: d2 | R2: =R1-(M3*SQRT(M6)) -> 0.82685307
A3: Volatility | B3: 0.141 | L3: Volatility | M3: 0.141
A4: Risk free | B4: 0.08 | C4: <<dom risk free (US) | F4: Call (GBP) | G4: =(B1*EXP(-B5*B6)*NORMSDIST(G1))-(B2*EXP(-B4*B6)*NORMSDIST(G2)) -> 0.013851662 | H4: USD per GBP | I4: <<<rate | L4: Risk free | M4: =B5 -> 0.11 | N4: <<dom risk free GBP | Q4: Call (USD) | R4: =(M1*EXP(-M5*M6)*NORMSDIST(R1))-(M2*EXP(-M4*M6)*NORMSDIST(R2)) -> 0.046588814 | S4: GBP per USD | T4: <<<rate
A5: Dividend | B5: 0.11 | C5: <<for risk free (GBP) | F5: Put (GBP) | G5: =(-B1*EXP(-B5*B6)*NORMSDIST(-G1))+(B2*EXP(-B4*B6)*NORMSDIST(-G2)) -> 0.12672157 | H5: USD per GBP | I5: <<<rate | L5: Dividend | M5: =B4 -> 0.08 | N5: <<for risk free (US) | Q5: Put (USD) | R5: =(-M1*EXP(-M5*M6)*NORMSDIST(-R1))+(M2*EXP(-M4*M6)*NORMSDIST(-R2)) -> 0.0050925229 | S5: GBP per USD | T5: <<<rate
A6: Term | B6: =1/3 -> 0.33333333 | C6: years | L6: Term | M6: =1/3 -> 0.33333333 | N6: years
F7: On 100,000 GBP notional | Q7: On 170,000 USD notional
F8: call (GBP) prem | G8: =G4*100000 -> 1385.1662 | H8: USD | Q8: call (USD) prem | R8: =R4*170000 -> 7920.0983 | S8: GBP
F9: put (GBP) prem | G9: =G5*100000 -> 12672.157 | H9: USD | Q9: put (USD) prem | R9: =R5*170000 -> 865.72889 | S9: GBP
A11: USD - domestic rate | F11: to pay in GBP
A12: GBP - foreign rate | F12: call (GBP) prem | G12: =G8/B1 -> 865.72889 | H12: GBP
F13: put (GBP) prem | G13: =G9/B1 -> 7920.0983 | H13: GBP

Sheet Slide 46_R
E2: Spot | F2: 135 | G2: ISK per USD | K2: option premium to increase as ISK increase
E3: strike | F3: 140 | G3: ISK per USD | K3: looking for a put
E4: dom risk (ISK) | F4: 0.1
E5: for risk (USD) | F5: 0.05
E6: volatility | F6: 0.3
E7: Time | F7: 0.5
E8: Notional (ISK) | F8: 100000000
E9: Notional (USD) | F9: =F8/F3 -> 714285.71
E12: d1 | F12: =(LN(F2/F3)+((F4-F5+(0.5*F6*F6))*F7))/(F6*SQRT(F7)) -> 0.052478429
E13: d2 | F13: =F12-(F6*SQRT(F7)) -> -0.15965361
E14: put (USD) | F14: =(-F2*EXP(-F5*F7)*NORMSDIST(-F12))+(F3*EXP(-F4*F7)*NORMSDIST(-F13)) -> 11.954114 | G14: ISK per USD
E15: put (USD) | F15: =F14*F9 -> 8538652.6 | G15: ISK

Sheet Slide 47_data
A1: Time (yrs) | B1: Zero Rate (US) | C1: Zero Rate (ISK) | D1: FX Volatility | F1: Spot (USD/ISK) | G1: 135 | H1: <<ISK per USD
A2: 0.25 | B2: 0.04 | C2: 0.07 | D2: 0.2 | F2: Quarterly Revenue | G2: 10000000 | H2: USD
A3: 0.5 | B3: 0.045 | C3: 0.05 | D3: 0.22
A4: 0.75 | B4: 0.05 | C4: 0.03 | D4: 0.24
A5: 1 | B5: 0.055 | C5: 0.01 | D5: 0.26

Sheet Slide 47_R
A1: Time (yrs) | B1: Zero Rate (US) | C1: Zero Rate (ISK) | D1: FX Volatility | E1: Forwards | F1: Revenue (USD) | G1: Revenue (ISK) | H1: Disc Factor (ISK) | I1: FV(Revenue in ISK) | K1: Spot (USD/ISK) | L1: 135 | M1: <<ISK per USD
A2: 0.25 | B2: 0.04 | C2: 0.07 | D2: 0.2 | E2: =$L$1*EXP((C2-B2)*A2) -> 136.01631 | F2: =L2 -> 10000000 | G2: =F2*E2 -> 1.3601631e+09 | H2: =EXP(-C2*A2) -> 0.98265224 | I2: =G2*H2/$H$5 -> 1.35e+09 | K2: Quarterly Revenue | L2: 10000000 | M2: USD
A3: =A2+0.25 -> 0.5 | B3: =B2+0.005 -> 0.045 | C3: 0.05 | D3: 0.22 | E3: =$L$1*EXP((C3-B3)*A3) -> 135.33792 | F3: =F2 -> 10000000 | G3: =F3*E3 -> 1.3533792e+09 | H3: =EXP(-C3*A3) -> 0.97530991 | I3: =G3*H3/$H$5 -> 1.33323e+09
A4: =A3+0.25 -> 0.75 | B4: =B3+0.005 -> 0.05 | C4: 0.03 | D4: 0.24 | E4: =$L$1*EXP((C4-B4)*A4) -> 132.99011 | F4: =F3 -> 10000000 | G4: =F4*E4 -> 1.3299011e+09 | H4: =EXP(-C4*A4) -> 0.97775124 | I4: =G4*H4/$H$5 -> 1.3133808e+09
A5: =A4+0.25 -> 1 | B5: =B4+0.005 -> 0.055 | C5: 0.01 | D5: 0.26 | E5: =$L$1*EXP((C5-B5)*A5) -> 129.05966 | F5: =F4 -> 10000000 | G5: =F5*E5 -> 1.2905966e+09 | H5: =EXP(-C5*A5) -> 0.99004983 | I5: =G5*H5/$H$5 -> 1.2905966e+09
I6: =SUM(I2:I5) -> 5.2872075e+09
C7: S1) | D7: Using the 4 forwards, the expected revenue at the end of 12 months is
D8: =I6 -> 5.2872075e+09 | E8: ISK. Cost of strategy is NOTHING
H9: premiums
A10: Time (yrs) | B10: Zero Rate (US) | C10: Zero Rate (ISK) | D10: FX Volatility | E10: Strikes | F10: d1 | G10: d2 | H10: rates (ISK per USD) | I10: ISK | J10: Future Value
A11: =A2 -> 0.25 | B11: =B2 -> 0.04 | C11: =C2 -> 0.07 | D11: =D2 -> 0.2 | E11: =E2 -> 136.01631 | F11: =(LN($L$1/E11)+((C11-B11+(0.5*D11*D11))*A11))/(D11*SQRT(A11)) -> 0.05 | G11: =F11-(D11*SQRT(A11)) -> -0.05 | H11: =-($L$1*EXP(-B11*A11)*NORMSDIST(-F11))+(E11*EXP(-C11*A11)*NORMSDIST(-G11)) -> 5.3299111 | I11: =H11*F2 -> 53299111 | J11: =I11/$H$5 -> 53834776
A12: =A3 -> 0.5 | B12: =B3 -> 0.045 | C12: =C3 -> 0.05 | D12: =D3 -> 0.22 | E12: =E3 -> 135.33792 | F12: =(LN($L$1/E12)+((C12-B12+(0.5*D12*D12))*A12))/(D12*SQRT(A12)) -> 0.077781746 | G12: =F12-(D12*SQRT(A12)) -> -0.077781746 | H12: =-($L$1*EXP(-B12*A12)*NORMSDIST(-F12))+(E12*EXP(-C12*A12)*NORMSDIST(-G12)) -> 8.1835578 | I12: =H12*F3 -> 81835578 | J12: =I12/$H$5 -> 82658039
A13: =A4 -> 0.75 | B13: =B4 -> 0.05 | C13: =C4 -> 0.03 | D13: =D4 -> 0.24 | E13: =E4 -> 132.99011 | F13: =(LN($L$1/E13)+((C13-B13+(0.5*D13*D13))*A13))/(D13*SQRT(A13)) -> 0.10392305 | G13: =F13-(D13*SQRT(A13)) -> -0.10392305 | H13: =-($L$1*EXP(-B13*A13)*NORMSDIST(-F13))+(E13*EXP(-C13*A13)*NORMSDIST(-G13)) -> 10.762632 | I13: =H13*F4 -> 1.0762632e+08 | J13: =I13/$H$5 -> 1.0870798e+08
A14: =A5 -> 1 | B14: =B5 -> 0.055 | C14: =C5 -> 0.01 | D14: =D5 -> 0.26 | E14: =E5 -> 129.05966 | F14: =(LN($L$1/E14)+((C14-B14+(0.5*D14*D14))*A14))/(D14*SQRT(A14)) -> 0.13 | G14: =F14-(D14*SQRT(A14)) -> -0.13 | H14: =-($L$1*EXP(-B14*A14)*NORMSDIST(-F14))+(E14*EXP(-C14*A14)*NORMSDIST(-G14)) -> 13.216276 | I14: =H14*F5 -> 1.3216276e+08 | J14: =I14/$H$5 -> 1.3349102e+08
J15: =SUM(J11:J14) -> 3.7869182e+08
C16: S2) | D16: To protect against the weakening of the USD, the treasurer would need to purchase 4 put options that
D17: are struck at the forwards given in Cells F2 - E5
D18: FV cost of strategy is 378,691,817 ISK
D19: The total FV(revenue) with this strategy is floored at | G19: =D8-J15 -> 4.9085156e+09 | H19: ISK
D20: But there is unlimited upside to that revenue
A22: Time (yrs) | B22: Zero Rate (US) | C22: Zero Rate (ISK) | D22: FX Volatility | E22: Fwd rate (US) | F22: Fwd rate (ISK) | G22: Fwd volatility | H22: uniform rand | I22: normal rand | J22: FX Rate | N22: =J30 -> 0
A23: 0 | J23: =L1 -> 135 | M23: 1 | N23: 0
A24: =A11 -> 0.25 | B24: =B11 -> 0.04 | C24: =C11 -> 0.07 | D24: =D11 -> 0.2 | E24: =B24 -> 0.04 | F24: =C24 -> 0.07 | G24: =D24 -> 0.2 | H24: =RAND() -> 0.78734232 | I24: =NORMSINV(H24) -> 0.79723363 | J24: =J23*EXP((F24-E24-(0.5*G24*G24))*0.25)*EXP(G24*I24*SQRT(0.25)) -> 146.56927 | M24: =M23+1 -> 2 | N24: 0
A25: =A12 -> 0.5 | B25: =B12 -> 0.045 | C25: =C12 -> 0.05 | D25: =D12 -> 0.22 | E25: =((B25*A25)-(B24*A24))/(A25-A24) -> 0.05 | F25: =((C25*A25)-(C24*A24))/(A25-A24) -> 0.03 | G25: =SQRT(((D25*D25*A25)-(D24*D24*A24))/(A25-A24)) -> 0.23832751 | H25: =RAND() -> 0.92360257 | I25: =NORMSINV(H25) -> 1.4297289 | J25: =J24*EXP((F25-E25-(0.5*G25*G25))*0.25)*EXP(G25*I25*SQRT(0.25)) -> 171.70365 | M25: =M24+1 -> 3 | N25: 0
A26: =A13 -> 0.75 | B26: =B13 -> 0.05 | C26: =C13 -> 0.03 | D26: =D13 -> 0.24 | E26: =((B26*A26)-(B25*A25))/(A26-A25) -> 0.06 | F26: =((C26*A26)-(C25*A25))/(A26-A25) -> -0.01 | G26: =SQRT(((D26*D26*A26)-(D25*D25*A25))/(A26-A25)) -> 0.27568098 | H26: =RAND() -> 0.84320672 | I26: =NORMSINV(H26) -> 1.0077249 | J26: =J25*EXP((F26-E26-(0.5*G26*G26))*0.25)*EXP(G26*I26*SQRT(0.25)) -> 192.03455 | M26: =M25+1 -> 4 | N26: 0
A27: =A14 -> 1 | B27: =B14 -> 0.055 | C27: =C14 -> 0.01 | D27: =D14 -> 0.26 | E27: =((B27*A27)-(B26*A26))/(A27-A26) -> 0.07 | F27: =((C27*A27)-(C26*A26))/(A27-A26) -> -0.05 | G27: =SQRT(((D27*D27*A27)-(D26*D26*A26))/(A27-A26)) -> 0.31240999 | H27: =RAND() -> 0.80575841 | I27: =NORMSINV(H27) -> 0.86237138 | J27: =J26*EXP((F27-E27-(0.5*G27*G27))*0.25)*EXP(G27*I27*SQRT(0.25)) -> 210.64663 | M27: =M26+1 -> 5 | N27: 5.4906055e+08
I28: Total Revenue (1 year) | J28: =SUMPRODUCT(J24:J27,F2:F5) -> 7.2095409e+09 | M28: =M27+1 -> 6 | N28: 2.6521131e+08
I29: Strike of cashflow option | J29: =D8 -> 5.2872075e+09 | M29: =M28+1 -> 7 | N29: 0
I30: Shortfall | J30: =MAX(J29-J28,0) -> 0 | M30: =M29+1 -> 8 | N30: 0
I31: Cost of option | J31: =AVERAGE(N23:N2522) -> 2.9918161e+08 | M31: =M30+1 -> 9 | N31: 0
M32: =M31+1 -> 10 | N32: 9.1891734e+08
C33: S3) | D33: The cost of the cashflow option is 313925555 | M33: =M32+1 -> 11 | N33: 1.1690784e+08
D34: it is definitely cheaper than buying all the 4 options | M34: =M33+1 -> 12 | N34: 0
D35: The floor of the revenue is trivially | F35: =J29-J31 -> 4.9880258e+09 | G35: ISK | M35: =M34+1 -> 13 | N35: 6.8728066e+08
D36: with an unlimited upside (but less than S2) | M36: =M35+1 -> 14 | N36: 0
M37: =M36+1 -> 15 | N37: 6.7245201e+08
M38: =M37+1 -> 16 | N38: 0
M39: =M38+1 -> 17 | N39: 3.5699727e+08
M40: =M39+1 -> 18 | N40: 0
M41: =M40+1 -> 19 | N41: 0
...

Sheet Slide 51
A2: Time | B2: Forward Rates | C2: ti | D2: Dfi | E2: Fi | F2: ti* Fi * Dfi | G2: ti * dfi
A3: 0 | B3: 0.042 | D3: 1
A4: 0.5 | B4: 0.048 | C4: =(A4-A3) -> 0.5 | D4: =D3/(1+(B3*C4)) -> 0.97943193 | E4: =B4 -> 0.048
A5: 1 | B5: 0.053 | C5: =(A5-A4) -> 0.5 | D5: =D4/(1+(B4*C5)) -> 0.95647649 | E5: =B5 -> 0.053 | F5: =E4*C5*D5 -> 0.022955436 | G5: =C5*D5 -> 0.47823825
A6: 1.5 | B6: 0.055 | C6: =(A6-A5) -> 0.5 | D6: =D5/(1+(B5*C6)) -> 0.93178421 | E6: =B6 -> 0.055 | F6: =E5*C6*D6 -> 0.024692282 | G6: =C6*D6 -> 0.46589211
A7: 2 | B7: 0.056 | C7: =(A7-A6) -> 0.5 | D7: =D6/(1+(B6*C7)) -> 0.90684595 | E7: =B7 -> 0.056 | F7: =E6*C7*D7 -> 0.024938264 | G7: =C7*D7 -> 0.45342297
A8: 2.5 | B8: 0.059 | C8: =(A8-A7) -> 0.5 | D8: =D7/(1+(B7*C8)) -> 0.88214586 | E8: =B8 -> 0.059 | F8: =E7*C8*D8 -> 0.024700084 | G8: =C8*D8 -> 0.44107293
A9: 3 | C9: =(A9-A8) -> 0.5 | D9: =D8/(1+(B8*C9)) -> 0.85686825
F10: =SUM(F5:F8) -> 0.097286065 | G10: =SUM(G5:G8) -> 1.8386263
A14: If I tell you that the option expires in 6 months and on expiry it settles into a 2 year semi-annual reset swap
A15: ----> forward rate is the 2-year semi0annual swap starting 6 months from now (first floating rate gets set in 6 months) | N15: F0 | O15: =F10/G10 -> 0.052912366 | P15: =(D4-D8)/G10 -> 0.052912366
N16: X | O16: 0.06
N17: volatility | O17: 0.2
N18: N | O18: 100000000
A19: If I tell you that the option expires in 2 years and on expiry it settles into a 5 year annual reset swap | N19: sum tidfi | O19: =G10 -> 1.8386263
A20: ----> forward rate is the 5-year annual swap starting 2 years from now (first floating rate gets set in 2 years) | N20: option life | O20: 0.5
N22: d1 | O22: =(LN(O15/O16)+(0.5*O17*O17*O20))/(O17*SQRT(O20)) -> -0.81817552
N23: d2 | O23: =O22-(O17*SQRT(O20)) -> -0.95959688
N25: RTP (call) | O25: =O18*((O15*NORMSDIST(O22))-(O16*NORMSDIST(O23)))*O19 -> 149932.21
N26: RTR (put) | O26: =O18*((-O15*NORMSDIST(-O22))+(O16*NORMSDIST(-O23)))*O19 -> 1453083.2

Sheet Slide 52_data
A1: Time | B1: Discount Factor | F1: Swaption Implied Volatility Matrix
A2: 0 | B2: 1 | F2: Maturity\U/L Swap | G2: 1year (semi-annually reset) | H2: 1year (annually reset) | I2: 2 year (semi-annually reset) | J2: 2 year (annually reset)
A3: 0.5 | B3: 0.97628571 | F3: 0.5 years | G3: 0.3 | H3: 0.28 | I3: 0.28 | J3: 0.25
A4: 1 | B4: 0.94838001 | F4: 1 year | G4: 0.35 | H4: 0.32 | I4: 0.32 | J4: 0.27
A5: 1.5 | B5: 0.92081144 | F5: 1.5 years | G5: 0.37 | H5: 0.35 | I5: 0.35 | J5: 0.3
A6: 2 | B6: 0.89404426 | F6: 2 years | G6: 0.39 | H6: 0.35 | I6: 0.37 | J6: 0.33
A7: 2.5 | B7: 0.86286244 | F7: 2.5 years | G7: 0.41 | H7: 0.37 | I7: 0.4 | J7: 0.37
A8: 3 | B8: 0.83527021 | F8: 3 years | G8: 0.45 | H8: 0.39 | I8: 0.43 | J8: 0.39

Sheet Slide 52_R_Q1
A1: Time | B1: Discount Factor | C1: Ti | D1: Fi | E1: ti* fi* dfi | F1: ti*dfi | J1: Swaption Implied Volatility Matrix
A2: 0 | B2: 1 | J2: Maturity\U/L Swap | K2: 1year (semi-annually reset) | L2: 1year (annually reset) | M2: 2 year (semi-annually reset) | N2: 2 year (annually reset)
A3: 0.5 | B3: 0.97628571 | J3: 0.5 years | K3: 0.3 | L3: 0.28 | M3: 0.28 | N3: 0.25
A4: 1 | B4: 0.94838001 | J4: 1 year | K4: 0.35 | L4: 0.32 | M4: 0.32 | N4: 0.27
A5: 1.5 | B5: 0.92081144 | C5: =(A5-A4) -> 0.5 | D5: =((B4/B5)-1)/C5 -> 0.059878871 | E5: =C5*D5*B5 -> 0.027568575 | F5: =C5*B5 -> 0.46040572 | J5: 1.5 years | K5: 0.37 | L5: 0.35 | M5: 0.35 | N5: 0.3
A6: 2 | B6: 0.89404426 | C6: =(A6-A5) -> 0.5 | D6: =((B5/B6)-1)/C6 -> 0.059878871 | E6: =C6*D6*B6 -> 0.02676718 | F6: =C6*B6 -> 0.44702213 | J6: 2 years | K6: 0.39 | L6: 0.35 | M6: 0.37 | N6: 0.33
A7: 2.5 | B7: 0.86286244 | J7: 2.5 years | K7: 0.41 | L7: 0.37 | M7: 0.4 | N7: 0.37
A8: 3 | B8: 0.83527021 | J8: 3 years | K8: 0.45 | L8: 0.39 | M8: 0.43 | N8: 0.39
E9: =SUM(E5:E6) -> 0.054335755 | F9: =SUM(F5:F6) -> 0.90742785
A11: ATM Fwd RTP (call) Swaption
A12: F0 | B12: =E9/F9 -> 0.059878871 | C12: <<fwd start swap rate for a 1-year sem-annual reset swap (whose first floating rate gets set in 12 months)
A13: X | B13: =B12 -> 0.059878871 | C13: << since the option is ATM forward
A14: volatility | B14: =K4 -> 0.35
A15: N | B15: 100000000
A16: sum tidfi | B16: =F9 -> 0.90742785
A17: option life | B17: 1
A19: d1 | B19: =(LN(B12/B13)+(0.5*B14*B14*B17))/(B14*SQRT(B17)) -> 0.175
A20: d2 | B20: =B19-(B14*SQRT(B17)) -> -0.175
A21: RTP premium | B21: =B15*((B12*NORMSDIST(B19))-(B13*NORMSDIST(B20)))*B16 -> 754834.3
A22: ATM RTR (put) Swaption | B22: =B15*((-B12*NORMSDIST(-B19))+(B13*NORMSDIST(-B20)))*B16 -> 754834.3

Sheet Slide 52_R_Q2
A1: Time | B1: Discount Factor | C1: Ti | D1: Fi | E1: ti* fi* dfi | F1: ti*dfi | J1: Swaption Implied Volatility Matrix
A2: 0 | B2: 1 | J2: Maturity\U/L Swap | K2: 1year (semi-annually reset) | L2: 1year (annually reset) | M2: 2 year (semi-annually reset) | N2: 2 year (annually reset)
A3: 0.5 | B3: 0.97628571 | J3: 0.5 years | K3: 0.3 | L3: 0.28 | M3: 0.28 | N3: 0.25
A4: 1 | B4: 0.94838001 | J4: 1 year | K4: 0.35 | L4: 0.32 | M4: 0.32 | N4: 0.27
A5: 1.5 | B5: 0.92081144 | J5: 1.5 years | K5: 0.37 | L5: 0.35 | M5: 0.35 | N5: 0.3
A6: 2 | B6: 0.89404426 | C6: =(A6-A4) -> 1 | D6: =((B4/B6)-1)/C6 -> 0.060775241 | E6: =C6*D6*B6 -> 0.054335755 | F6: =C6*B6 -> 0.89404426 | J6: 2 years | K6: 0.39 | L6: 0.35 | M6: 0.37 | N6: 0.33
A7: 2.5 | B7: 0.86286244 | J7: 2.5 years | K7: 0.41 | L7: 0.37 | M7: 0.4 | N7: 0.37
A8: 3 | B8: 0.83527021 | C8: =(A8-A6) -> 1 | D8: =((B6/B8)-1)/C8 -> 0.070365308 | E8: =C8*D8*B8 -> 0.058774046 | F8: =C8*B8 -> 0.83527021 | J8: 3 years | K8: 0.45 | L8: 0.39 | M8: 0.43 | N8: 0.39
E9: =SUM(E5:E8) -> 0.1131098 | F9: =SUM(F5:F8) -> 1.7293145
A11: ATM Fwd RTR (put) Swaption
A12: F0 | B12: =E9/F9 -> 0.065407306 | C12: <<fwd start swap rate for a 2-year annual reset swap (whose first floating rate gets set in 12 months)
A13: X | B13: =B12 -> 0.065407306 | C13: << since the option is ATM forward
A14: volatility | B14: =N4 -> 0.27
A15: N | B15: 100000000
A16: sum tidfi | B16: =F9 -> 1.7293145
A17: option life | B17: 1
A19: d1 | B19: =(LN(B12/B13)+(0.5*B14*B14*B17))/(B14*SQRT(B17)) -> 0.135
A20: d2 | B20: =B19-(B14*SQRT(B17)) -> -0.135
A21: ATM RTR (put) Swaption | B21: =B15*((-B12*NORMSDIST(-B19))+(B13*NORMSDIST(-B20)))*B16 -> 1214665

Sheet Slide 54_R_Caplet_6%
A1: Time | B1: Discount Factor | C1: Ti | D1: Fi | E1: ti* fi* dfi | F1: ti*dfi
A2: 0 | B2: 1
A3: 0.5 | B3: 0.97628571
A4: 1 | B4: 0.94838001 | C4: =A4-A3 -> 0.5 | D4: =((B3/B4)-1)/C4 -> 0.058849189 | E4: =C4*D4*B4 -> 0.027905697 | F4: =C4*B4 -> 0.47419001
A5: 1.5 | B5: 0.92081144
A6: 2 | B6: 0.89404426
A7: 2.5 | B7: 0.86286244
A8: 3 | B8: 0.83527021
E9: =E4 -> 0.027905697 | F9: =F4 -> 0.47419001
A12: F0 | B12: =E9/F9 -> 0.058849189
A13: X | B13: 0.06
A14: volatility | B14: 0.25
A15: N | B15: 1000000
A16: sum tidfi | B16: =F4 -> 0.47419001
A17: option life | B17: 0.5
A19: d1 | B19: =(LN(B12/B13)+(0.5*B14*B14*B17))/(B14*SQRT(B17)) -> -0.021165178
A20: d2 | B20: =B19-(B14*SQRT(B17)) -> -0.19794187
A21: Caplet premium | B21: =B15*((B12*NORMSDIST(B19))-(B13*NORMSDIST(B20)))*B16 -> 1723.686

Sheet Slide 54_R_Caplet_ATM
A1: Time | B1: Discount Factor | C1: Ti | D1: Fi | E1: ti* fi* dfi | F1: ti*dfi
A2: 0 | B2: 1
A3: 0.5 | B3: 0.97628571
A4: 1 | B4: 0.94838001 | C4: =A4-A3 -> 0.5 | D4: =((B3/B4)-1)/C4 -> 0.058849189 | E4: =C4*D4*B4 -> 0.027905697 | F4: =C4*B4 -> 0.47419001
A5: 1.5 | B5: 0.92081144
A6: 2 | B6: 0.89404426
A7: 2.5 | B7: 0.86286244
A8: 3 | B8: 0.83527021
E9: =E4 -> 0.027905697 | F9: =F4 -> 0.47419001
A12: F0 | B12: =E9/F9 -> 0.058849189
A13: X | B13: =B12 -> 0.058849189
A14: volatility | B14: 0.25
A15: N | B15: 1000000
A16: sum tidfi | B16: =F4 -> 0.47419001
A17: option life | B17: 0.5
A19: d1 | B19: =(LN(B12/B13)+(0.5*B14*B14*B17))/(B14*SQRT(B17)) -> 0.088388348
A20: d2 | B20: =B19-(B14*SQRT(B17)) -> -0.088388348
A21: Caplet premium | B21: =B15*((B12*NORMSDIST(B19))-(B13*NORMSDIST(B20)))*B16 -> 1965.4534

Sheet Slide 54_R_Cap
A1: Time | B1: Discount Factor | C1: Ti | D1: Fi | E1: ti* fi* dfi | F1: ti*dfi
A2: 0 | B2: 1
A3: 0.5 | B3: 0.97628571
A4: 1 | B4: 0.94838001 | C4: =A4-A3 -> 0.5 | D4: =((B3/B4)-1)/C4 -> 0.058849189 | E4: =C4*D4*B4 -> 0.027905697 | F4: =C4*B4 -> 0.47419001
A5: 1.5 | B5: 0.92081144 | C5: =A5-A4 -> 0.5 | D5: =((B4/B5)-1)/C5 -> 0.059878871 | E5: =C5*D5*B5 -> 0.027568575 | F5: =C5*B5 -> 0.46040572
A6: 2 | B6: 0.89404426 | C6: =A6-A5 -> 0.5 | D6: =((B5/B6)-1)/C6 -> 0.059878871 | E6: =C6*D6*B6 -> 0.02676718 | F6: =C6*B6 -> 0.44702213
A7: 2.5 | B7: 0.86286244 | C7: =A7-A6 -> 0.5 | D7: =((B6/B7)-1)/C7 -> 0.072275296 | E7: =C7*D7*B7 -> 0.031181819 | F7: =C7*B7 -> 0.43143122
A8: 3 | B8: 0.83527021 | C8: =A8-A7 -> 0.5 | D8: =((B7/B8)-1)/C8 -> 0.066067786 | E8: =C8*D8*B8 -> 0.027592227 | F8: =C8*B8 -> 0.41763511
E9: =E4 -> 0.027905697 | F9: =F4 -> 0.47419001
A11: 1st caplet
A12: F0 | B12: =E9/F9 -> 0.058849189
A13: X | B13: 0.06
A14: volatility | B14: 0.25
A15: N | B15: 1000000 | D15: cap value | E15: =B21+B33+B45+B57+B69 -> 20372.622
A16: sum tidfi | B16: =F4 -> 0.47419001
A17: option life | B17: 0.5
A19: d1 | B19: =(LN(B12/B13)+(0.5*B14*B14*B17))/(B14*SQRT(B17)) -> -0.021165178
A20: d2 | B20: =B19-(B14*SQRT(B17)) -> -0.19794187
A21: RTP (call) Swaption | B21: =B15*((B12*NORMSDIST(B19))-(B13*NORMSDIST(B20)))*B16 -> 1723.686
A23: 2nd caplet
A24: F0 | B24: =D5 -> 0.059878871
A25: X | B25: 0.06
A26: volatility | B26: 0.25
A27: N | B27: 1000000
A28: sum tidfi | B28: =F5 -> 0.46040572
A29: option life | B29: 1
A31: d1 | B31: =(LN(B24/B25)+(0.5*B26*B26*B29))/(B26*SQRT(B29)) -> 0.11691657
A32: d2 | B32: =B31-(B26*SQRT(B29)) -> -0.13308343
A33: RTP (call) Swaption | B33: =B27*((B24*NORMSDIST(B31))-(B25*NORMSDIST(B32)))*B28 -> 2717.4027
A35: 3rd caplet
A36: F0 | B36: =D6 -> 0.059878871
A37: X | B37: 0.06
A38: volatility | B38: 0.25
A39: N | B39: 1000000
A40: sum tidfi | B40: =F6 -> 0.44702213
A41: option life | B41: 1.5
A43: d1 | B43: =(LN(B36/B37)+(0.5*B38*B38*B41))/(B38*SQRT(B41)) -> 0.14649301
A44: d2 | B44: =B43-(B38*SQRT(B41)) -> -0.1596932
A45: RTP (call) Swaption | B45: =B39*((B36*NORMSDIST(B43))-(B37*NORMSDIST(B44)))*B40 -> 3233.1916
A47: 4th caplet
...

Sheet Slide 56_(changing notional)_R
A1: S0 | B1: 135 | C1: ISK per USD | E1: Working | F1: Delta t | G1: =B6/B7 -> 0.016666667
A2: X | B2: 140 | C2: ISK per USD | F2: u | G2: =EXP(B3*SQRT(G1)) -> 1.0394896
A3: volatility | B3: 0.3 | F3: d | G3: =1/G2 -> 0.96201058
A4: Dom Risk free (ISK) | B4: 0.1 | F4: p | G4: =(EXP((B4-B5)*G1)-G3)/(G2-G3) -> 0.50107883
A5: For Risk Free (USD) | B5: 0.05 | F5: Option Value | G5: =A108 -> 12.582318 | H5: ISK per USD
A6: Term (yrs) | B6: 0.5 | G6: =G5*B9 -> 8987369.8 | H6: ISK
A7: n | B7: 30 | G7: =G6/B1 -> 66573.11 | H7: USD
A8: Notional | B8: 100000000 | C8: ISK
A9: Notional | B9: =B8/B2 -> 714285.71 | C9: USD
A14: 0 | B14: Delta t | C14: 2 Delta t | D14: 3 Delta t | E14: 4 Delta t | F14: 5 Delta t | G14: 6 Delta t | H14: 7 Delta t | I14: 8 Delta t | J14: 9 Delta t | K14: 10 Delta t | L14: 11 Delta t | M14: 12 Delta t | N14: 13 Delta t | O14: 14 Delta t | P14: 15 Delta t | Q14: 16 Delta t | R14: 17 Delta t | S14: 18 Delta t | T14: 19 Delta t | U14: 20 Delta t | V14: 21 Delta t | W14: 22 Delta t | X14: 23 Delta t | Y14: 24 Delta t | Z14: 25 Delta t | AA14: 26 Delta t | AB14: 27 Delta t | AC14: 28 Delta t | AD14: 29 Delta t | AE14: 30 Delta t
AE15: =$G$2*AD16 -> 431.45783
AD16: =$G$2*AC17 -> 415.067
AC17: =$G$2*AB18 -> 399.29884 | AE17: =$G$2*AD18 -> 399.29884
AB18: =$G$2*AA19 -> 384.12971 | AD18: =$G$2*AC19 -> 384.12971
AA19: =$G$2*Z20 -> 369.53684 | AC19: =$G$2*AB20 -> 369.53684 | AE19: =$G$2*AD20 -> 369.53684
Z20: =$G$2*Y21 -> 355.49835 | AB20: =$G$2*AA21 -> 355.49835 | AD20: =$G$2*AC21 -> 355.49835
Y21: =$G$2*X22 -> 341.99318 | AA21: =$G$2*Z22 -> 341.99318 | AC21: =$G$2*AB22 -> 341.99318 | AE21: =$G$2*AD22 -> 341.99318
X22: =$G$2*W23 -> 329.00105 | Z22: =$G$2*Y23 -> 329.00105 | AB22: =$G$2*AA23 -> 329.00105 | AD22: =$G$2*AC23 -> 329.00105
W23: =$G$2*V24 -> 316.50249 | Y23: =$G$2*X24 -> 316.50249 | AA23: =$G$2*Z24 -> 316.50249 | AC23: =$G$2*AB24 -> 316.50249 | AE23: =$G$2*AD24 -> 316.50249
V24: =$G$2*U25 -> 304.47874 | X24: =$G$2*W25 -> 304.47874 | Z24: =$G$2*Y25 -> 304.47874 | AB24: =$G$2*AA25 -> 304.47874 | AD24: =$G$2*AC25 -> 304.47874
U25: =$G$2*T26 -> 292.91177 | W25: =$G$2*V26 -> 292.91177 | Y25: =$G$2*X26 -> 292.91177 | AA25: =$G$2*Z26 -> 292.91177 | AC25: =$G$2*AB26 -> 292.91177 | AE25: =$G$2*AD26 -> 292.91177
